Workbook
Name GoldPoints: #REF!
Name LeagueName: #REF!
Name SilverPoints: #REF!
Name BronzePoints: #REF!

Sheet Leaderboard
B1: 🏆 LEADERBOARD 🏔️
O2: Scoring Table
B3: Rank | C3: Player | D3: Total Pts | E3: Tiebreaker | F3: Diff | G3: Countries Picked | I3: _Player | J3: _Points | K3: _USAGuess | L3: _Diff | M3: _Countries | N3: _SortKey | O3: Tier: | P3: Gold | Q3: Silver | R3: Bronze
B4: =IFERROR(__xludf.DUMMYFUNCTION("ARRAYFORMULA(IF(I4:I33="""","""",{SEQUENCE(COUNTA(FILTER(I4:I33,I4:I33<>""""))),SORT(FILTER(I4:M33,I4:I33<>""""),2,FALSE,4,TRUE)}))"),1.0) -> 1 | C4: =IFERROR(__xludf.DUMMYFUNCTION("""COMPUTED_VALUE"""),"LucasF") -> LucasF | D4: =IFERROR(__xludf.DUMMYFUNCTION("""COMPUTED_VALUE"""),762.0) -> 762 | E4: =IFERROR(__xludf.DUMMYFUNCTION("""COMPUTED_VALUE"""),50.0) -> 50 | F4: =IFERROR(__xludf.DUMMYFUNCTION("""COMPUTED_VALUE"""),50.0) -> 50 | G4: =IFERROR(__xludf.DUMMYFUNCTION("""COMPUTED_VALUE"""),"Germany, Austria, Switzerland, Italy, Finland, Australia, New Zealand, Spain") -> Germany, Austria, Switzerland, Italy, Finland, Australia, New Zealand, Spain | I4: {=IFERROR(INDEX(Entries!$E$2:$E$50,ROW()-3)&"","")} -> King Towsk | J4: =IF(I4="","",SUMIF('Team Scores'!$O$2:$O$401,I4,'Team Scores'!$AA$2:$AA$401)) -> 705 | K4: {=IF(I4="","",IFERROR(INDEX(Entries!$L$2:$L$50,ROW()-3),0))} -> 27 | L4: {=IF(I4="","",ABS(K4-IFERROR(XLOOKUP("United States",'Live Medal Table'!$B$2:$B$94,'Live Medal Table'!$J$2:$J$94,0),0)))} -> 6 | M4: {=IF(I4="","",INDEX(Entries!$F$2:$F$51,ROW()-3)&", "&INDEX(Entries!$M$2:$M$51,ROW()-3)&", "&INDEX(Entries!$N$2:$N$51,ROW()-3)&", "&INDEX(Entries!$H$2:$H$51,ROW()-3)&", "&INDEX(Entries!$I$2:$I$51,ROW()-3)&", "&INDEX(Entries!$J$2:$J$51,ROW()-3)&", "&INDEX(Entries!$O$2:$O$51,ROW()-3)&", "&INDEX(Entries!$P$2:$P$51,ROW()-3))} -> Norway, Austria, Netherlands, Italy, Finland, Australia, New Zealand, Ukraine | N4: =IF(I4="",999999999,J4*-1000000+L4) -> -704999994 | O4: 1 | P4: 3 | Q4: 2 | R4: 1
B5: =IFERROR(__xludf.DUMMYFUNCTION("""COMPUTED_VALUE"""),2.0) -> 2 | C5: =IFERROR(__xludf.DUMMYFUNCTION("""COMPUTED_VALUE"""),"Brad’s Cousin’s Cousin") -> Brad’s Cousin’s Cousin | D5: =IFERROR(__xludf.DUMMYFUNCTION("""COMPUTED_VALUE"""),741.0) -> 741 | E5: =IFERROR(__xludf.DUMMYFUNCTION("""COMPUTED_VALUE"""),25.0) -> 25 | F5: =IFERROR(__xludf.DUMMYFUNCTION("""COMPUTED_VALUE"""),25.0) -> 25 | G5: =IFERROR(__xludf.DUMMYFUNCTION("""COMPUTED_VALUE"""),"Norway, Netherlands, Switzerland, Italy, Finland, Australia, Belgium, New Zealand") -> Norway, Netherlands, Switzerland, Italy, Finland, Australia, Belgium, New Zealand | I5: {=IFERROR(INDEX(Entries!$E$2:$E$50,ROW()-3)&"","")} -> Wyatt | J5: =IF(I5="","",SUMIF('Team Scores'!$O$2:$O$401,I5,'Team Scores'!$AA$2:$AA$401)) -> 497 | K5: {=IF(I5="","",IFERROR(INDEX(Entries!$L$2:$L$50,ROW()-3),0))} -> 27 | L5: {=IF(I5="","",ABS(K5-IFERROR(XLOOKUP("United States",'Live Medal Table'!$B$2:$B$94,'Live Medal Table'!$J$2:$J$94,0),0)))} -> 6 | M5: {=IF(I5="","",INDEX(Entries!$F$2:$F$51,ROW()-3)&", "&INDEX(Entries!$M$2:$M$51,ROW()-3)&", "&INDEX(Entries!$N$2:$N$51,ROW()-3)&", "&INDEX(Entries!$H$2:$H$51,ROW()-3)&", "&INDEX(Entries!$I$2:$I$51,ROW()-3)&", "&INDEX(Entries!$J$2:$J$51,ROW()-3)&", "&INDEX(Entries!$O$2:$O$51,ROW()-3)&", "&INDEX(Entries!$P$2:$P$51,ROW()-3))} -> Canada, Austria, Netherlands, China, Czech Republic, Australia, Croatia, Ukraine | N5: =IF(I5="",999999999,J5*-1000000+L5) -> -496999994 | O5: 2 | P5: 6 | Q5: 4 | R5: 2
B6: =IFERROR(__xludf.DUMMYFUNCTION("""COMPUTED_VALUE"""),3.0) -> 3 | C6: =IFERROR(__xludf.DUMMYFUNCTION("""COMPUTED_VALUE"""),"King Towsk") -> King Towsk | D6: =IFERROR(__xludf.DUMMYFUNCTION("""COMPUTED_VALUE"""),705.0) -> 705 | E6: =IFERROR(__xludf.DUMMYFUNCTION("""COMPUTED_VALUE"""),27.0) -> 27 | F6: =IFERROR(__xludf.DUMMYFUNCTION("""COMPUTED_VALUE"""),6.0) -> 6 | G6: =IFERROR(__xludf.DUMMYFUNCTION("""COMPUTED_VALUE"""),"Norway, Austria, Netherlands, Italy, Finland, Australia, New Zealand, Ukraine") -> Norway, Austria, Netherlands, Italy, Finland, Australia, New Zealand, Ukraine | I6: {=IFERROR(INDEX(Entries!$E$2:$E$50,ROW()-3)&"","")} -> Jack Jansen | J6: =IF(I6="","",SUMIF('Team Scores'!$O$2:$O$401,I6,'Team Scores'!$AA$2:$AA$401)) -> 582 | K6: {=IF(I6="","",IFERROR(INDEX(Entries!$L$2:$L$50,ROW()-3),0))} -> 52 | L6: {=IF(I6="","",ABS(K6-IFERROR(XLOOKUP("United States",'Live Medal Table'!$B$2:$B$94,'Live Medal Table'!$J$2:$J$94,0),0)))} -> 19 | M6: {=IF(I6="","",INDEX(Entries!$F$2:$F$51,ROW()-3)&", "&INDEX(Entries!$M$2:$M$51,ROW()-3)&", "&INDEX(Entries!$N$2:$N$51,ROW()-3)&", "&INDEX(Entries!$H$2:$H$51,ROW()-3)&", "&INDEX(Entries!$I$2:$I$51,ROW()-3)&", "&INDEX(Entries!$J$2:$J$51,ROW()-3)&", "&INDEX(Entries!$O$2:$O$51,ROW()-3)&", "&INDEX(Entries!$P$2:$P$51,ROW()-3))} -> Norway, Netherlands, Sweden, Japan, Czech Republic, Poland, Belgium, Denmark | N6: =IF(I6="",999999999,J6*-1000000+L6) -> -581999981 | O6: 3 | P6: 9 | Q6: 6 | R6: 3
B7: =IFERROR(__xludf.DUMMYFUNCTION("""COMPUTED_VALUE"""),4.0) -> 4 | C7: =IFERROR(__xludf.DUMMYFUNCTION("""COMPUTED_VALUE"""),"Reb") -> Reb | D7: =IFERROR(__xludf.DUMMYFUNCTION("""COMPUTED_VALUE"""),680.0) -> 680 | E7: =IFERROR(__xludf.DUMMYFUNCTION("""COMPUTED_VALUE"""),65.0) -> 65 | F7: =IFERROR(__xludf.DUMMYFUNCTION("""COMPUTED_VALUE"""),65.0) -> 65 | G7: =IFERROR(__xludf.DUMMYFUNCTION("""COMPUTED_VALUE"""),"Germany, Netherlands, Sweden, Italy, Czech Republic, Great Britain, Denmark, Kazakhstan") -> Germany, Netherlands, Sweden, Italy, Czech Republic, Great Britain, Denmark, Kazakhstan | I7: {=IFERROR(INDEX(Entries!$E$2:$E$50,ROW()-3)&"","")} -> Charlie | J7: =IF(I7="","",SUMIF('Team Scores'!$O$2:$O$401,I7,'Team Scores'!$AA$2:$AA$401)) -> 570 | K7: {=IF(I7="","",IFERROR(INDEX(Entries!$L$2:$L$50,ROW()-3),0))} -> 29 | L7: =IF(I7="","",ABS(K7-$F$2)) -> 29 | M7: {=IF(I7="","",INDEX(Entries!$F$2:$F$51,ROW()-3)&", "&INDEX(Entries!$M$2:$M$51,ROW()-3)&", "&INDEX(Entries!$N$2:$N$51,ROW()-3)&", "&INDEX(Entries!$H$2:$H$51,ROW()-3)&", "&INDEX(Entries!$I$2:$I$51,ROW()-3)&", "&INDEX(Entries!$J$2:$J$51,ROW()-3)&", "&INDEX(Entries!$O$2:$O$51,ROW()-3)&", "&INDEX(Entries!$P$2:$P$51,ROW()-3))} -> Norway, Austria, Sweden, Japan, Czech Republic, Australia, Chile, Chinese Taipei | N7: =IF(I7="",999999999,J7*-1000000+L7) -> -569999971 | O7: 4 | P7: 18 | Q7: 12 | R7: 6
B8: =IFERROR(__xludf.DUMMYFUNCTION("""COMPUTED_VALUE"""),5.0) -> 5 | C8: =IFERROR(__xludf.DUMMYFUNCTION("""COMPUTED_VALUE"""),"Murph") -> Murph | D8: =IFERROR(__xludf.DUMMYFUNCTION("""COMPUTED_VALUE"""),676.0) -> 676 | E8: =IFERROR(__xludf.DUMMYFUNCTION("""COMPUTED_VALUE"""),25.0) -> 25 | F8: =IFERROR(__xludf.DUMMYFUNCTION("""COMPUTED_VALUE"""),25.0) -> 25 | G8: =IFERROR(__xludf.DUMMYFUNCTION("""COMPUTED_VALUE"""),"Norway, Netherlands, Switzerland, Japan, Finland, Great Britain, Belgium, Spain") -> Norway, Netherlands, Switzerland, Japan, Finland, Great Britain, Belgium, Spain | I8: {=IFERROR(INDEX(Entries!$E$2:$E$50,ROW()-3)&"","")} -> Murph | J8: =IF(I8="","",SUMIF('Team Scores'!$O$2:$O$401,I8,'Team Scores'!$AA$2:$AA$401)) -> 676 | K8: {=IF(I8="","",IFERROR(INDEX(Entries!$L$2:$L$50,ROW()-3),0))} -> 25 | L8: =IF(I8="","",ABS(K8-$F$2)) -> 25 | M8: {=IF(I8="","",INDEX(Entries!$F$2:$F$51,ROW()-3)&", "&INDEX(Entries!$M$2:$M$51,ROW()-3)&", "&INDEX(Entries!$N$2:$N$51,ROW()-3)&", "&INDEX(Entries!$H$2:$H$51,ROW()-3)&", "&INDEX(Entries!$I$2:$I$51,ROW()-3)&", "&INDEX(Entries!$J$2:$J$51,ROW()-3)&", "&INDEX(Entries!$O$2:$O$51,ROW()-3)&", "&INDEX(Entries!$P$2:$P$51,ROW()-3))} -> Norway, Netherlands, Switzerland, Japan, Finland, Great Britain, Belgium, Spain | N8: =IF(I8="",999999999,J8*-1000000+L8) -> -675999975 | O8: 5 | P8: 30 | Q8: 20 | R8: 10
B9: =IFERROR(__xludf.DUMMYFUNCTION("""COMPUTED_VALUE"""),6.0) -> 6 | C9: =IFERROR(__xludf.DUMMYFUNCTION("""COMPUTED_VALUE"""),"Bryan Jakobsze🇵🇱") -> Bryan Jakobsze🇵🇱 | D9: =IFERROR(__xludf.DUMMYFUNCTION("""COMPUTED_VALUE"""),669.0) -> 669 | E9: =IFERROR(__xludf.DUMMYFUNCTION("""COMPUTED_VALUE"""),29.0) -> 29 | F9: =IFERROR(__xludf.DUMMYFUNCTION("""COMPUTED_VALUE"""),29.0) -> 29 | G9: =IFERROR(__xludf.DUMMYFUNCTION("""COMPUTED_VALUE"""),"Norway, France, Netherlands, Italy, Finland, Great Britain, Kazakhstan, Ukraine") -> Norway, France, Netherlands, Italy, Finland, Great Britain, Kazakhstan, Ukraine | I9: {=IFERROR(INDEX(Entries!$E$2:$E$50,ROW()-3)&"","")} -> Josh’s Dawgs | J9: =IF(I9="","",SUMIF('Team Scores'!$O$2:$O$401,I9,'Team Scores'!$AA$2:$AA$401)) -> 464 | K9: {=IF(I9="","",IFERROR(INDEX(Entries!$L$2:$L$50,ROW()-3),0))} -> 200 | L9: =IF(I9="","",ABS(K9-$F$2)) -> 200 | M9: {=IF(I9="","",INDEX(Entries!$F$2:$F$51,ROW()-3)&", "&INDEX(Entries!$M$2:$M$51,ROW()-3)&", "&INDEX(Entries!$N$2:$N$51,ROW()-3)&", "&INDEX(Entries!$H$2:$H$51,ROW()-3)&", "&INDEX(Entries!$I$2:$I$51,ROW()-3)&", "&INDEX(Entries!$J$2:$J$51,ROW()-3)&", "&INDEX(Entries!$O$2:$O$51,ROW()-3)&", "&INDEX(Entries!$P$2:$P$51,ROW()-3))} -> United States, France, Sweden, China, Finland, Poland, Belgium, Ukraine | N9: =IF(I9="",999999999,J9*-1000000+L9) -> -463999800 | O9: 6 | P9: 60 | Q9: 40 | R9: 20
B10: =IFERROR(__xludf.DUMMYFUNCTION("""COMPUTED_VALUE"""),7.0) -> 7 | C10: =IFERROR(__xludf.DUMMYFUNCTION("""COMPUTED_VALUE"""),"SMAC") -> SMAC | D10: =IFERROR(__xludf.DUMMYFUNCTION("""COMPUTED_VALUE"""),651.0) -> 651 | E10: =IFERROR(__xludf.DUMMYFUNCTION("""COMPUTED_VALUE"""),27.0) -> 27 | F10: =IFERROR(__xludf.DUMMYFUNCTION("""COMPUTED_VALUE"""),27.0) -> 27 | G10: =IFERROR(__xludf.DUMMYFUNCTION("""COMPUTED_VALUE"""),"Norway, Netherlands, Switzerland, Italy, Finland, Poland, Spain, Ukraine") -> Norway, Netherlands, Switzerland, Italy, Finland, Poland, Spain, Ukraine | I10: {=IFERROR(INDEX(Entries!$E$2:$E$50,ROW()-3)&"","")} -> bgreen | J10: =IF(I10="","",SUMIF('Team Scores'!$O$2:$O$401,I10,'Team Scores'!$AA$2:$AA$401)) -> 611 | K10: {=IF(I10="","",IFERROR(INDEX(Entries!$L$2:$L$50,ROW()-3),0))} -> 29 | L10: =IF(I10="","",ABS(K10-$F$2)) -> 29 | M10: {=IF(I10="","",INDEX(Entries!$F$2:$F$51,ROW()-3)&", "&INDEX(Entries!$M$2:$M$51,ROW()-3)&", "&INDEX(Entries!$N$2:$N$51,ROW()-3)&", "&INDEX(Entries!$H$2:$H$51,ROW()-3)&", "&INDEX(Entries!$I$2:$I$51,ROW()-3)&", "&INDEX(Entries!$J$2:$J$51,ROW()-3)&", "&INDEX(Entries!$O$2:$O$51,ROW()-3)&", "&INDEX(Entries!$P$2:$P$51,ROW()-3))} -> Norway, Austria, Sweden, Italy, Finland, Great Britain, Estonia, Ukraine | N10: =IF(I10="",999999999,J10*-1000000+L10) -> -610999971
B11: =IFERROR(__xludf.DUMMYFUNCTION("""COMPUTED_VALUE"""),8.0) -> 8 | C11: =IFERROR(__xludf.DUMMYFUNCTION("""COMPUTED_VALUE"""),"Mark Mattson") -> Mark Mattson | D11: =IFERROR(__xludf.DUMMYFUNCTION("""COMPUTED_VALUE"""),647.0) -> 647 | E11: =IFERROR(__xludf.DUMMYFUNCTION("""COMPUTED_VALUE"""),27.0) -> 27 | F11: =IFERROR(__xludf.DUMMYFUNCTION("""COMPUTED_VALUE"""),27.0) -> 27 | G11: =IFERROR(__xludf.DUMMYFUNCTION("""COMPUTED_VALUE"""),"United States, Netherlands, Sweden, Italy, Czech Republic, Poland, Ireland, Spain") -> United States, Netherlands, Sweden, Italy, Czech Republic, Poland, Ireland, Spain | I11: {=IFERROR(INDEX(Entries!$E$2:$E$50,ROW()-3)&"","")} -> kborst13 | J11: =IF(I11="","",SUMIF('Team Scores'!$O$2:$O$401,I11,'Team Scores'!$AA$2:$AA$401)) -> 564 | K11: {=IF(I11="","",IFERROR(INDEX(Entries!$L$2:$L$50,ROW()-3),0))} -> 47 | L11: =IF(I11="","",ABS(K11-$F$2)) -> 47 | M11: {=IF(I11="","",INDEX(Entries!$F$2:$F$51,ROW()-3)&", "&INDEX(Entries!$M$2:$M$51,ROW()-3)&", "&INDEX(Entries!$N$2:$N$51,ROW()-3)&", "&INDEX(Entries!$H$2:$H$51,ROW()-3)&", "&INDEX(Entries!$I$2:$I$51,ROW()-3)&", "&INDEX(Entries!$J$2:$J$51,ROW()-3)&", "&INDEX(Entries!$O$2:$O$51,ROW()-3)&", "&INDEX(Entries!$P$2:$P$51,ROW()-3))} -> Norway, Austria, Netherlands, China, Finland, Great Britain, Belgium, Estonia | N11: =IF(I11="",999999999,J11*-1000000+L11) -> -563999953 | O11: {="USA Total Medal Count = "&IFERROR(XLOOKUP("United States",'Live Medal Table'!$B$2:$B$94,'Live Medal Table'!$J$2:$J$94,0),0)} -> USA Total Medal Count = 33
A12: View Player Rosters and Scores | B12: =IFERROR(__xludf.DUMMYFUNCTION("""COMPUTED_VALUE"""),9.0) -> 9 | C12: =IFERROR(__xludf.DUMMYFUNCTION("""COMPUTED_VALUE"""),"A taco93") -> A taco93 | D12: =IFERROR(__xludf.DUMMYFUNCTION("""COMPUTED_VALUE"""),646.0) -> 646 | E12: =IFERROR(__xludf.DUMMYFUNCTION("""COMPUTED_VALUE"""),27.0) -> 27 | F12: =IFERROR(__xludf.DUMMYFUNCTION("""COMPUTED_VALUE"""),27.0) -> 27 | G12: =IFERROR(__xludf.DUMMYFUNCTION("""COMPUTED_VALUE"""),"United States, Sweden, Switzerland, China, Finland, Australia, Estonia, New Zealand") -> United States, Sweden, Switzerland, China, Finland, Australia, Estonia, New Zealand | I12: {=IFERROR(INDEX(Entries!$E$2:$E$50,ROW()-3)&"","")} -> SMAC | J12: =IF(I12="","",SUMIF('Team Scores'!$O$2:$O$401,I12,'Team Scores'!$AA$2:$AA$401)) -> 651 | K12: {=IF(I12="","",IFERROR(INDEX(Entries!$L$2:$L$50,ROW()-3),0))} -> 27 | L12: =IF(I12="","",ABS(K12-$F$2)) -> 27 | M12: {=IF(I12="","",INDEX(Entries!$F$2:$F$51,ROW()-3)&", "&INDEX(Entries!$M$2:$M$51,ROW()-3)&", "&INDEX(Entries!$N$2:$N$51,ROW()-3)&", "&INDEX(Entries!$H$2:$H$51,ROW()-3)&", "&INDEX(Entries!$I$2:$I$51,ROW()-3)&", "&INDEX(Entries!$J$2:$J$51,ROW()-3)&", "&INDEX(Entries!$O$2:$O$51,ROW()-3)&", "&INDEX(Entries!$P$2:$P$51,ROW()-3))} -> Norway, Netherlands, Switzerland, Italy, Finland, Poland, Spain, Ukraine | N12: =IF(I12="",999999999,J12*-1000000+L12) -> -650999973
B13: =IFERROR(__xludf.DUMMYFUNCTION("""COMPUTED_VALUE"""),10.0) -> 10 | C13: =IFERROR(__xludf.DUMMYFUNCTION("""COMPUTED_VALUE"""),"Molly ") -> Molly | D13: =IFERROR(__xludf.DUMMYFUNCTION("""COMPUTED_VALUE"""),645.0) -> 645 | E13: =IFERROR(__xludf.DUMMYFUNCTION("""COMPUTED_VALUE"""),26.0) -> 26 | F13: =IFERROR(__xludf.DUMMYFUNCTION("""COMPUTED_VALUE"""),26.0) -> 26 | G13: =IFERROR(__xludf.DUMMYFUNCTION("""COMPUTED_VALUE"""),"Norway, Austria, Netherlands, Italy, Finland, Great Britain, Kazakhstan, Ukraine") -> Norway, Austria, Netherlands, Italy, Finland, Great Britain, Kazakhstan, Ukraine | I13: {=IFERROR(INDEX(Entries!$E$2:$E$50,ROW()-3)&"","")} -> Pat Doherty | J13: =IF(I13="","",SUMIF('Team Scores'!$O$2:$O$401,I13,'Team Scores'!$AA$2:$AA$401)) -> 621 | K13: {=IF(I13="","",IFERROR(INDEX(Entries!$L$2:$L$50,ROW()-3),0))} -> 52 | L13: =IF(I13="","",ABS(K13-$F$2)) -> 52 | M13: {=IF(I13="","",INDEX(Entries!$F$2:$F$51,ROW()-3)&", "&INDEX(Entries!$M$2:$M$51,ROW()-3)&", "&INDEX(Entries!$N$2:$N$51,ROW()-3)&", "&INDEX(Entries!$H$2:$H$51,ROW()-3)&", "&INDEX(Entries!$I$2:$I$51,ROW()-3)&", "&INDEX(Entries!$J$2:$J$51,ROW()-3)&", "&INDEX(Entries!$O$2:$O$51,ROW()-3)&", "&INDEX(Entries!$P$2:$P$51,ROW()-3))} -> Norway, Netherlands, Switzerland, Italy, Finland, Great Britain, Belgium, Hungary | N13: =IF(I13="",999999999,J13*-1000000+L13) -> -620999948
A14: View Live Medal Table | B14: =IFERROR(__xludf.DUMMYFUNCTION("""COMPUTED_VALUE"""),11.0) -> 11 | C14: =IFERROR(__xludf.DUMMYFUNCTION("""COMPUTED_VALUE"""),"SilkMaster420") -> SilkMaster420 | D14: =IFERROR(__xludf.DUMMYFUNCTION("""COMPUTED_VALUE"""),623.0) -> 623 | E14: =IFERROR(__xludf.DUMMYFUNCTION("""COMPUTED_VALUE"""),45.0) -> 45 | F14: =IFERROR(__xludf.DUMMYFUNCTION("""COMPUTED_VALUE"""),45.0) -> 45 | G14: =IFERROR(__xludf.DUMMYFUNCTION("""COMPUTED_VALUE"""),"Norway, Netherlands, Sweden, Italy, Finland, Poland, Bulgaria, Denmark") -> Norway, Netherlands, Sweden, Italy, Finland, Poland, Bulgaria, Denmark | I14: {=IFERROR(INDEX(Entries!$E$2:$E$50,ROW()-3)&"","")} -> Reb | J14: =IF(I14="","",SUMIF('Team Scores'!$O$2:$O$401,I14,'Team Scores'!$AA$2:$AA$401)) -> 680 | K14: {=IF(I14="","",IFERROR(INDEX(Entries!$L$2:$L$50,ROW()-3),0))} -> 65 | L14: =IF(I14="","",ABS(K14-$F$2)) -> 65 | M14: {=IF(I14="","",INDEX(Entries!$F$2:$F$51,ROW()-3)&", "&INDEX(Entries!$M$2:$M$51,ROW()-3)&", "&INDEX(Entries!$N$2:$N$51,ROW()-3)&", "&INDEX(Entries!$H$2:$H$51,ROW()-3)&", "&INDEX(Entries!$I$2:$I$51,ROW()-3)&", "&INDEX(Entries!$J$2:$J$51,ROW()-3)&", "&INDEX(Entries!$O$2:$O$51,ROW()-3)&", "&INDEX(Entries!$P$2:$P$51,ROW()-3))} -> Germany, Netherlands, Sweden, Italy, Czech Republic, Great Britain, Denmark, Kazakhstan | N14: =IF(I14="",999999999,J14*-1000000+L14) -> -679999935
B15: =IFERROR(__xludf.DUMMYFUNCTION("""COMPUTED_VALUE"""),12.0) -> 12 | C15: =IFERROR(__xludf.DUMMYFUNCTION("""COMPUTED_VALUE"""),"Pat Doherty") -> Pat Doherty | D15: =IFERROR(__xludf.DUMMYFUNCTION("""COMPUTED_VALUE"""),621.0) -> 621 | E15: =IFERROR(__xludf.DUMMYFUNCTION("""COMPUTED_VALUE"""),52.0) -> 52 | F15: =IFERROR(__xludf.DUMMYFUNCTION("""COMPUTED_VALUE"""),52.0) -> 52 | G15: =IFERROR(__xludf.DUMMYFUNCTION("""COMPUTED_VALUE"""),"Norway, Netherlands, Switzerland, Italy, Finland, Great Britain, Belgium, Hungary") -> Norway, Netherlands, Switzerland, Italy, Finland, Great Britain, Belgium, Hungary | I15: {=IFERROR(INDEX(Entries!$E$2:$E$50,ROW()-3)&"","")} -> Siri | J15: =IF(I15="","",SUMIF('Team Scores'!$O$2:$O$401,I15,'Team Scores'!$AA$2:$AA$401)) -> 550 | K15: {=IF(I15="","",IFERROR(INDEX(Entries!$L$2:$L$50,ROW()-3),0))} -> 67 | L15: =IF(I15="","",ABS(K15-$F$2)) -> 67 | M15: {=IF(I15="","",INDEX(Entries!$F$2:$F$51,ROW()-3)&", "&INDEX(Entries!$M$2:$M$51,ROW()-3)&", "&INDEX(Entries!$N$2:$N$51,ROW()-3)&", "&INDEX(Entries!$H$2:$H$51,ROW()-3)&", "&INDEX(Entries!$I$2:$I$51,ROW()-3)&", "&INDEX(Entries!$J$2:$J$51,ROW()-3)&", "&INDEX(Entries!$O$2:$O$51,ROW()-3)&", "&INDEX(Entries!$P$2:$P$51,ROW()-3))} -> United States, Netherlands, Switzerland, China, Finland, Poland, New Zealand, Ukraine | N15: =IF(I15="",999999999,J15*-1000000+L15) -> -549999933
B16: =IFERROR(__xludf.DUMMYFUNCTION("""COMPUTED_VALUE"""),13.0) -> 13 | C16: =IFERROR(__xludf.DUMMYFUNCTION("""COMPUTED_VALUE"""),"bgreen") -> bgreen | D16: =IFERROR(__xludf.DUMMYFUNCTION("""COMPUTED_VALUE"""),611.0) -> 611 | E16: =IFERROR(__xludf.DUMMYFUNCTION("""COMPUTED_VALUE"""),29.0) -> 29 | F16: =IFERROR(__xludf.DUMMYFUNCTION("""COMPUTED_VALUE"""),29.0) -> 29 | G16: =IFERROR(__xludf.DUMMYFUNCTION("""COMPUTED_VALUE"""),"Norway, Austria, Sweden, Italy, Finland, Great Britain, Estonia, Ukraine") -> Norway, Austria, Sweden, Italy, Finland, Great Britain, Estonia, Ukraine | I16: {=IFERROR(INDEX(Entries!$E$2:$E$50,ROW()-3)&"","")} -> SilkMaster420 | J16: =IF(I16="","",SUMIF('Team Scores'!$O$2:$O$401,I16,'Team Scores'!$AA$2:$AA$401)) -> 623 | K16: {=IF(I16="","",IFERROR(INDEX(Entries!$L$2:$L$50,ROW()-3),0))} -> 45 | L16: =IF(I16="","",ABS(K16-$F$2)) -> 45 | M16: {=IF(I16="","",INDEX(Entries!$F$2:$F$51,ROW()-3)&", "&INDEX(Entries!$M$2:$M$51,ROW()-3)&", "&INDEX(Entries!$N$2:$N$51,ROW()-3)&", "&INDEX(Entries!$H$2:$H$51,ROW()-3)&", "&INDEX(Entries!$I$2:$I$51,ROW()-3)&", "&INDEX(Entries!$J$2:$J$51,ROW()-3)&", "&INDEX(Entries!$O$2:$O$51,ROW()-3)&", "&INDEX(Entries!$P$2:$P$51,ROW()-3))} -> Norway, Netherlands, Sweden, Italy, Finland, Poland, Bulgaria, Denmark | N16: =IF(I16="",999999999,J16*-1000000+L16) -> -622999955
B17: =IFERROR(__xludf.DUMMYFUNCTION("""COMPUTED_VALUE"""),14.0) -> 14 | C17: =IFERROR(__xludf.DUMMYFUNCTION("""COMPUTED_VALUE"""),"Jack Jansen") -> Jack Jansen | D17: =IFERROR(__xludf.DUMMYFUNCTION("""COMPUTED_VALUE"""),582.0) -> 582 | E17: =IFERROR(__xludf.DUMMYFUNCTION("""COMPUTED_VALUE"""),52.0) -> 52 | F17: =IFERROR(__xludf.DUMMYFUNCTION("""COMPUTED_VALUE"""),19.0) -> 19 | G17: =IFERROR(__xludf.DUMMYFUNCTION("""COMPUTED_VALUE"""),"Norway, Netherlands, Sweden, Japan, Czech Republic, Poland, Belgium, Denmark") -> Norway, Netherlands, Sweden, Japan, Czech Republic, Poland, Belgium, Denmark | I17: {=IFERROR(INDEX(Entries!$E$2:$E$50,ROW()-3)&"","")} -> A taco93 | J17: =IF(I17="","",SUMIF('Team Scores'!$O$2:$O$401,I17,'Team Scores'!$AA$2:$AA$401)) -> 646 | K17: {=IF(I17="","",IFERROR(INDEX(Entries!$L$2:$L$50,ROW()-3),0))} -> 27 | L17: =IF(I17="","",ABS(K17-$F$2)) -> 27 | M17: {=IF(I17="","",INDEX(Entries!$F$2:$F$51,ROW()-3)&", "&INDEX(Entries!$M$2:$M$51,ROW()-3)&", "&INDEX(Entries!$N$2:$N$51,ROW()-3)&", "&INDEX(Entries!$H$2:$H$51,ROW()-3)&", "&INDEX(Entries!$I$2:$I$51,ROW()-3)&", "&INDEX(Entries!$J$2:$J$51,ROW()-3)&", "&INDEX(Entries!$O$2:$O$51,ROW()-3)&", "&INDEX(Entries!$P$2:$P$51,ROW()-3))} -> United States, Sweden, Switzerland, China, Finland, Australia, Estonia, New Zealand | N17: =IF(I17="",999999999,J17*-1000000+L17) -> -645999973
B18: =IFERROR(__xludf.DUMMYFUNCTION("""COMPUTED_VALUE"""),15.0) -> 15 | C18: =IFERROR(__xludf.DUMMYFUNCTION("""COMPUTED_VALUE"""),"Jennie") -> Jennie | D18: =IFERROR(__xludf.DUMMYFUNCTION("""COMPUTED_VALUE"""),571.0) -> 571 | E18: =IFERROR(__xludf.DUMMYFUNCTION("""COMPUTED_VALUE"""),25.0) -> 25 | F18: =IFERROR(__xludf.DUMMYFUNCTION("""COMPUTED_VALUE"""),25.0) -> 25 | G18: =IFERROR(__xludf.DUMMYFUNCTION("""COMPUTED_VALUE"""),"United States, Austria, Sweden, Italy, Finland, Australia, Croatia, Ukraine") -> United States, Austria, Sweden, Italy, Finland, Australia, Croatia, Ukraine | I18: {=IFERROR(INDEX(Entries!$E$2:$E$50,ROW()-3)&"","")} -> Mark Mattson | J18: =IF(I18="","",SUMIF('Team Scores'!$O$2:$O$401,I18,'Team Scores'!$AA$2:$AA$401)) -> 647 | K18: {=IF(I18="","",IFERROR(INDEX(Entries!$L$2:$L$50,ROW()-3),0))} -> 27 | L18: =IF(I18="","",ABS(K18-$F$2)) -> 27 | M18: {=IF(I18="","",INDEX(Entries!$F$2:$F$51,ROW()-3)&", "&INDEX(Entries!$M$2:$M$51,ROW()-3)&", "&INDEX(Entries!$N$2:$N$51,ROW()-3)&", "&INDEX(Entries!$H$2:$H$51,ROW()-3)&", "&INDEX(Entries!$I$2:$I$51,ROW()-3)&", "&INDEX(Entries!$J$2:$J$51,ROW()-3)&", "&INDEX(Entries!$O$2:$O$51,ROW()-3)&", "&INDEX(Entries!$P$2:$P$51,ROW()-3))} -> United States, Netherlands, Sweden, Italy, Czech Republic, Poland, Ireland, Spain | N18: =IF(I18="",999999999,J18*-1000000+L18) -> -646999973
B19: =IFERROR(__xludf.DUMMYFUNCTION("""COMPUTED_VALUE"""),16.0) -> 16 | C19: =IFERROR(__xludf.DUMMYFUNCTION("""COMPUTED_VALUE"""),"Charlie ") -> Charlie | D19: =IFERROR(__xludf.DUMMYFUNCTION("""COMPUTED_VALUE"""),570.0) -> 570 | E19: =IFERROR(__xludf.DUMMYFUNCTION("""COMPUTED_VALUE"""),29.0) -> 29 | F19: =IFERROR(__xludf.DUMMYFUNCTION("""COMPUTED_VALUE"""),29.0) -> 29 | G19: =IFERROR(__xludf.DUMMYFUNCTION("""COMPUTED_VALUE"""),"Norway, Austria, Sweden, Japan, Czech Republic, Australia, Chile, Chinese Taipei") -> Norway, Austria, Sweden, Japan, Czech Republic, Australia, Chile, Chinese Taipei | I19: {=IFERROR(INDEX(Entries!$E$2:$E$50,ROW()-3)&"","")} -> Tate McRae | J19: =IF(I19="","",SUMIF('Team Scores'!$O$2:$O$401,I19,'Team Scores'!$AA$2:$AA$401)) -> 470 | K19: {=IF(I19="","",IFERROR(INDEX(Entries!$L$2:$L$50,ROW()-3),0))} -> 23 | L19: =IF(I19="","",ABS(K19-$F$2)) -> 23 | M19: {=IF(I19="","",INDEX(Entries!$F$2:$F$51,ROW()-3)&", "&INDEX(Entries!$M$2:$M$51,ROW()-3)&", "&INDEX(Entries!$N$2:$N$51,ROW()-3)&", "&INDEX(Entries!$H$2:$H$51,ROW()-3)&", "&INDEX(Entries!$I$2:$I$51,ROW()-3)&", "&INDEX(Entries!$J$2:$J$51,ROW()-3)&", "&INDEX(Entries!$O$2:$O$51,ROW()-3)&", "&INDEX(Entries!$P$2:$P$51,ROW()-3))} -> United States, France, Sweden, Japan, Finland, Slovakia, Kazakhstan, Ukraine | N19: =IF(I19="",999999999,J19*-1000000+L19) -> -469999977
B20: =IFERROR(__xludf.DUMMYFUNCTION("""COMPUTED_VALUE"""),17.0) -> 17 | C20: =IFERROR(__xludf.DUMMYFUNCTION("""COMPUTED_VALUE"""),"kborst13") -> kborst13 | D20: =IFERROR(__xludf.DUMMYFUNCTION("""COMPUTED_VALUE"""),564.0) -> 564 | E20: =IFERROR(__xludf.DUMMYFUNCTION("""COMPUTED_VALUE"""),47.0) -> 47 | F20: =IFERROR(__xludf.DUMMYFUNCTION("""COMPUTED_VALUE"""),47.0) -> 47 | G20: =IFERROR(__xludf.DUMMYFUNCTION("""COMPUTED_VALUE"""),"Norway, Austria, Netherlands, China, Finland, Great Britain, Belgium, Estonia") -> Norway, Austria, Netherlands, China, Finland, Great Britain, Belgium, Estonia | I20: {=IFERROR(INDEX(Entries!$E$2:$E$50,ROW()-3)&"","")} -> LucasF | J20: =IF(I20="","",SUMIF('Team Scores'!$O$2:$O$401,I20,'Team Scores'!$AA$2:$AA$401)) -> 762 | K20: {=IF(I20="","",IFERROR(INDEX(Entries!$L$2:$L$50,ROW()-3),0))} -> 50 | L20: =IF(I20="","",ABS(K20-$F$2)) -> 50 | M20: {=IF(I20="","",INDEX(Entries!$F$2:$F$51,ROW()-3)&", "&INDEX(Entries!$M$2:$M$51,ROW()-3)&", "&INDEX(Entries!$N$2:$N$51,ROW()-3)&", "&INDEX(Entries!$H$2:$H$51,ROW()-3)&", "&INDEX(Entries!$I$2:$I$51,ROW()-3)&", "&INDEX(Entries!$J$2:$J$51,ROW()-3)&", "&INDEX(Entries!$O$2:$O$51,ROW()-3)&", "&INDEX(Entries!$P$2:$P$51,ROW()-3))} -> Germany, Austria, Switzerland, Italy, Finland, Australia, New Zealand, Spain | N20: =IF(I20="",999999999,J20*-1000000+L20) -> -761999950
B21: =IFERROR(__xludf.DUMMYFUNCTION("""COMPUTED_VALUE"""),18.0) -> 18 | C21: =IFERROR(__xludf.DUMMYFUNCTION("""COMPUTED_VALUE"""),"Siri") -> Siri | D21: =IFERROR(__xludf.DUMMYFUNCTION("""COMPUTED_VALUE"""),550.0) -> 550 | E21: =IFERROR(__xludf.DUMMYFUNCTION("""COMPUTED_VALUE"""),67.0) -> 67 | F21: =IFERROR(__xludf.DUMMYFUNCTION("""COMPUTED_VALUE"""),67.0) -> 67 | G21: =IFERROR(__xludf.DUMMYFUNCTION("""COMPUTED_VALUE"""),"United States, Netherlands, Switzerland, China, Finland, Poland, New Zealand, Ukraine") -> United States, Netherlands, Switzerland, China, Finland, Poland, New Zealand, Ukraine | I21: {=IFERROR(INDEX(Entries!$E$2:$E$50,ROW()-3)&"","")} -> Bryan Jakobsze🇵🇱 | J21: =IF(I21="","",SUMIF('Team Scores'!$O$2:$O$401,I21,'Team Scores'!$AA$2:$AA$401)) -> 669 | K21: {=IF(I21="","",IFERROR(INDEX(Entries!$L$2:$L$50,ROW()-3),0))} -> 29 | L21: =IF(I21="","",ABS(K21-$F$2)) -> 29 | M21: {=IF(I21="","",INDEX(Entries!$F$2:$F$51,ROW()-3)&", "&INDEX(Entries!$M$2:$M$51,ROW()-3)&", "&INDEX(Entries!$N$2:$N$51,ROW()-3)&", "&INDEX(Entries!$H$2:$H$51,ROW()-3)&", "&INDEX(Entries!$I$2:$I$51,ROW()-3)&", "&INDEX(Entries!$J$2:$J$51,ROW()-3)&", "&INDEX(Entries!$O$2:$O$51,ROW()-3)&", "&INDEX(Entries!$P$2:$P$51,ROW()-3))} -> Norway, France, Netherlands, Italy, Finland, Great Britain, Kazakhstan, Ukraine | N21: =IF(I21="",999999999,J21*-1000000+L21) -> -668999971
B22: =IFERROR(__xludf.DUMMYFUNCTION("""COMPUTED_VALUE"""),19.0) -> 19 | C22: =IFERROR(__xludf.DUMMYFUNCTION("""COMPUTED_VALUE"""),"Wyatt") -> Wyatt | D22: =IFERROR(__xludf.DUMMYFUNCTION("""COMPUTED_VALUE"""),497.0) -> 497 | E22: =IFERROR(__xludf.DUMMYFUNCTION("""COMPUTED_VALUE"""),27.0) -> 27 | F22: =IFERROR(__xludf.DUMMYFUNCTION("""COMPUTED_VALUE"""),6.0) -> 6 | G22: =IFERROR(__xludf.DUMMYFUNCTION("""COMPUTED_VALUE"""),"Canada, Austria, Netherlands, China, Czech Republic, Australia, Croatia, Ukraine") -> Canada, Austria, Netherlands, China, Czech Republic, Australia, Croatia, Ukraine | I22: {=IFERROR(INDEX(Entries!$E$2:$E$50,ROW()-3)&"","")} -> Wicks | J22: =IF(I22="","",SUMIF('Team Scores'!$O$2:$O$401,I22,'Team Scores'!$AA$2:$AA$401)) -> 458 | K22: {=IF(I22="","",IFERROR(INDEX(Entries!$L$2:$L$50,ROW()-3),0))} -> 26 | L22: =IF(I22="","",ABS(K22-$F$2)) -> 26 | M22: {=IF(I22="","",INDEX(Entries!$F$2:$F$51,ROW()-3)&", "&INDEX(Entries!$M$2:$M$51,ROW()-3)&", "&INDEX(Entries!$N$2:$N$51,ROW()-3)&", "&INDEX(Entries!$H$2:$H$51,ROW()-3)&", "&INDEX(Entries!$I$2:$I$51,ROW()-3)&", "&INDEX(Entries!$J$2:$J$51,ROW()-3)&", "&INDEX(Entries!$O$2:$O$51,ROW()-3)&", "&INDEX(Entries!$P$2:$P$51,ROW()-3))} -> Norway, Netherlands, South Korea, Japan, Finland, Poland, Croatia, Israel | N22: =IF(I22="",999999999,J22*-1000000+L22) -> -457999974
B23: =IFERROR(__xludf.DUMMYFUNCTION("""COMPUTED_VALUE"""),20.0) -> 20 | C23: =IFERROR(__xludf.DUMMYFUNCTION("""COMPUTED_VALUE"""),"Tate McRae ") -> Tate McRae | D23: =IFERROR(__xludf.DUMMYFUNCTION("""COMPUTED_VALUE"""),470.0) -> 470 | E23: =IFERROR(__xludf.DUMMYFUNCTION("""COMPUTED_VALUE"""),23.0) -> 23 | F23: =IFERROR(__xludf.DUMMYFUNCTION("""COMPUTED_VALUE"""),23.0) -> 23 | G23: =IFERROR(__xludf.DUMMYFUNCTION("""COMPUTED_VALUE"""),"United States, France, Sweden, Japan, Finland, Slovakia, Kazakhstan, Ukraine") -> United States, France, Sweden, Japan, Finland, Slovakia, Kazakhstan, Ukraine | I23: {=IFERROR(INDEX(Entries!$E$2:$E$50,ROW()-3)&"","")} -> Brad’s Cousin’s Cousin | J23: =IF(I23="","",SUMIF('Team Scores'!$O$2:$O$401,I23,'Team Scores'!$AA$2:$AA$401)) -> 741 | K23: {=IF(I23="","",IFERROR(INDEX(Entries!$L$2:$L$50,ROW()-3),0))} -> 25 | L23: =IF(I23="","",ABS(K23-$F$2)) -> 25 | M23: {=IF(I23="","",INDEX(Entries!$F$2:$F$51,ROW()-3)&", "&INDEX(Entries!$M$2:$M$51,ROW()-3)&", "&INDEX(Entries!$N$2:$N$51,ROW()-3)&", "&INDEX(Entries!$H$2:$H$51,ROW()-3)&", "&INDEX(Entries!$I$2:$I$51,ROW()-3)&", "&INDEX(Entries!$J$2:$J$51,ROW()-3)&", "&INDEX(Entries!$O$2:$O$51,ROW()-3)&", "&INDEX(Entries!$P$2:$P$51,ROW()-3))} -> Norway, Netherlands, Switzerland, Italy, Finland, Australia, Belgium, New Zealand | N23: =IF(I23="",999999999,J23*-1000000+L23) -> -740999975
B24: =IFERROR(__xludf.DUMMYFUNCTION("""COMPUTED_VALUE"""),21.0) -> 21 | C24: =IFERROR(__xludf.DUMMYFUNCTION("""COMPUTED_VALUE"""),"Josh’s Dawgs") -> Josh’s Dawgs | D24: =IFERROR(__xludf.DUMMYFUNCTION("""COMPUTED_VALUE"""),464.0) -> 464 | E24: =IFERROR(__xludf.DUMMYFUNCTION("""COMPUTED_VALUE"""),200.0) -> 200 | F24: =IFERROR(__xludf.DUMMYFUNCTION("""COMPUTED_VALUE"""),200.0) -> 200 | G24: =IFERROR(__xludf.DUMMYFUNCTION("""COMPUTED_VALUE"""),"United States, France, Sweden, China, Finland, Poland, Belgium, Ukraine") -> United States, France, Sweden, China, Finland, Poland, Belgium, Ukraine | I24: {=IFERROR(INDEX(Entries!$E$2:$E$50,ROW()-3)&"","")} -> Jennie | J24: =IF(I24="","",SUMIF('Team Scores'!$O$2:$O$401,I24,'Team Scores'!$AA$2:$AA$401)) -> 571 | K24: {=IF(I24="","",IFERROR(INDEX(Entries!$L$2:$L$50,ROW()-3),0))} -> 25 | L24: =IF(I24="","",ABS(K24-$F$2)) -> 25 | M24: {=IF(I24="","",INDEX(Entries!$F$2:$F$51,ROW()-3)&", "&INDEX(Entries!$M$2:$M$51,ROW()-3)&", "&INDEX(Entries!$N$2:$N$51,ROW()-3)&", "&INDEX(Entries!$H$2:$H$51,ROW()-3)&", "&INDEX(Entries!$I$2:$I$51,ROW()-3)&", "&INDEX(Entries!$J$2:$J$51,ROW()-3)&", "&INDEX(Entries!$O$2:$O$51,ROW()-3)&", "&INDEX(Entries!$P$2:$P$51,ROW()-3))} -> United States, Austria, Sweden, Italy, Finland, Australia, Croatia, Ukraine | N24: =IF(I24="",999999999,J24*-1000000+L24) -> -570999975
B25: =IFERROR(__xludf.DUMMYFUNCTION("""COMPUTED_VALUE"""),22.0) -> 22 | C25: =IFERROR(__xludf.DUMMYFUNCTION("""COMPUTED_VALUE"""),"Wicks") -> Wicks | D25: =IFERROR(__xludf.DUMMYFUNCTION("""COMPUTED_VALUE"""),458.0) -> 458 | E25: =IFERROR(__xludf.DUMMYFUNCTION("""COMPUTED_VALUE"""),26.0) -> 26 | F25: =IFERROR(__xludf.DUMMYFUNCTION("""COMPUTED_VALUE"""),26.0) -> 26 | G25: =IFERROR(__xludf.DUMMYFUNCTION("""COMPUTED_VALUE"""),"Norway, Netherlands, South Korea, Japan, Finland, Poland, Croatia, Israel") -> Norway, Netherlands, South Korea, Japan, Finland, Poland, Croatia, Israel | I25: {=IFERROR(INDEX(Entries!$E$2:$E$50,ROW()-3)&"","")} -> Molly | J25: =IF(I25="","",SUMIF('Team Scores'!$O$2:$O$401,I25,'Team Scores'!$AA$2:$AA$401)) -> 645 | K25: {=IF(I25="","",IFERROR(INDEX(Entries!$L$2:$L$50,ROW()-3),0))} -> 26 | L25: =IF(I25="","",ABS(K25-$F$2)) -> 26 | M25: {=IF(I25="","",INDEX(Entries!$F$2:$F$51,ROW()-3)&", "&INDEX(Entries!$M$2:$M$51,ROW()-3)&", "&INDEX(Entries!$N$2:$N$51,ROW()-3)&", "&INDEX(Entries!$H$2:$H$51,ROW()-3)&", "&INDEX(Entries!$I$2:$I$51,ROW()-3)&", "&INDEX(Entries!$J$2:$J$51,ROW()-3)&", "&INDEX(Entries!$O$2:$O$51,ROW()-3)&", "&INDEX(Entries!$P$2:$P$51,ROW()-3))} -> Norway, Austria, Netherlands, Italy, Finland, Great Britain, Kazakhstan, Ukraine | N25: =IF(I25="",999999999,J25*-1000000+L25) -> -644999974
B26: =IFERROR(__xludf.DUMMYFUNCTION("""COMPUTED_VALUE"""),23.0) -> 23 | C26: =IFERROR(__xludf.DUMMYFUNCTION("""COMPUTED_VALUE"""),"Jdrobny") -> Jdrobny | D26: =IFERROR(__xludf.DUMMYFUNCTION("""COMPUTED_VALUE"""),451.0) -> 451 | E26: =IFERROR(__xludf.DUMMYFUNCTION("""COMPUTED_VALUE"""),26.0) -> 26 | F26: =IFERROR(__xludf.DUMMYFUNCTION("""COMPUTED_VALUE"""),26.0) -> 26 | G26: =IFERROR(__xludf.DUMMYFUNCTION("""COMPUTED_VALUE"""),"Norway, South Korea, Sweden, Italy, Slovenia, Slovakia, Belgium, Ukraine") -> Norway, South Korea, Sweden, Italy, Slovenia, Slovakia, Belgium, Ukraine | I26: {=IFERROR(INDEX(Entries!$E$2:$E$50,ROW()-3)&"","")} -> Jdrobny | J26: =IF(I26="","",SUMIF('Team Scores'!$O$2:$O$401,I26,'Team Scores'!$AA$2:$AA$401)) -> 451 | K26: {=IF(I26="","",IFERROR(INDEX(Entries!$L$2:$L$50,ROW()-3),0))} -> 26 | L26: =IF(I26="","",ABS(K26-$F$2)) -> 26 | M26: {=IF(I26="","",INDEX(Entries!$F$2:$F$51,ROW()-3)&", "&INDEX(Entries!$M$2:$M$51,ROW()-3)&", "&INDEX(Entries!$N$2:$N$51,ROW()-3)&", "&INDEX(Entries!$H$2:$H$51,ROW()-3)&", "&INDEX(Entries!$I$2:$I$51,ROW()-3)&", "&INDEX(Entries!$J$2:$J$51,ROW()-3)&", "&INDEX(Entries!$O$2:$O$51,ROW()-3)&", "&INDEX(Entries!$P$2:$P$51,ROW()-3))} -> Norway, South Korea, Sweden, Italy, Slovenia, Slovakia, Belgium, Ukraine | N26: =IF(I26="",999999999,J26*-1000000+L26) -> -450999974
B27: =IFERROR(__xludf.DUMMYFUNCTION("""COMPUTED_VALUE"""),"") | C27: =IFERROR(__xludf.DUMMYFUNCTION("""COMPUTED_VALUE"""),"") | D27: =IFERROR(__xludf.DUMMYFUNCTION("""COMPUTED_VALUE"""),"") | E27: =IFERROR(__xludf.DUMMYFUNCTION("""COMPUTED_VALUE"""),"") | F27: =IFERROR(__xludf.DUMMYFUNCTION("""COMPUTED_VALUE"""),"") | G27: =IFERROR(__xludf.DUMMYFUNCTION("""COMPUTED_VALUE"""),"") | I27: {=IFERROR(INDEX(Entries!$E$2:$E$50,ROW()-3)&"","")} | J27: =IF(I27="","",SUMIF('Team Scores'!$O$2:$O$401,I27,'Team Scores'!$AA$2:$AA$401)) | K27: {=IF(I27="","",IFERROR(INDEX(Entries!$L$2:$L$50,ROW()-3),0))} | L27: =IF(I27="","",ABS(K27-$F$2)) | M27: {=IF(I27="","",INDEX(Entries!$F$2:$F$51,ROW()-3)&", "&INDEX(Entries!$M$2:$M$51,ROW()-3)&", "&INDEX(Entries!$N$2:$N$51,ROW()-3)&", "&INDEX(Entries!$H$2:$H$51,ROW()-3)&", "&INDEX(Entries!$I$2:$I$51,ROW()-3)&", "&INDEX(Entries!$J$2:$J$51,ROW()-3)&", "&INDEX(Entries!$O$2:$O$51,ROW()-3)&", "&INDEX(Entries!$P$2:$P$51,ROW()-3))} | N27: =IF(I27="",999999999,J27*-1000000+L27) -> 999999999
B28: =IFERROR(__xludf.DUMMYFUNCTION("""COMPUTED_VALUE"""),"") | C28: =IFERROR(__xludf.DUMMYFUNCTION("""COMPUTED_VALUE"""),"") | D28: =IFERROR(__xludf.DUMMYFUNCTION("""COMPUTED_VALUE"""),"") | E28: =IFERROR(__xludf.DUMMYFUNCTION("""COMPUTED_VALUE"""),"") | F28: =IFERROR(__xludf.DUMMYFUNCTION("""COMPUTED_VALUE"""),"") | G28: =IFERROR(__xludf.DUMMYFUNCTION("""COMPUTED_VALUE"""),"") | I28: {=IFERROR(INDEX(Entries!$E$2:$E$50,ROW()-3)&"","")} | J28: =IF(I28="","",SUMIF('Team Scores'!$O$2:$O$401,I28,'Team Scores'!$AA$2:$AA$401)) | K28: {=IF(I28="","",IFERROR(INDEX(Entries!$L$2:$L$50,ROW()-3),0))} | L28: =IF(I28="","",ABS(K28-$F$2)) | M28: {=IF(I28="","",INDEX(Entries!$F$2:$F$51,ROW()-3)&", "&INDEX(Entries!$M$2:$M$51,ROW()-3)&", "&INDEX(Entries!$N$2:$N$51,ROW()-3)&", "&INDEX(Entries!$H$2:$H$51,ROW()-3)&", "&INDEX(Entries!$I$2:$I$51,ROW()-3)&", "&INDEX(Entries!$J$2:$J$51,ROW()-3)&", "&INDEX(Entries!$O$2:$O$51,ROW()-3)&", "&INDEX(Entries!$P$2:$P$51,ROW()-3))} | N28: =IF(I28="",999999999,J28*-1000000+L28) -> 999999999
B29: =IFERROR(__xludf.DUMMYFUNCTION("""COMPUTED_VALUE"""),"") | C29: =IFERROR(__xludf.DUMMYFUNCTION("""COMPUTED_VALUE"""),"") | D29: =IFERROR(__xludf.DUMMYFUNCTION("""COMPUTED_VALUE"""),"") | E29: =IFERROR(__xludf.DUMMYFUNCTION("""COMPUTED_VALUE"""),"") | F29: =IFERROR(__xludf.DUMMYFUNCTION("""COMPUTED_VALUE"""),"") | G29: =IFERROR(__xludf.DUMMYFUNCTION("""COMPUTED_VALUE"""),"") | I29: {=IFERROR(INDEX(Entries!$E$2:$E$50,ROW()-3)&"","")} | J29: =IF(I29="","",SUMIF('Team Scores'!$O$2:$O$401,I29,'Team Scores'!$AA$2:$AA$401)) | K29: {=IF(I29="","",IFERROR(INDEX(Entries!$L$2:$L$50,ROW()-3),0))} | L29: =IF(I29="","",ABS(K29-$F$2)) | M29: {=IF(I29="","",INDEX(Entries!$F$2:$F$51,ROW()-3)&", "&INDEX(Entries!$M$2:$M$51,ROW()-3)&", "&INDEX(Entries!$N$2:$N$51,ROW()-3)&", "&INDEX(Entries!$H$2:$H$51,ROW()-3)&", "&INDEX(Entries!$I$2:$I$51,ROW()-3)&", "&INDEX(Entries!$J$2:$J$51,ROW()-3)&", "&INDEX(Entries!$O$2:$O$51,ROW()-3)&", "&INDEX(Entries!$P$2:$P$51,ROW()-3))} | N29: =IF(I29="",999999999,J29*-1000000+L29) -> 999999999
B30: =IFERROR(__xludf.DUMMYFUNCTION("""COMPUTED_VALUE"""),"") | C30: =IFERROR(__xludf.DUMMYFUNCTION("""COMPUTED_VALUE"""),"") | D30: =IFERROR(__xludf.DUMMYFUNCTION("""COMPUTED_VALUE"""),"") | E30: =IFERROR(__xludf.DUMMYFUNCTION("""COMPUTED_VALUE"""),"") | F30: =IFERROR(__xludf.DUMMYFUNCTION("""COMPUTED_VALUE"""),"") | G30: =IFERROR(__xludf.DUMMYFUNCTION("""COMPUTED_VALUE"""),"") | I30: {=IFERROR(INDEX(Entries!$E$2:$E$50,ROW()-3)&"","")} | J30: =IF(I30="","",SUMIF('Team Scores'!$O$2:$O$401,I30,'Team Scores'!$AA$2:$AA$401)) | K30: {=IF(I30="","",IFERROR(INDEX(Entries!$L$2:$L$50,ROW()-3),0))} | L30: =IF(I30="","",ABS(K30-$F$2)) | M30: {=IF(I30="","",INDEX(Entries!$F$2:$F$51,ROW()-3)&", "&INDEX(Entries!$M$2:$M$51,ROW()-3)&", "&INDEX(Entries!$N$2:$N$51,ROW()-3)&", "&INDEX(Entries!$H$2:$H$51,ROW()-3)&", "&INDEX(Entries!$I$2:$I$51,ROW()-3)&", "&INDEX(Entries!$J$2:$J$51,ROW()-3)&", "&INDEX(Entries!$O$2:$O$51,ROW()-3)&", "&INDEX(Entries!$P$2:$P$51,ROW()-3))} | N30: =IF(I30="",999999999,J30*-1000000+L30) -> 999999999
B31: =IFERROR(__xludf.DUMMYFUNCTION("""COMPUTED_VALUE"""),"") | C31: =IFERROR(__xludf.DUMMYFUNCTION("""COMPUTED_VALUE"""),"") | D31: =IFERROR(__xludf.DUMMYFUNCTION("""COMPUTED_VALUE"""),"") | E31: =IFERROR(__xludf.DUMMYFUNCTION("""COMPUTED_VALUE"""),"") | F31: =IFERROR(__xludf.DUMMYFUNCTION("""COMPUTED_VALUE"""),"") | G31: =IFERROR(__xludf.DUMMYFUNCTION("""COMPUTED_VALUE"""),"") | I31: {=IFERROR(INDEX(Entries!$E$2:$E$50,ROW()-3)&"","")} | J31: =IF(I31="","",SUMIF('Team Scores'!$O$2:$O$401,I31,'Team Scores'!$AA$2:$AA$401)) | K31: {=IF(I31="","",IFERROR(INDEX(Entries!$L$2:$L$50,ROW()-3),0))} | L31: =IF(I31="","",ABS(K31-$F$2)) | M31: {=IF(I31="","",INDEX(Entries!$F$2:$F$51,ROW()-3)&", "&INDEX(Entries!$M$2:$M$51,ROW()-3)&", "&INDEX(Entries!$N$2:$N$51,ROW()-3)&", "&INDEX(Entries!$H$2:$H$51,ROW()-3)&", "&INDEX(Entries!$I$2:$I$51,ROW()-3)&", "&INDEX(Entries!$J$2:$J$51,ROW()-3)&", "&INDEX(Entries!$O$2:$O$51,ROW()-3)&", "&INDEX(Entries!$P$2:$P$51,ROW()-3))} | N31: =IF(I31="",999999999,J31*-1000000+L31) -> 999999999
B32: =IFERROR(__xludf.DUMMYFUNCTION("""COMPUTED_VALUE"""),"") | C32: =IFERROR(__xludf.DUMMYFUNCTION("""COMPUTED_VALUE"""),"") | D32: =IFERROR(__xludf.DUMMYFUNCTION("""COMPUTED_VALUE"""),"") | E32: =IFERROR(__xludf.DUMMYFUNCTION("""COMPUTED_VALUE"""),"") | F32: =IFERROR(__xludf.DUMMYFUNCTION("""COMPUTED_VALUE"""),"") | G32: =IFERROR(__xludf.DUMMYFUNCTION("""COMPUTED_VALUE"""),"") | I32: {=IFERROR(INDEX(Entries!$E$2:$E$50,ROW()-3)&"","")} | J32: =IF(I32="","",SUMIF('Team Scores'!$O$2:$O$401,I32,'Team Scores'!$AA$2:$AA$401)) | K32: {=IF(I32="","",IFERROR(INDEX(Entries!$L$2:$L$50,ROW()-3),0))} | L32: =IF(I32="","",ABS(K32-$F$2)) | M32: {=IF(I32="","",INDEX(Entries!$F$2:$F$51,ROW()-3)&", "&INDEX(Entries!$M$2:$M$51,ROW()-3)&", "&INDEX(Entries!$N$2:$N$51,ROW()-3)&", "&INDEX(Entries!$H$2:$H$51,ROW()-3)&", "&INDEX(Entries!$I$2:$I$51,ROW()-3)&", "&INDEX(Entries!$J$2:$J$51,ROW()-3)&", "&INDEX(Entries!$O$2:$O$51,ROW()-3)&", "&INDEX(Entries!$P$2:$P$51,ROW()-3))} | N32: =IF(I32="",999999999,J32*-1000000+L32) -> 999999999
B33: =IFERROR(__xludf.DUMMYFUNCTION("""COMPUTED_VALUE"""),"") | C33: =IFERROR(__xludf.DUMMYFUNCTION("""COMPUTED_VALUE"""),"") | D33: =IFERROR(__xludf.DUMMYFUNCTION("""COMPUTED_VALUE"""),"") | E33: =IFERROR(__xludf.DUMMYFUNCTION("""COMPUTED_VALUE"""),"") | F33: =IFERROR(__xludf.DUMMYFUNCTION("""COMPUTED_VALUE"""),"") | G33: =IFERROR(__xludf.DUMMYFUNCTION("""COMPUTED_VALUE"""),"") | I33: {=IFERROR(INDEX(Entries!$E$2:$E$50,ROW()-3)&"","")} | J33: =IF(I33="","",SUMIF('Team Scores'!$O$2:$O$401,I33,'Team Scores'!$AA$2:$AA$401)) | K33: {=IF(I33="","",IFERROR(INDEX(Entries!$L$2:$L$50,ROW()-3),0))} | L33: =IF(I33="","",ABS(K33-$F$2)) | M33: {=IF(I33="","",INDEX(Entries!$F$2:$F$51,ROW()-3)&", "&INDEX(Entries!$M$2:$M$51,ROW()-3)&", "&INDEX(Entries!$N$2:$N$51,ROW()-3)&", "&INDEX(Entries!$H$2:$H$51,ROW()-3)&", "&INDEX(Entries!$I$2:$I$51,ROW()-3)&", "&INDEX(Entries!$J$2:$J$51,ROW()-3)&", "&INDEX(Entries!$O$2:$O$51,ROW()-3)&", "&INDEX(Entries!$P$2:$P$51,ROW()-3))} | N33: =IF(I33="",999999999,J33*-1000000+L33) -> 999999999

Sheet Team Scores
N1: PlayerID | O1: DisplayName | P1: PickSlot | Q1: Tier | R1: CountryName | S1: IOC | T1: Multiplier | U1: Gold | V1: Silver | W1: Bronze | X1: GoldPts | Y1: SilverPts | Z1: BronzePts | AA1: TotalPts | AB1: IsValid
D2: Click here to change the team ⬇️ | G2: =IFERROR(__xludf.DUMMYFUNCTION("SORT(FILTER(Entries!$E$2:$E$100,Entries!$E$2:$E$100<>""""))"),"A taco93") -> A taco93 | H2: Scoring Table | N2: {=IFERROR(IF(INDEX(Entries!$C$2:$C$47,1)="","",INDEX(Entries!$Q$2:$Q$47,1)),"")} -> Brad_Hagstrom_King Towsk | O2: {=IF(N2="","",IFERROR(INDEX(Entries!$E$2:$E$47,1),""))} -> King Towsk | P2: =IF(N2="","","Tier1_Pick1") -> Tier1_Pick1 | Q2: =IF(N2="","",1) -> 1 | R2: {=IF(N2="","",IFERROR(INDEX(Entries!$F$2:$F$47,1),""))} -> Norway | S2: {=IF(R2="","",IFERROR(XLOOKUP(R2,'Live Medal Table'!$B$2:$B$94,'Live Medal Table'!$C$2:$C$94,"???"),"???"))} -> NOR | T2: {=IF(R2="",0,IFERROR(XLOOKUP(R2,'Live Medal Table'!$B$2:$B$94,'Live Medal Table'!$F$2:$F$94,0),0))} -> 1 | U2: {=IF(R2="",0,IFERROR(XLOOKUP(R2,'Live Medal Table'!$B$2:$B$94,'Live Medal Table'!$G$2:$G$94,0),0))} -> 18 | V2: {=IF(R2="",0,IFERROR(XLOOKUP(R2,'Live Medal Table'!$B$2:$B$94,'Live Medal Table'!$H$2:$H$94,0),0))} -> 12 | W2: {=IF(R2="",0,IFERROR(XLOOKUP(R2,'Live Medal Table'!$B$2:$B$94,'Live Medal Table'!$I$2:$I$94,0),0))} -> 11 | X2: =U2*3*T2 -> 54 | Y2: =V2*2*T2 -> 24 | Z2: =W2*1*T2 -> 11 | AA2: =X2+Y2+Z2 -> 89 | AB2: {=IF(R2="",FALSE,IFERROR(AND(ISNUMBER(MATCH(R2,'Live Medal Table'!$B$2:$B$94,0)),XLOOKUP(R2,'Live Medal Table'!$B$2:$B$94,Countries!$I$2:$I$72,FALSE)),FALSE))} -> FALSE
B3: Team -> | C3: SilkMaster420 | F3: {=XLOOKUP(C3,Entries!E:E,Entries!C:C)&" "&XLOOKUP(C3,Entries!E:E,Entries!D:D)} -> Ellis Johnson | G3: =IFERROR(__xludf.DUMMYFUNCTION("""COMPUTED_VALUE"""),"bgreen") -> bgreen | H3: Tier: | I3: Gold | J3: Silver | K3: Bronze | N3: {=IFERROR(IF(INDEX(Entries!$C$2:$C$47,1)="","",INDEX(Entries!$Q$2:$Q$47,1)),"")} -> Brad_Hagstrom_King Towsk | O3: {=IF(N3="","",IFERROR(INDEX(Entries!$E$2:$E$47,1),""))} -> King Towsk | P3: =IF(N3="","","Tier2_Pick1") -> Tier2_Pick1 | Q3: =IF(N3="","",2) -> 2 | R3: {=IF(N3="","",IFERROR(INDEX(Entries!$M$2:$M$47,1),""))} -> Austria | S3: {=IF(R3="","",IFERROR(XLOOKUP(R3,'Live Medal Table'!$B$2:$B$94,'Live Medal Table'!$C$2:$C$94,"???"),"???"))} -> AUT | T3: {=IF(R3="",0,IFERROR(XLOOKUP(R3,'Live Medal Table'!$B$2:$B$94,'Live Medal Table'!$F$2:$F$94,0),0))} -> 2 | U3: {=IF(R3="",0,IFERROR(XLOOKUP(R3,'Live Medal Table'!$B$2:$B$94,'Live Medal Table'!$G$2:$G$94,0),0))} -> 5 | V3: {=IF(R3="",0,IFERROR(XLOOKUP(R3,'Live Medal Table'!$B$2:$B$94,'Live Medal Table'!$H$2:$H$94,0),0))} -> 8 | W3: {=IF(R3="",0,IFERROR(XLOOKUP(R3,'Live Medal Table'!$B$2:$B$94,'Live Medal Table'!$I$2:$I$94,0),0))} -> 5 | X3: =U3*3*T3 -> 30 | Y3: =V3*2*T3 -> 32 | Z3: =W3*1*T3 -> 10 | AA3: =X3+Y3+Z3 -> 72 | AB3: {=IF(R3="",FALSE,IFERROR(AND(ISNUMBER(MATCH(R3,'Live Medal Table'!$B$2:$B$94,0)),XLOOKUP(R3,'Live Medal Table'!$B$2:$B$94,Countries!$I$2:$I$72,FALSE)),FALSE))} -> FALSE
B4: Countries Selected: | C4: Tier | D4: Points | E4: Flag | G4: =IFERROR(__xludf.DUMMYFUNCTION("""COMPUTED_VALUE"""),"Brad’s Cousin’s Cousin") -> Brad’s Cousin’s Cousin | H4: 1 | I4: 3 | J4: 2 | K4: 1 | N4: {=IFERROR(IF(INDEX(Entries!$C$2:$C$47,1)="","",INDEX(Entries!$Q$2:$Q$47,1)),"")} -> Brad_Hagstrom_King Towsk | O4: {=IF(N4="","",IFERROR(INDEX(Entries!$E$2:$E$47,1),""))} -> King Towsk | P4: =IF(N4="","","Tier2_Pick2") -> Tier2_Pick2 | Q4: =IF(N4="","",2) -> 2 | R4: {=IF(N4="","",IFERROR(INDEX(Entries!$N$2:$N$47,1),""))} -> Netherlands | S4: {=IF(R4="","",IFERROR(XLOOKUP(R4,'Live Medal Table'!$B$2:$B$94,'Live Medal Table'!$C$2:$C$94,"???"),"???"))} -> NED | T4: {=IF(R4="",0,IFERROR(XLOOKUP(R4,'Live Medal Table'!$B$2:$B$94,'Live Medal Table'!$F$2:$F$94,0),0))} -> 2 | U4: {=IF(R4="",0,IFERROR(XLOOKUP(R4,'Live Medal Table'!$B$2:$B$94,'Live Medal Table'!$G$2:$G$94,0),0))} -> 10 | V4: {=IF(R4="",0,IFERROR(XLOOKUP(R4,'Live Medal Table'!$B$2:$B$94,'Live Medal Table'!$H$2:$H$94,0),0))} -> 7 | W4: {=IF(R4="",0,IFERROR(XLOOKUP(R4,'Live Medal Table'!$B$2:$B$94,'Live Medal Table'!$I$2:$I$94,0),0))} -> 3 | X4: =U4*3*T4 -> 60 | Y4: =V4*2*T4 -> 28 | Z4: =W4*1*T4 -> 6 | AA4: =X4+Y4+Z4 -> 94 | AB4: {=IF(R4="",FALSE,IFERROR(AND(ISNUMBER(MATCH(R4,'Live Medal Table'!$B$2:$B$94,0)),XLOOKUP(R4,'Live Medal Table'!$B$2:$B$94,Countries!$I$2:$I$72,FALSE)),FALSE))} -> FALSE
B5: =IFERROR(__xludf.DUMMYFUNCTION("IFERROR(FILTER('Team Scores'!R:R, 'Team Scores'!O:O=$C$3), """")"),"Norway") -> Norway | C5: =IFERROR(__xludf.DUMMYFUNCTION("IFERROR(FILTER('Team Scores'!Q:Q, 'Team Scores'!O:O=$C$3), """")"),1.0) -> 1 | D5: =IFERROR(__xludf.DUMMYFUNCTION("IFERROR(FILTER('Team Scores'!AA:AA, 'Team Scores'!O:O=$C$3), """")"),89.0) -> 89 | E5: {=XLOOKUP(B5,'Live Medal Table'!N:N,'Live Medal Table'!X:X,"")} | G5: =IFERROR(__xludf.DUMMYFUNCTION("""COMPUTED_VALUE"""),"Bryan Jakobsze🇵🇱") -> Bryan Jakobsze🇵🇱 | H5: 2 | I5: 6 | J5: 4 | K5: 2 | N5: {=IFERROR(IF(INDEX(Entries!$C$2:$C$47,1)="","",INDEX(Entries!$Q$2:$Q$47,1)),"")} -> Brad_Hagstrom_King Towsk | O5: {=IF(N5="","",IFERROR(INDEX(Entries!$E$2:$E$47,1),""))} -> King Towsk | P5: =IF(N5="","","Tier3_Pick1") -> Tier3_Pick1 | Q5: =IF(N5="","",3) -> 3 | R5: {=IF(N5="","",IFERROR(INDEX(Entries!$H$2:$H$47,1),""))} -> Italy | S5: {=IF(R5="","",IFERROR(XLOOKUP(R5,'Live Medal Table'!$B$2:$B$94,'Live Medal Table'!$C$2:$C$94,"???"),"???"))} -> ITA | T5: {=IF(R5="",0,IFERROR(XLOOKUP(R5,'Live Medal Table'!$B$2:$B$94,'Live Medal Table'!$F$2:$F$94,0),0))} -> 3 | U5: {=IF(R5="",0,IFERROR(XLOOKUP(R5,'Live Medal Table'!$B$2:$B$94,'Live Medal Table'!$G$2:$G$94,0),0))} -> 10 | V5: {=IF(R5="",0,IFERROR(XLOOKUP(R5,'Live Medal Table'!$B$2:$B$94,'Live Medal Table'!$H$2:$H$94,0),0))} -> 6 | W5: {=IF(R5="",0,IFERROR(XLOOKUP(R5,'Live Medal Table'!$B$2:$B$94,'Live Medal Table'!$I$2:$I$94,0),0))} -> 14 | X5: =U5*3*T5 -> 90 | Y5: =V5*2*T5 -> 36 | Z5: =W5*1*T5 -> 42 | AA5: =X5+Y5+Z5 -> 168 | AB5: {=IF(R5="",FALSE,IFERROR(AND(ISNUMBER(MATCH(R5,'Live Medal Table'!$B$2:$B$94,0)),XLOOKUP(R5,'Live Medal Table'!$B$2:$B$94,Countries!$I$2:$I$72,FALSE)),FALSE))} -> FALSE
B6: =IFERROR(__xludf.DUMMYFUNCTION("""COMPUTED_VALUE"""),"Netherlands") -> Netherlands | C6: =IFERROR(__xludf.DUMMYFUNCTION("""COMPUTED_VALUE"""),2.0) -> 2 | D6: =IFERROR(__xludf.DUMMYFUNCTION("""COMPUTED_VALUE"""),94.0) -> 94 | E6: {=XLOOKUP(B6,'Live Medal Table'!N:N,'Live Medal Table'!X:X,"")} | G6: =IFERROR(__xludf.DUMMYFUNCTION("""COMPUTED_VALUE"""),"Charlie ") -> Charlie | H6: 3 | I6: 9 | J6: 6 | K6: 3 | N6: {=IFERROR(IF(INDEX(Entries!$C$2:$C$47,1)="","",INDEX(Entries!$Q$2:$Q$47,1)),"")} -> Brad_Hagstrom_King Towsk | O6: {=IF(N6="","",IFERROR(INDEX(Entries!$E$2:$E$47,1),""))} -> King Towsk | P6: =IF(N6="","","Tier4_Pick1") -> Tier4_Pick1 | Q6: =IF(N6="","",4) -> 4 | R6: {=IF(N6="","",IFERROR(INDEX(Entries!$I$2:$I$47,1),""))} -> Finland | S6: {=IF(R6="","",IFERROR(XLOOKUP(R6,'Live Medal Table'!$B$2:$B$94,'Live Medal Table'!$C$2:$C$94,"???"),"???"))} -> FIN | T6: {=IF(R6="",0,IFERROR(XLOOKUP(R6,'Live Medal Table'!$B$2:$B$94,'Live Medal Table'!$F$2:$F$94,0),0))} -> 6 | U6: {=IF(R6="",0,IFERROR(XLOOKUP(R6,'Live Medal Table'!$B$2:$B$94,'Live Medal Table'!$G$2:$G$94,0),0))} -> 0 | V6: {=IF(R6="",0,IFERROR(XLOOKUP(R6,'Live Medal Table'!$B$2:$B$94,'Live Medal Table'!$H$2:$H$94,0),0))} -> 1 | W6: {=IF(R6="",0,IFERROR(XLOOKUP(R6,'Live Medal Table'!$B$2:$B$94,'Live Medal Table'!$I$2:$I$94,0),0))} -> 5 | X6: =U6*3*T6 -> 0 | Y6: =V6*2*T6 -> 12 | Z6: =W6*1*T6 -> 30 | AA6: =X6+Y6+Z6 -> 42 | AB6: {=IF(R6="",FALSE,IFERROR(AND(ISNUMBER(MATCH(R6,'Live Medal Table'!$B$2:$B$94,0)),XLOOKUP(R6,'Live Medal Table'!$B$2:$B$94,Countries!$I$2:$I$72,FALSE)),FALSE))} -> FALSE
B7: =IFERROR(__xludf.DUMMYFUNCTION("""COMPUTED_VALUE"""),"Sweden") -> Sweden | C7: =IFERROR(__xludf.DUMMYFUNCTION("""COMPUTED_VALUE"""),2.0) -> 2 | D7: =IFERROR(__xludf.DUMMYFUNCTION("""COMPUTED_VALUE"""),80.0) -> 80 | E7: {=XLOOKUP(B7,'Live Medal Table'!N:N,'Live Medal Table'!X:X,"")} | G7: =IFERROR(__xludf.DUMMYFUNCTION("""COMPUTED_VALUE"""),"Jack Jansen") -> Jack Jansen | H7: 4 | I7: 18 | J7: 12 | K7: 6 | N7: {=IFERROR(IF(INDEX(Entries!$C$2:$C$47,1)="","",INDEX(Entries!$Q$2:$Q$47,1)),"")} -> Brad_Hagstrom_King Towsk | O7: {=IF(N7="","",IFERROR(INDEX(Entries!$E$2:$E$47,1),""))} -> King Towsk | P7: =IF(N7="","","Tier5_Pick1") -> Tier5_Pick1 | Q7: =IF(N7="","",5) -> 5 | R7: {=IF(N7="","",IFERROR(INDEX(Entries!$J$2:$J$47,1),""))} -> Australia | S7: {=IF(R7="","",IFERROR(XLOOKUP(R7,'Live Medal Table'!$B$2:$B$94,'Live Medal Table'!$C$2:$C$94,"???"),"???"))} -> AUS | T7: {=IF(R7="",0,IFERROR(XLOOKUP(R7,'Live Medal Table'!$B$2:$B$94,'Live Medal Table'!$F$2:$F$94,0),0))} -> 10 | U7: {=IF(R7="",0,IFERROR(XLOOKUP(R7,'Live Medal Table'!$B$2:$B$94,'Live Medal Table'!$G$2:$G$94,0),0))} -> 3 | V7: {=IF(R7="",0,IFERROR(XLOOKUP(R7,'Live Medal Table'!$B$2:$B$94,'Live Medal Table'!$H$2:$H$94,0),0))} -> 2 | W7: {=IF(R7="",0,IFERROR(XLOOKUP(R7,'Live Medal Table'!$B$2:$B$94,'Live Medal Table'!$I$2:$I$94,0),0))} -> 1 | X7: =U7*3*T7 -> 90 | Y7: =V7*2*T7 -> 40 | Z7: =W7*1*T7 -> 10 | AA7: =X7+Y7+Z7 -> 140 | AB7: {=IF(R7="",FALSE,IFERROR(AND(ISNUMBER(MATCH(R7,'Live Medal Table'!$B$2:$B$94,0)),XLOOKUP(R7,'Live Medal Table'!$B$2:$B$94,Countries!$I$2:$I$72,FALSE)),FALSE))} -> FALSE
B8: =IFERROR(__xludf.DUMMYFUNCTION("""COMPUTED_VALUE"""),"Italy") -> Italy | C8: =IFERROR(__xludf.DUMMYFUNCTION("""COMPUTED_VALUE"""),3.0) -> 3 | D8: =IFERROR(__xludf.DUMMYFUNCTION("""COMPUTED_VALUE"""),168.0) -> 168 | E8: {=XLOOKUP(B8,'Live Medal Table'!N:N,'Live Medal Table'!X:X,"")} | G8: =IFERROR(__xludf.DUMMYFUNCTION("""COMPUTED_VALUE"""),"Jdrobny") -> Jdrobny | H8: 5 | I8: 30 | J8: 20 | K8: 10 | N8: {=IFERROR(IF(INDEX(Entries!$C$2:$C$47,1)="","",INDEX(Entries!$Q$2:$Q$47,1)),"")} -> Brad_Hagstrom_King Towsk | O8: {=IF(N8="","",IFERROR(INDEX(Entries!$E$2:$E$47,1),""))} -> King Towsk | P8: =IF(N8="","","Tier6_Pick1") -> Tier6_Pick1 | Q8: =IF(N8="","",6) -> 6 | R8: {=IF(N8="","",IFERROR(INDEX(Entries!$O$2:$O$47,1),""))} -> New Zealand | S8: {=IF(R8="","",IFERROR(XLOOKUP(R8,'Live Medal Table'!$B$2:$B$94,'Live Medal Table'!$C$2:$C$94,"???"),"???"))} -> NZL | T8: {=IF(R8="",0,IFERROR(XLOOKUP(R8,'Live Medal Table'!$B$2:$B$94,'Live Medal Table'!$F$2:$F$94,0),0))} -> 20 | U8: {=IF(R8="",0,IFERROR(XLOOKUP(R8,'Live Medal Table'!$B$2:$B$94,'Live Medal Table'!$G$2:$G$94,0),0))} -> 0 | V8: {=IF(R8="",0,IFERROR(XLOOKUP(R8,'Live Medal Table'!$B$2:$B$94,'Live Medal Table'!$H$2:$H$94,0),0))} -> 2 | W8: {=IF(R8="",0,IFERROR(XLOOKUP(R8,'Live Medal Table'!$B$2:$B$94,'Live Medal Table'!$I$2:$I$94,0),0))} -> 1 | X8: =U8*3*T8 -> 0 | Y8: =V8*2*T8 -> 80 | Z8: =W8*1*T8 -> 20 | AA8: =X8+Y8+Z8 -> 100 | AB8: {=IF(R8="",FALSE,IFERROR(AND(ISNUMBER(MATCH(R8,'Live Medal Table'!$B$2:$B$94,0)),XLOOKUP(R8,'Live Medal Table'!$B$2:$B$94,Countries!$I$2:$I$72,FALSE)),FALSE))} -> FALSE
B9: =IFERROR(__xludf.DUMMYFUNCTION("""COMPUTED_VALUE"""),"Finland") -> Finland | C9: =IFERROR(__xludf.DUMMYFUNCTION("""COMPUTED_VALUE"""),4.0) -> 4 | D9: =IFERROR(__xludf.DUMMYFUNCTION("""COMPUTED_VALUE"""),42.0) -> 42 | E9: {=XLOOKUP(B9,'Live Medal Table'!N:N,'Live Medal Table'!X:X,"")} | G9: =IFERROR(__xludf.DUMMYFUNCTION("""COMPUTED_VALUE"""),"Jennie") -> Jennie | H9: 6 | I9: 60 | J9: 40 | K9: 20 | N9: {=IFERROR(IF(INDEX(Entries!$C$2:$C$47,1)="","",INDEX(Entries!$Q$2:$Q$47,1)),"")} -> Brad_Hagstrom_King Towsk | O9: {=IF(N9="","",IFERROR(INDEX(Entries!$E$2:$E$47,1),""))} -> King Towsk | P9: =IF(N9="","","Tier6_Pick2") -> Tier6_Pick2 | Q9: =IF(N9="","",6) -> 6 | R9: {=IF(N9="","",IFERROR(INDEX(Entries!$P$2:$P$47,1),""))} -> Ukraine | S9: {=IF(R9="","",IFERROR(XLOOKUP(R9,'Live Medal Table'!$B$2:$B$94,'Live Medal Table'!$C$2:$C$94,"???"),"???"))} -> UKR | T9: {=IF(R9="",0,IFERROR(XLOOKUP(R9,'Live Medal Table'!$B$2:$B$94,'Live Medal Table'!$F$2:$F$94,0),0))} -> 20 | U9: {=IF(R9="",0,IFERROR(XLOOKUP(R9,'Live Medal Table'!$B$2:$B$94,'Live Medal Table'!$G$2:$G$94,0),0))} -> 0 | V9: {=IF(R9="",0,IFERROR(XLOOKUP(R9,'Live Medal Table'!$B$2:$B$94,'Live Medal Table'!$H$2:$H$94,0),0))} -> 0 | W9: {=IF(R9="",0,IFERROR(XLOOKUP(R9,'Live Medal Table'!$B$2:$B$94,'Live Medal Table'!$I$2:$I$94,0),0))} -> 0 | X9: =U9*3*T9 -> 0 | Y9: =V9*2*T9 -> 0 | Z9: =W9*1*T9 -> 0 | AA9: =X9+Y9+Z9 -> 0 | AB9: {=IF(R9="",FALSE,IFERROR(AND(ISNUMBER(MATCH(R9,'Live Medal Table'!$B$2:$B$94,0)),XLOOKUP(R9,'Live Medal Table'!$B$2:$B$94,Countries!$I$2:$I$72,FALSE)),FALSE))} -> FALSE
B10: =IFERROR(__xludf.DUMMYFUNCTION("""COMPUTED_VALUE"""),"Poland") -> Poland | C10: =IFERROR(__xludf.DUMMYFUNCTION("""COMPUTED_VALUE"""),5.0) -> 5 | D10: =IFERROR(__xludf.DUMMYFUNCTION("""COMPUTED_VALUE"""),70.0) -> 70 | E10: {=XLOOKUP(B10,'Live Medal Table'!N:N,'Live Medal Table'!X:X,"")} | G10: =IFERROR(__xludf.DUMMYFUNCTION("""COMPUTED_VALUE"""),"Josh’s Dawgs") -> Josh’s Dawgs | N10: {=IFERROR(IF(INDEX(Entries!$C$2:$C$47,2)="","",INDEX(Entries!$Q$2:$Q$47,2)),"")} -> Wyatt_Eisen_Wyatt | O10: {=IF(N10="","",IFERROR(INDEX(Entries!$E$2:$E$47,2),""))} -> Wyatt | P10: =IF(N10="","","Tier1_Pick1") -> Tier1_Pick1 | Q10: =IF(N10="","",1) -> 1 | R10: {=IF(N10="","",IFERROR(INDEX(Entries!$F$2:$F$47,2),""))} -> Canada | S10: {=IF(R10="","",IFERROR(XLOOKUP(R10,'Live Medal Table'!$B$2:$B$94,'Live Medal Table'!$C$2:$C$94,"???"),"???"))} -> CAN | T10: {=IF(R10="",0,IFERROR(XLOOKUP(R10,'Live Medal Table'!$B$2:$B$94,'Live Medal Table'!$F$2:$F$94,0),0))} -> 1 | U10: {=IF(R10="",0,IFERROR(XLOOKUP(R10,'Live Medal Table'!$B$2:$B$94,'Live Medal Table'!$G$2:$G$94,0),0))} -> 5 | V10: {=IF(R10="",0,IFERROR(XLOOKUP(R10,'Live Medal Table'!$B$2:$B$94,'Live Medal Table'!$H$2:$H$94,0),0))} -> 7 | W10: {=IF(R10="",0,IFERROR(XLOOKUP(R10,'Live Medal Table'!$B$2:$B$94,'Live Medal Table'!$I$2:$I$94,0),0))} -> 9 | X10: =U10*3*T10 -> 15 | Y10: =V10*2*T10 -> 14 | Z10: =W10*1*T10 -> 9 | AA10: =X10+Y10+Z10 -> 38 | AB10: {=IF(R10="",FALSE,IFERROR(AND(ISNUMBER(MATCH(R10,'Live Medal Table'!$B$2:$B$94,0)),XLOOKUP(R10,'Live Medal Table'!$B$2:$B$94,Countries!$I$2:$I$72,FALSE)),FALSE))} -> FALSE
B11: =IFERROR(__xludf.DUMMYFUNCTION("""COMPUTED_VALUE"""),"Bulgaria") -> Bulgaria | C11: =IFERROR(__xludf.DUMMYFUNCTION("""COMPUTED_VALUE"""),6.0) -> 6 | D11: =IFERROR(__xludf.DUMMYFUNCTION("""COMPUTED_VALUE"""),40.0) -> 40 | E11: {=XLOOKUP(B11,'Live Medal Table'!N:N,'Live Medal Table'!X:X,"")} | G11: =IFERROR(__xludf.DUMMYFUNCTION("""COMPUTED_VALUE"""),"kborst13") -> kborst13 | N11: {=IFERROR(IF(INDEX(Entries!$C$2:$C$47,2)="","",INDEX(Entries!$Q$2:$Q$47,2)),"")} -> Wyatt_Eisen_Wyatt | O11: {=IF(N11="","",IFERROR(INDEX(Entries!$E$2:$E$47,2),""))} -> Wyatt | P11: =IF(N11="","","Tier2_Pick1") -> Tier2_Pick1 | Q11: =IF(N11="","",2) -> 2 | R11: {=IF(N11="","",IFERROR(INDEX(Entries!$M$2:$M$47,2),""))} -> Austria | S11: {=IF(R11="","",IFERROR(XLOOKUP(R11,'Live Medal Table'!$B$2:$B$94,'Live Medal Table'!$C$2:$C$94,"???"),"???"))} -> AUT | T11: {=IF(R11="",0,IFERROR(XLOOKUP(R11,'Live Medal Table'!$B$2:$B$94,'Live Medal Table'!$F$2:$F$94,0),0))} -> 2 | U11: {=IF(R11="",0,IFERROR(XLOOKUP(R11,'Live Medal Table'!$B$2:$B$94,'Live Medal Table'!$G$2:$G$94,0),0))} -> 5 | V11: {=IF(R11="",0,IFERROR(XLOOKUP(R11,'Live Medal Table'!$B$2:$B$94,'Live Medal Table'!$H$2:$H$94,0),0))} -> 8 | W11: {=IF(R11="",0,IFERROR(XLOOKUP(R11,'Live Medal Table'!$B$2:$B$94,'Live Medal Table'!$I$2:$I$94,0),0))} -> 5 | X11: =U11*3*T11 -> 30 | Y11: =V11*2*T11 -> 32 | Z11: =W11*1*T11 -> 10 | AA11: =X11+Y11+Z11 -> 72 | AB11: {=IF(R11="",FALSE,IFERROR(AND(ISNUMBER(MATCH(R11,'Live Medal Table'!$B$2:$B$94,0)),XLOOKUP(R11,'Live Medal Table'!$B$2:$B$94,Countries!$I$2:$I$72,FALSE)),FALSE))} -> FALSE
B12: =IFERROR(__xludf.DUMMYFUNCTION("""COMPUTED_VALUE"""),"Denmark") -> Denmark | C12: =IFERROR(__xludf.DUMMYFUNCTION("""COMPUTED_VALUE"""),6.0) -> 6 | D12: =IFERROR(__xludf.DUMMYFUNCTION("""COMPUTED_VALUE"""),40.0) -> 40 | E12: {=XLOOKUP(B12,'Live Medal Table'!N:N,'Live Medal Table'!X:X,"")} | G12: =IFERROR(__xludf.DUMMYFUNCTION("""COMPUTED_VALUE"""),"King Towsk") -> King Towsk | N12: {=IFERROR(IF(INDEX(Entries!$C$2:$C$47,2)="","",INDEX(Entries!$Q$2:$Q$47,2)),"")} -> Wyatt_Eisen_Wyatt | O12: {=IF(N12="","",IFERROR(INDEX(Entries!$E$2:$E$47,2),""))} -> Wyatt | P12: =IF(N12="","","Tier2_Pick2") -> Tier2_Pick2 | Q12: =IF(N12="","",2) -> 2 | R12: {=IF(N12="","",IFERROR(INDEX(Entries!$N$2:$N$47,2),""))} -> Netherlands | S12: {=IF(R12="","",IFERROR(XLOOKUP(R12,'Live Medal Table'!$B$2:$B$94,'Live Medal Table'!$C$2:$C$94,"???"),"???"))} -> NED | T12: {=IF(R12="",0,IFERROR(XLOOKUP(R12,'Live Medal Table'!$B$2:$B$94,'Live Medal Table'!$F$2:$F$94,0),0))} -> 2 | U12: {=IF(R12="",0,IFERROR(XLOOKUP(R12,'Live Medal Table'!$B$2:$B$94,'Live Medal Table'!$G$2:$G$94,0),0))} -> 10 | V12: {=IF(R12="",0,IFERROR(XLOOKUP(R12,'Live Medal Table'!$B$2:$B$94,'Live Medal Table'!$H$2:$H$94,0),0))} -> 7 | W12: {=IF(R12="",0,IFERROR(XLOOKUP(R12,'Live Medal Table'!$B$2:$B$94,'Live Medal Table'!$I$2:$I$94,0),0))} -> 3 | X12: =U12*3*T12 -> 60 | Y12: =V12*2*T12 -> 28 | Z12: =W12*1*T12 -> 6 | AA12: =X12+Y12+Z12 -> 94 | AB12: {=IF(R12="",FALSE,IFERROR(AND(ISNUMBER(MATCH(R12,'Live Medal Table'!$B$2:$B$94,0)),XLOOKUP(R12,'Live Medal Table'!$B$2:$B$94,Countries!$I$2:$I$72,FALSE)),FALSE))} -> FALSE
C13: Total: | D13: =SUM(D5:D12) -> 623 | G13: =IFERROR(__xludf.DUMMYFUNCTION("""COMPUTED_VALUE"""),"LucasF") -> LucasF | N13: {=IFERROR(IF(INDEX(Entries!$C$2:$C$47,2)="","",INDEX(Entries!$Q$2:$Q$47,2)),"")} -> Wyatt_Eisen_Wyatt | O13: {=IF(N13="","",IFERROR(INDEX(Entries!$E$2:$E$47,2),""))} -> Wyatt | P13: =IF(N13="","","Tier3_Pick1") -> Tier3_Pick1 | Q13: =IF(N13="","",3) -> 3 | R13: {=IF(N13="","",IFERROR(INDEX(Entries!$H$2:$H$47,2),""))} -> China | S13: {=IF(R13="","",IFERROR(XLOOKUP(R13,'Live Medal Table'!$B$2:$B$94,'Live Medal Table'!$C$2:$C$94,"???"),"???"))} -> CHN | T13: {=IF(R13="",0,IFERROR(XLOOKUP(R13,'Live Medal Table'!$B$2:$B$94,'Live Medal Table'!$F$2:$F$94,0),0))} -> 3 | U13: {=IF(R13="",0,IFERROR(XLOOKUP(R13,'Live Medal Table'!$B$2:$B$94,'Live Medal Table'!$G$2:$G$94,0),0))} -> 5 | V13: {=IF(R13="",0,IFERROR(XLOOKUP(R13,'Live Medal Table'!$B$2:$B$94,'Live Medal Table'!$H$2:$H$94,0),0))} -> 4 | W13: {=IF(R13="",0,IFERROR(XLOOKUP(R13,'Live Medal Table'!$B$2:$B$94,'Live Medal Table'!$I$2:$I$94,0),0))} -> 6 | X13: =U13*3*T13 -> 45 | Y13: =V13*2*T13 -> 24 | Z13: =W13*1*T13 -> 18 | AA13: =X13+Y13+Z13 -> 87 | AB13: {=IF(R13="",FALSE,IFERROR(AND(ISNUMBER(MATCH(R13,'Live Medal Table'!$B$2:$B$94,0)),XLOOKUP(R13,'Live Medal Table'!$B$2:$B$94,Countries!$I$2:$I$72,FALSE)),FALSE))} -> FALSE
G14: =IFERROR(__xludf.DUMMYFUNCTION("""COMPUTED_VALUE"""),"Mark Mattson") -> Mark Mattson | N14: {=IFERROR(IF(INDEX(Entries!$C$2:$C$47,2)="","",INDEX(Entries!$Q$2:$Q$47,2)),"")} -> Wyatt_Eisen_Wyatt | O14: {=IF(N14="","",IFERROR(INDEX(Entries!$E$2:$E$47,2),""))} -> Wyatt | P14: =IF(N14="","","Tier4_Pick1") -> Tier4_Pick1 | Q14: =IF(N14="","",4) -> 4 | R14: {=IF(N14="","",IFERROR(INDEX(Entries!$I$2:$I$47,2),""))} -> Czech Republic | S14: {=IF(R14="","",IFERROR(XLOOKUP(R14,'Live Medal Table'!$B$2:$B$94,'Live Medal Table'!$C$2:$C$94,"???"),"???"))} -> CZE | T14: {=IF(R14="",0,IFERROR(XLOOKUP(R14,'Live Medal Table'!$B$2:$B$94,'Live Medal Table'!$F$2:$F$94,0),0))} -> 6 | U14: {=IF(R14="",0,IFERROR(XLOOKUP(R14,'Live Medal Table'!$B$2:$B$94,'Live Medal Table'!$G$2:$G$94,0),0))} -> 2 | V14: {=IF(R14="",0,IFERROR(XLOOKUP(R14,'Live Medal Table'!$B$2:$B$94,'Live Medal Table'!$H$2:$H$94,0),0))} -> 2 | W14: {=IF(R14="",0,IFERROR(XLOOKUP(R14,'Live Medal Table'!$B$2:$B$94,'Live Medal Table'!$I$2:$I$94,0),0))} -> 1 | X14: =U14*3*T14 -> 36 | Y14: =V14*2*T14 -> 24 | Z14: =W14*1*T14 -> 6 | AA14: =X14+Y14+Z14 -> 66 | AB14: {=IF(R14="",FALSE,IFERROR(AND(ISNUMBER(MATCH(R14,'Live Medal Table'!$B$2:$B$94,0)),XLOOKUP(R14,'Live Medal Table'!$B$2:$B$94,Countries!$I$2:$I$72,FALSE)),FALSE))} -> FALSE
