Workbook
Name GoldPoints: Config!$B$4
Name LeagueName: Config!$B$2
Name SilverPoints: Config!$B$5
Name BronzePoints: Config!$B$6

Sheet Leaderboard
A1: 🏆 LEADERBOARD
D2: USA Actual Medals: | E2: {=IFERROR(XLOOKUP("United States",Medals!$B$2:$B$51,Medals!$D$2:$D$51,0)+XLOOKUP("United States",Medals!$B$2:$B$51,Medals!$E$2:$E$51,0)+XLOOKUP("United States",Medals!$B$2:$B$51,Medals!$F$2:$F$51,0),0)} -> 21
A3: Rank | B3: Player | C3: Total Pts | D3: USA Guess | E3: Diff | F3: Countries Picked
A4: =IF(B4="","",RANK(C4,$C$4:$C$53,0)+SUMPRODUCT(($C$4:$C$53=C4)*($E$4:$E$53<E4))) -> #ERROR! | B4: {=IFERROR(INDEX(Entries!$E$2:$E$51,ROW()-3)&"","")} -> Brad Hagstrom | C4: =IF(B4="","",SUMIF(Scores!$B$2:$B$401,B4,Scores!$N$2:$N$401)) -> 296 | D4: {=IF(B4="","",IFERROR(INDEX(Entries!$L$2:$L$51,ROW()-3),0))} -> 12 | E4: =IF(B4="","",ABS(D4-[USA_TOTAL_CELL])) -> #ERROR! | F4: {=IF(B4="","",INDEX(Entries!$F$2:$F$51,ROW()-3)&", "&INDEX(Entries!$M$2:$M$51,ROW()-3)&", "&INDEX(Entries!$N$2:$N$51,ROW()-3)&", "&INDEX(Entries!$H$2:$H$51,ROW()-3)&", "&INDEX(Entries!$I$2:$I$51,ROW()-3)&", "&INDEX(Entries!$J$2:$J$51,ROW()-3)&", "&INDEX(Entries!$O$2:$O$51,ROW()-3)&", "&INDEX(Entries!$P$2:$P$51,ROW()-3))} -> United States, France, South Korea, China, Finland, Great Britain, Belgium, âšª Benin
A5: =IF(B5="","",RANK(C5,$C$4:$C$52,0)+SUMPRODUCT(($C$4:$C$52=C5)*((#REF!<#REF!)+(#REF!=#REF!)*(#REF!<#REF!)+(#REF!=#REF!)*(#REF!=#REF!)*(#REF!<#REF!)))) | B5: {=IFERROR(INDEX(Entries!$E$2:$E$48,3)&"","")} | C5: =IF(B5="","",SUMIF(Scores!$B$2:$B$401,B5,Scores!$N$2:$N$401)) | D5: {=IF(B5="","",IFERROR(INDEX(Entries!$L$2:$L$48,3),0))} | E5: {=IF(B5="","",IFERROR(INDEX(#REF!,3),0))} | F5: =IFERROR(__xludf.DUMMYFUNCTION("IF(B5="""","""",TEXTJOIN("", "",TRUE,FILTER(Scores!$E$2:$E$401,Scores!$B$2:$B$401=B5)))"),"")
A6: =IF(B6="","",RANK(C6,$C$4:$C$52,0)+SUMPRODUCT(($C$4:$C$52=C6)*((#REF!<#REF!)+(#REF!=#REF!)*(#REF!<#REF!)+(#REF!=#REF!)*(#REF!=#REF!)*(#REF!<#REF!)))) | B6: {=IFERROR(INDEX(Entries!$E$2:$E$48,4)&"","")} | C6: =IF(B6="","",SUMIF(Scores!$B$2:$B$401,B6,Scores!$N$2:$N$401)) | D6: {=IF(B6="","",IFERROR(INDEX(Entries!$L$2:$L$48,4),0))} | E6: {=IF(B6="","",IFERROR(INDEX(#REF!,4),0))}
A7: =IF(B7="","",RANK(C7,$C$4:$C$52,0)+SUMPRODUCT(($C$4:$C$52=C7)*((#REF!<#REF!)+(#REF!=#REF!)*(#REF!<#REF!)+(#REF!=#REF!)*(#REF!=#REF!)*(#REF!<#REF!)))) | B7: {=IFERROR(INDEX(Entries!$E$2:$E$48,5)&"","")} | C7: =IF(B7="","",SUMIF(Scores!$B$2:$B$401,B7,Scores!$N$2:$N$401)) | D7: {=IF(B7="","",IFERROR(INDEX(Entries!$L$2:$L$48,5),0))} | E7: {=IF(B7="","",IFERROR(INDEX(#REF!,5),0))}
A8: =IF(B8="","",RANK(C8,$C$4:$C$52,0)+SUMPRODUCT(($C$4:$C$52=C8)*((#REF!<#REF!)+(#REF!=#REF!)*(#REF!<#REF!)+(#REF!=#REF!)*(#REF!=#REF!)*(#REF!<#REF!)))) | B8: {=IFERROR(INDEX(Entries!$E$2:$E$48,6)&"","")} | C8: =IF(B8="","",SUMIF(Scores!$B$2:$B$401,B8,Scores!$N$2:$N$401)) | D8: {=IF(B8="","",IFERROR(INDEX(Entries!$L$2:$L$48,6),0))} | E8: {=IF(B8="","",IFERROR(INDEX(#REF!,6),0))}
A9: =IF(B9="","",RANK(C9,$C$4:$C$52,0)+SUMPRODUCT(($C$4:$C$52=C9)*((#REF!<#REF!)+(#REF!=#REF!)*(#REF!<#REF!)+(#REF!=#REF!)*(#REF!=#REF!)*(#REF!<#REF!)))) | B9: {=IFERROR(INDEX(Entries!$E$2:$E$48,7)&"","")} | C9: =IF(B9="","",SUMIF(Scores!$B$2:$B$401,B9,Scores!$N$2:$N$401)) | D9: {=IF(B9="","",IFERROR(INDEX(Entries!$L$2:$L$48,7),0))} | E9: {=IF(B9="","",IFERROR(INDEX(#REF!,7),0))}
A10: =IF(B10="","",RANK(C10,$C$4:$C$52,0)+SUMPRODUCT(($C$4:$C$52=C10)*((#REF!<#REF!)+(#REF!=#REF!)*(#REF!<#REF!)+(#REF!=#REF!)*(#REF!=#REF!)*(#REF!<#REF!)))) | B10: {=IFERROR(INDEX(Entries!$E$2:$E$48,8)&"","")} | C10: =IF(B10="","",SUMIF(Scores!$B$2:$B$401,B10,Scores!$N$2:$N$401)) | D10: {=IF(B10="","",IFERROR(INDEX(Entries!$L$2:$L$48,8),0))} | E10: {=IF(B10="","",IFERROR(INDEX(#REF!,8),0))}
A11: =IF(B11="","",RANK(C11,$C$4:$C$52,0)+SUMPRODUCT(($C$4:$C$52=C11)*((#REF!<#REF!)+(#REF!=#REF!)*(#REF!<#REF!)+(#REF!=#REF!)*(#REF!=#REF!)*(#REF!<#REF!)))) | B11: {=IFERROR(INDEX(Entries!$E$2:$E$48,9)&"","")} | C11: =IF(B11="","",SUMIF(Scores!$B$2:$B$401,B11,Scores!$N$2:$N$401)) | D11: {=IF(B11="","",IFERROR(INDEX(Entries!$L$2:$L$48,9),0))} | E11: {=IF(B11="","",IFERROR(INDEX(#REF!,9),0))}
A12: =IF(B12="","",RANK(C12,$C$4:$C$52,0)+SUMPRODUCT(($C$4:$C$52=C12)*((#REF!<#REF!)+(#REF!=#REF!)*(#REF!<#REF!)+(#REF!=#REF!)*(#REF!=#REF!)*(#REF!<#REF!)))) | B12: {=IFERROR(INDEX(Entries!$E$2:$E$48,10)&"","")} | C12: =IF(B12="","",SUMIF(Scores!$B$2:$B$401,B12,Scores!$N$2:$N$401)) | D12: {=IF(B12="","",IFERROR(INDEX(Entries!$L$2:$L$48,10),0))} | E12: {=IF(B12="","",IFERROR(INDEX(#REF!,10),0))}
A13: =IF(B13="","",RANK(C13,$C$4:$C$52,0)+SUMPRODUCT(($C$4:$C$52=C13)*((#REF!<#REF!)+(#REF!=#REF!)*(#REF!<#REF!)+(#REF!=#REF!)*(#REF!=#REF!)*(#REF!<#REF!)))) | B13: {=IFERROR(INDEX(Entries!$E$2:$E$48,11)&"","")} | C13: =IF(B13="","",SUMIF(Scores!$B$2:$B$401,B13,Scores!$N$2:$N$401)) | D13: {=IF(B13="","",IFERROR(INDEX(Entries!$L$2:$L$48,11),0))} | E13: {=IF(B13="","",IFERROR(INDEX(#REF!,11),0))}
A14: =IF(B14="","",RANK(C14,$C$4:$C$52,0)+SUMPRODUCT(($C$4:$C$52=C14)*((#REF!<#REF!)+(#REF!=#REF!)*(#REF!<#REF!)+(#REF!=#REF!)*(#REF!=#REF!)*(#REF!<#REF!)))) | B14: {=IFERROR(INDEX(Entries!$E$2:$E$48,12)&"","")} | C14: =IF(B14="","",SUMIF(Scores!$B$2:$B$401,B14,Scores!$N$2:$N$401)) | D14: {=IF(B14="","",IFERROR(INDEX(Entries!$L$2:$L$48,12),0))} | E14: {=IF(B14="","",IFERROR(INDEX(#REF!,12),0))}
A15: =IF(B15="","",RANK(C15,$C$4:$C$52,0)+SUMPRODUCT(($C$4:$C$52=C15)*((#REF!<#REF!)+(#REF!=#REF!)*(#REF!<#REF!)+(#REF!=#REF!)*(#REF!=#REF!)*(#REF!<#REF!)))) | B15: {=IFERROR(INDEX(Entries!$E$2:$E$48,13)&"","")} | C15: =IF(B15="","",SUMIF(Scores!$B$2:$B$401,B15,Scores!$N$2:$N$401)) | D15: {=IF(B15="","",IFERROR(INDEX(Entries!$L$2:$L$48,13),0))} | E15: {=IF(B15="","",IFERROR(INDEX(#REF!,13),0))}
A16: =IF(B16="","",RANK(C16,$C$4:$C$52,0)+SUMPRODUCT(($C$4:$C$52=C16)*((#REF!<#REF!)+(#REF!=#REF!)*(#REF!<#REF!)+(#REF!=#REF!)*(#REF!=#REF!)*(#REF!<#REF!)))) | B16: {=IFERROR(INDEX(Entries!$E$2:$E$48,14)&"","")} | C16: =IF(B16="","",SUMIF(Scores!$B$2:$B$401,B16,Scores!$N$2:$N$401)) | D16: {=IF(B16="","",IFERROR(INDEX(Entries!$L$2:$L$48,14),0))} | E16: {=IF(B16="","",IFERROR(INDEX(#REF!,14),0))}
A17: =IF(B17="","",RANK(C17,$C$4:$C$52,0)+SUMPRODUCT(($C$4:$C$52=C17)*((#REF!<#REF!)+(#REF!=#REF!)*(#REF!<#REF!)+(#REF!=#REF!)*(#REF!=#REF!)*(#REF!<#REF!)))) | B17: {=IFERROR(INDEX(Entries!$E$2:$E$48,15)&"","")} | C17: =IF(B17="","",SUMIF(Scores!$B$2:$B$401,B17,Scores!$N$2:$N$401)) | D17: {=IF(B17="","",IFERROR(INDEX(Entries!$L$2:$L$48,15),0))} | E17: {=IF(B17="","",IFERROR(INDEX(#REF!,15),0))}
A18: =IF(B18="","",RANK(C18,$C$4:$C$52,0)+SUMPRODUCT(($C$4:$C$52=C18)*((#REF!<#REF!)+(#REF!=#REF!)*(#REF!<#REF!)+(#REF!=#REF!)*(#REF!=#REF!)*(#REF!<#REF!)))) | B18: {=IFERROR(INDEX(Entries!$E$2:$E$48,16)&"","")} | C18: =IF(B18="","",SUMIF(Scores!$B$2:$B$401,B18,Scores!$N$2:$N$401)) | D18: {=IF(B18="","",IFERROR(INDEX(Entries!$L$2:$L$48,16),0))} | E18: {=IF(B18="","",IFERROR(INDEX(#REF!,16),0))}
A19: =IF(B19="","",RANK(C19,$C$4:$C$52,0)+SUMPRODUCT(($C$4:$C$52=C19)*((#REF!<#REF!)+(#REF!=#REF!)*(#REF!<#REF!)+(#REF!=#REF!)*(#REF!=#REF!)*(#REF!<#REF!)))) | B19: {=IFERROR(INDEX(Entries!$E$2:$E$48,17)&"","")} | C19: =IF(B19="","",SUMIF(Scores!$B$2:$B$401,B19,Scores!$N$2:$N$401)) | D19: {=IF(B19="","",IFERROR(INDEX(Entries!$L$2:$L$48,17),0))} | E19: {=IF(B19="","",IFERROR(INDEX(#REF!,17),0))}
A20: =IF(B20="","",RANK(C20,$C$4:$C$52,0)+SUMPRODUCT(($C$4:$C$52=C20)*((#REF!<#REF!)+(#REF!=#REF!)*(#REF!<#REF!)+(#REF!=#REF!)*(#REF!=#REF!)*(#REF!<#REF!)))) | B20: {=IFERROR(INDEX(Entries!$E$2:$E$48,18)&"","")} | C20: =IF(B20="","",SUMIF(Scores!$B$2:$B$401,B20,Scores!$N$2:$N$401)) | D20: {=IF(B20="","",IFERROR(INDEX(Entries!$L$2:$L$48,18),0))} | E20: {=IF(B20="","",IFERROR(INDEX(#REF!,18),0))}
A21: =IF(B21="","",RANK(C21,$C$4:$C$52,0)+SUMPRODUCT(($C$4:$C$52=C21)*((#REF!<#REF!)+(#REF!=#REF!)*(#REF!<#REF!)+(#REF!=#REF!)*(#REF!=#REF!)*(#REF!<#REF!)))) | B21: {=IFERROR(INDEX(Entries!$E$2:$E$48,19)&"","")} | C21: =IF(B21="","",SUMIF(Scores!$B$2:$B$401,B21,Scores!$N$2:$N$401)) | D21: {=IF(B21="","",IFERROR(INDEX(Entries!$L$2:$L$48,19),0))} | E21: {=IF(B21="","",IFERROR(INDEX(#REF!,19),0))}
A22: =IF(B22="","",RANK(C22,$C$4:$C$52,0)+SUMPRODUCT(($C$4:$C$52=C22)*((#REF!<#REF!)+(#REF!=#REF!)*(#REF!<#REF!)+(#REF!=#REF!)*(#REF!=#REF!)*(#REF!<#REF!)))) | B22: {=IFERROR(INDEX(Entries!$E$2:$E$48,20)&"","")} | C22: =IF(B22="","",SUMIF(Scores!$B$2:$B$401,B22,Scores!$N$2:$N$401)) | D22: {=IF(B22="","",IFERROR(INDEX(Entries!$L$2:$L$48,20),0))} | E22: {=IF(B22="","",IFERROR(INDEX(#REF!,20),0))}
A23: =IF(B23="","",RANK(C23,$C$4:$C$52,0)+SUMPRODUCT(($C$4:$C$52=C23)*((#REF!<#REF!)+(#REF!=#REF!)*(#REF!<#REF!)+(#REF!=#REF!)*(#REF!=#REF!)*(#REF!<#REF!)))) | B23: {=IFERROR(INDEX(Entries!$E$2:$E$48,21)&"","")} | C23: =IF(B23="","",SUMIF(Scores!$B$2:$B$401,B23,Scores!$N$2:$N$401)) | D23: {=IF(B23="","",IFERROR(INDEX(Entries!$L$2:$L$48,21),0))} | E23: {=IF(B23="","",IFERROR(INDEX(#REF!,21),0))}
A24: =IF(B24="","",RANK(C24,$C$4:$C$52,0)+SUMPRODUCT(($C$4:$C$52=C24)*((#REF!<#REF!)+(#REF!=#REF!)*(#REF!<#REF!)+(#REF!=#REF!)*(#REF!=#REF!)*(#REF!<#REF!)))) | B24: {=IFERROR(INDEX(Entries!$E$2:$E$48,22)&"","")} | C24: =IF(B24="","",SUMIF(Scores!$B$2:$B$401,B24,Scores!$N$2:$N$401)) | D24: {=IF(B24="","",IFERROR(INDEX(Entries!$L$2:$L$48,22),0))} | E24: {=IF(B24="","",IFERROR(INDEX(#REF!,22),0))}
A25: =IF(B25="","",RANK(C25,$C$4:$C$52,0)+SUMPRODUCT(($C$4:$C$52=C25)*((#REF!<#REF!)+(#REF!=#REF!)*(#REF!<#REF!)+(#REF!=#REF!)*(#REF!=#REF!)*(#REF!<#REF!)))) | B25: {=IFERROR(INDEX(Entries!$E$2:$E$48,23)&"","")} | C25: =IF(B25="","",SUMIF(Scores!$B$2:$B$401,B25,Scores!$N$2:$N$401)) | D25: {=IF(B25="","",IFERROR(INDEX(Entries!$L$2:$L$48,23),0))} | E25: {=IF(B25="","",IFERROR(INDEX(#REF!,23),0))}
A26: =IF(B26="","",RANK(C26,$C$4:$C$52,0)+SUMPRODUCT(($C$4:$C$52=C26)*((#REF!<#REF!)+(#REF!=#REF!)*(#REF!<#REF!)+(#REF!=#REF!)*(#REF!=#REF!)*(#REF!<#REF!)))) | B26: {=IFERROR(INDEX(Entries!$E$2:$E$48,24)&"","")} | C26: =IF(B26="","",SUMIF(Scores!$B$2:$B$401,B26,Scores!$N$2:$N$401)) | D26: {=IF(B26="","",IFERROR(INDEX(Entries!$L$2:$L$48,24),0))} | E26: {=IF(B26="","",IFERROR(INDEX(#REF!,24),0))}
A27: =IF(B27="","",RANK(C27,$C$4:$C$52,0)+SUMPRODUCT(($C$4:$C$52=C27)*((#REF!<#REF!)+(#REF!=#REF!)*(#REF!<#REF!)+(#REF!=#REF!)*(#REF!=#REF!)*(#REF!<#REF!)))) | B27: {=IFERROR(INDEX(Entries!$E$2:$E$48,25)&"","")} | C27: =IF(B27="","",SUMIF(Scores!$B$2:$B$401,B27,Scores!$N$2:$N$401)) | D27: {=IF(B27="","",IFERROR(INDEX(Entries!$L$2:$L$48,25),0))} | E27: {=IF(B27="","",IFERROR(INDEX(#REF!,25),0))}
A28: =IF(B28="","",RANK(C28,$C$4:$C$52,0)+SUMPRODUCT(($C$4:$C$52=C28)*((#REF!<#REF!)+(#REF!=#REF!)*(#REF!<#REF!)+(#REF!=#REF!)*(#REF!=#REF!)*(#REF!<#REF!)))) | B28: {=IFERROR(INDEX(Entries!$E$2:$E$48,26)&"","")} | C28: =IF(B28="","",SUMIF(Scores!$B$2:$B$401,B28,Scores!$N$2:$N$401)) | D28: {=IF(B28="","",IFERROR(INDEX(Entries!$L$2:$L$48,26),0))} | E28: {=IF(B28="","",IFERROR(INDEX(#REF!,26),0))}
A29: =IF(B29="","",RANK(C29,$C$4:$C$52,0)+SUMPRODUCT(($C$4:$C$52=C29)*((#REF!<#REF!)+(#REF!=#REF!)*(#REF!<#REF!)+(#REF!=#REF!)*(#REF!=#REF!)*(#REF!<#REF!)))) | B29: {=IFERROR(INDEX(Entries!$E$2:$E$48,27)&"","")} | C29: =IF(B29="","",SUMIF(Scores!$B$2:$B$401,B29,Scores!$N$2:$N$401)) | D29: {=IF(B29="","",IFERROR(INDEX(Entries!$L$2:$L$48,27),0))} | E29: {=IF(B29="","",IFERROR(INDEX(#REF!,27),0))}
A30: =IF(B30="","",RANK(C30,$C$4:$C$52,0)+SUMPRODUCT(($C$4:$C$52=C30)*((#REF!<#REF!)+(#REF!=#REF!)*(#REF!<#REF!)+(#REF!=#REF!)*(#REF!=#REF!)*(#REF!<#REF!)))) | B30: {=IFERROR(INDEX(Entries!$E$2:$E$48,28)&"","")} | C30: =IF(B30="","",SUMIF(Scores!$B$2:$B$401,B30,Scores!$N$2:$N$401)) | D30: {=IF(B30="","",IFERROR(INDEX(Entries!$L$2:$L$48,28),0))} | E30: {=IF(B30="","",IFERROR(INDEX(#REF!,28),0))}
A31: =IF(B31="","",RANK(C31,$C$4:$C$52,0)+SUMPRODUCT(($C$4:$C$52=C31)*((#REF!<#REF!)+(#REF!=#REF!)*(#REF!<#REF!)+(#REF!=#REF!)*(#REF!=#REF!)*(#REF!<#REF!)))) | B31: {=IFERROR(INDEX(Entries!$E$2:$E$48,29)&"","")} | C31: =IF(B31="","",SUMIF(Scores!$B$2:$B$401,B31,Scores!$N$2:$N$401)) | D31: {=IF(B31="","",IFERROR(INDEX(Entries!$L$2:$L$48,29),0))} | E31: {=IF(B31="","",IFERROR(INDEX(#REF!,29),0))}
A32: =IF(B32="","",RANK(C32,$C$4:$C$52,0)+SUMPRODUCT(($C$4:$C$52=C32)*((#REF!<#REF!)+(#REF!=#REF!)*(#REF!<#REF!)+(#REF!=#REF!)*(#REF!=#REF!)*(#REF!<#REF!)))) | B32: {=IFERROR(INDEX(Entries!$E$2:$E$48,30)&"","")} | C32: =IF(B32="","",SUMIF(Scores!$B$2:$B$401,B32,Scores!$N$2:$N$401)) | D32: {=IF(B32="","",IFERROR(INDEX(Entries!$L$2:$L$48,30),0))} | E32: {=IF(B32="","",IFERROR(INDEX(#REF!,30),0))}
A33: =IF(B33="","",RANK(C33,$C$4:$C$52,0)+SUMPRODUCT(($C$4:$C$52=C33)*((#REF!<#REF!)+(#REF!=#REF!)*(#REF!<#REF!)+(#REF!=#REF!)*(#REF!=#REF!)*(#REF!<#REF!)))) | B33: {=IFERROR(INDEX(Entries!$E$2:$E$48,31)&"","")} | C33: =IF(B33="","",SUMIF(Scores!$B$2:$B$401,B33,Scores!$N$2:$N$401)) | D33: {=IF(B33="","",IFERROR(INDEX(Entries!$L$2:$L$48,31),0))} | E33: {=IF(B33="","",IFERROR(INDEX(#REF!,31),0))}
A34: =IF(B34="","",RANK(C34,$C$4:$C$52,0)+SUMPRODUCT(($C$4:$C$52=C34)*((#REF!<#REF!)+(#REF!=#REF!)*(#REF!<#REF!)+(#REF!=#REF!)*(#REF!=#REF!)*(#REF!<#REF!)))) | B34: {=IFERROR(INDEX(Entries!$E$2:$E$48,32)&"","")} | C34: =IF(B34="","",SUMIF(Scores!$B$2:$B$401,B34,Scores!$N$2:$N$401)) | D34: {=IF(B34="","",IFERROR(INDEX(Entries!$L$2:$L$48,32),0))} | E34: {=IF(B34="","",IFERROR(INDEX(#REF!,32),0))}
A35: =IF(B35="","",RANK(C35,$C$4:$C$52,0)+SUMPRODUCT(($C$4:$C$52=C35)*((#REF!<#REF!)+(#REF!=#REF!)*(#REF!<#REF!)+(#REF!=#REF!)*(#REF!=#REF!)*(#REF!<#REF!)))) | B35: {=IFERROR(INDEX(Entries!$E$2:$E$48,33)&"","")} | C35: =IF(B35="","",SUMIF(Scores!$B$2:$B$401,B35,Scores!$N$2:$N$401)) | D35: {=IF(B35="","",IFERROR(INDEX(Entries!$L$2:$L$48,33),0))} | E35: {=IF(B35="","",IFERROR(INDEX(#REF!,33),0))}
A36: =IF(B36="","",RANK(C36,$C$4:$C$52,0)+SUMPRODUCT(($C$4:$C$52=C36)*((#REF!<#REF!)+(#REF!=#REF!)*(#REF!<#REF!)+(#REF!=#REF!)*(#REF!=#REF!)*(#REF!<#REF!)))) | B36: {=IFERROR(INDEX(Entries!$E$2:$E$48,34)&"","")} | C36: =IF(B36="","",SUMIF(Scores!$B$2:$B$401,B36,Scores!$N$2:$N$401)) | D36: {=IF(B36="","",IFERROR(INDEX(Entries!$L$2:$L$48,34),0))} | E36: {=IF(B36="","",IFERROR(INDEX(#REF!,34),0))}
A37: =IF(B37="","",RANK(C37,$C$4:$C$52,0)+SUMPRODUCT(($C$4:$C$52=C37)*((#REF!<#REF!)+(#REF!=#REF!)*(#REF!<#REF!)+(#REF!=#REF!)*(#REF!=#REF!)*(#REF!<#REF!)))) | B37: {=IFERROR(INDEX(Entries!$E$2:$E$48,35)&"","")} | C37: =IF(B37="","",SUMIF(Scores!$B$2:$B$401,B37,Scores!$N$2:$N$401)) | D37: {=IF(B37="","",IFERROR(INDEX(Entries!$L$2:$L$48,35),0))} | E37: {=IF(B37="","",IFERROR(INDEX(#REF!,35),0))}
A38: =IF(B38="","",RANK(C38,$C$4:$C$52,0)+SUMPRODUCT(($C$4:$C$52=C38)*((#REF!<#REF!)+(#REF!=#REF!)*(#REF!<#REF!)+(#REF!=#REF!)*(#REF!=#REF!)*(#REF!<#REF!)))) | B38: {=IFERROR(INDEX(Entries!$E$2:$E$48,36)&"","")} | C38: =IF(B38="","",SUMIF(Scores!$B$2:$B$401,B38,Scores!$N$2:$N$401)) | D38: {=IF(B38="","",IFERROR(INDEX(Entries!$L$2:$L$48,36),0))} | E38: {=IF(B38="","",IFERROR(INDEX(#REF!,36),0))}
A39: =IF(B39="","",RANK(C39,$C$4:$C$52,0)+SUMPRODUCT(($C$4:$C$52=C39)*((#REF!<#REF!)+(#REF!=#REF!)*(#REF!<#REF!)+(#REF!=#REF!)*(#REF!=#REF!)*(#REF!<#REF!)))) | B39: {=IFERROR(INDEX(Entries!$E$2:$E$48,37)&"","")} | C39: =IF(B39="","",SUMIF(Scores!$B$2:$B$401,B39,Scores!$N$2:$N$401)) | D39: {=IF(B39="","",IFERROR(INDEX(Entries!$L$2:$L$48,37),0))} | E39: {=IF(B39="","",IFERROR(INDEX(#REF!,37),0))}
A40: =IF(B40="","",RANK(C40,$C$4:$C$52,0)+SUMPRODUCT(($C$4:$C$52=C40)*((#REF!<#REF!)+(#REF!=#REF!)*(#REF!<#REF!)+(#REF!=#REF!)*(#REF!=#REF!)*(#REF!<#REF!)))) | B40: {=IFERROR(INDEX(Entries!$E$2:$E$48,38)&"","")} | C40: =IF(B40="","",SUMIF(Scores!$B$2:$B$401,B40,Scores!$N$2:$N$401)) | D40: {=IF(B40="","",IFERROR(INDEX(Entries!$L$2:$L$48,38),0))} | E40: {=IF(B40="","",IFERROR(INDEX(#REF!,38),0))}
...

Sheet Medals
A1: RawName | B1: CanonicalName | C1: IOC | D1: Gold | E1: Silver | F1: Bronze | G1: Total | H1: MappingStatus
A2: =IF(MedalImport!B3="","",MedalImport!B3) -> Norway | B2: {=IF(A2="","",LET(_xlpm.raw,A2,_xlpm.alias,XLOOKUP(_xlpm.raw,Aliases!$A$2:$A$50,Aliases!$B$2:$B$50,""),IF(_xlpm.alias<>"",_xlpm.alias,_xlpm.raw)))} -> Norway | C2: {=IF(B2="","",XLOOKUP(B2,Countries!$A$2:$A$72,Countries!$B$2:$B$72,"???"))} -> NOR | D2: =IF(A2="","",MedalImport!C3) -> 10 | E2: =IF(A2="","",MedalImport!D3) -> 8 | F2: =IF(A2="","",MedalImport!E3) -> 6 | G2: =IF(A2="","",D2+E2+F2) -> 24 | H2: {=IF(A2="","",LET(_xlpm.raw,A2,_xlpm.isExcluded,XLOOKUP(_xlpm.raw,Aliases!$A$2:$A$50,Aliases!$D$2:$D$50,FALSE),_xlpm.isMapped,ISNUMBER(MATCH(B2,Countries!$A$2:$A$72,0)),IF(_xlpm.isExcluded,"EXCLUDED",IF(_xlpm.isMapped,"OK","UNMAPPED"))))} -> OK
A3: =IF(MedalImport!B4="","",MedalImport!B4) -> Germany | B3: {=IF(A3="","",LET(_xlpm.raw,A3,_xlpm.alias,XLOOKUP(_xlpm.raw,Aliases!$A$2:$A$50,Aliases!$B$2:$B$50,""),IF(_xlpm.alias<>"",_xlpm.alias,_xlpm.raw)))} -> Germany | C3: {=IF(B3="","",XLOOKUP(B3,Countries!$A$2:$A$72,Countries!$B$2:$B$72,"???"))} -> GER | D3: =IF(A3="","",MedalImport!C4) -> 8 | E3: =IF(A3="","",MedalImport!D4) -> 7 | F3: =IF(A3="","",MedalImport!E4) -> 5 | G3: =IF(A3="","",D3+E3+F3) -> 20 | H3: {=IF(A3="","",LET(_xlpm.raw,A3,_xlpm.isExcluded,XLOOKUP(_xlpm.raw,Aliases!$A$2:$A$50,Aliases!$D$2:$D$50,FALSE),_xlpm.isMapped,ISNUMBER(MATCH(B3,Countries!$A$2:$A$72,0)),IF(_xlpm.isExcluded,"EXCLUDED",IF(_xlpm.isMapped,"OK","UNMAPPED"))))} -> OK
A4: =IF(MedalImport!B5="","",MedalImport!B5) -> United States | B4: {=IF(A4="","",LET(_xlpm.raw,A4,_xlpm.alias,XLOOKUP(_xlpm.raw,Aliases!$A$2:$A$50,Aliases!$B$2:$B$50,""),IF(_xlpm.alias<>"",_xlpm.alias,_xlpm.raw)))} -> United States | C4: {=IF(B4="","",XLOOKUP(B4,Countries!$A$2:$A$72,Countries!$B$2:$B$72,"???"))} -> USA | D4: =IF(A4="","",MedalImport!C5) -> 6 | E4: =IF(A4="","",MedalImport!D5) -> 8 | F4: =IF(A4="","",MedalImport!E5) -> 7 | G4: =IF(A4="","",D4+E4+F4) -> 21 | H4: {=IF(A4="","",LET(_xlpm.raw,A4,_xlpm.isExcluded,XLOOKUP(_xlpm.raw,Aliases!$A$2:$A$50,Aliases!$D$2:$D$50,FALSE),_xlpm.isMapped,ISNUMBER(MATCH(B4,Countries!$A$2:$A$72,0)),IF(_xlpm.isExcluded,"EXCLUDED",IF(_xlpm.isMapped,"OK","UNMAPPED"))))} -> OK
A5: =IF(MedalImport!B6="","",MedalImport!B6) -> Canada | B5: {=IF(A5="","",LET(_xlpm.raw,A5,_xlpm.alias,XLOOKUP(_xlpm.raw,Aliases!$A$2:$A$50,Aliases!$B$2:$B$50,""),IF(_xlpm.alias<>"",_xlpm.alias,_xlpm.raw)))} -> Canada | C5: {=IF(B5="","",XLOOKUP(B5,Countries!$A$2:$A$72,Countries!$B$2:$B$72,"???"))} -> CAN | D5: =IF(A5="","",MedalImport!C6) -> 5 | E5: =IF(A5="","",MedalImport!D6) -> 6 | F5: =IF(A5="","",MedalImport!E6) -> 8 | G5: =IF(A5="","",D5+E5+F5) -> 19 | H5: {=IF(A5="","",LET(_xlpm.raw,A5,_xlpm.isExcluded,XLOOKUP(_xlpm.raw,Aliases!$A$2:$A$50,Aliases!$D$2:$D$50,FALSE),_xlpm.isMapped,ISNUMBER(MATCH(B5,Countries!$A$2:$A$72,0)),IF(_xlpm.isExcluded,"EXCLUDED",IF(_xlpm.isMapped,"OK","UNMAPPED"))))} -> OK
A6: =IF(MedalImport!B7="","",MedalImport!B7) -> Netherlands | B6: {=IF(A6="","",LET(_xlpm.raw,A6,_xlpm.alias,XLOOKUP(_xlpm.raw,Aliases!$A$2:$A$50,Aliases!$B$2:$B$50,""),IF(_xlpm.alias<>"",_xlpm.alias,_xlpm.raw)))} -> Netherlands | C6: {=IF(B6="","",XLOOKUP(B6,Countries!$A$2:$A$72,Countries!$B$2:$B$72,"???"))} -> NED | D6: =IF(A6="","",MedalImport!C7) -> 7 | E6: =IF(A6="","",MedalImport!D7) -> 5 | F6: =IF(A6="","",MedalImport!E7) -> 3 | G6: =IF(A6="","",D6+E6+F6) -> 15 | H6: {=IF(A6="","",LET(_xlpm.raw,A6,_xlpm.isExcluded,XLOOKUP(_xlpm.raw,Aliases!$A$2:$A$50,Aliases!$D$2:$D$50,FALSE),_xlpm.isMapped,ISNUMBER(MATCH(B6,Countries!$A$2:$A$72,0)),IF(_xlpm.isExcluded,"EXCLUDED",IF(_xlpm.isMapped,"OK","UNMAPPED"))))} -> OK
A7: =IF(MedalImport!B8="","",MedalImport!B8) -> France | B7: {=IF(A7="","",LET(_xlpm.raw,A7,_xlpm.alias,XLOOKUP(_xlpm.raw,Aliases!$A$2:$A$50,Aliases!$B$2:$B$50,""),IF(_xlpm.alias<>"",_xlpm.alias,_xlpm.raw)))} -> France | C7: {=IF(B7="","",XLOOKUP(B7,Countries!$A$2:$A$72,Countries!$B$2:$B$72,"???"))} -> FRA | D7: =IF(A7="","",MedalImport!C8) -> 3 | E7: =IF(A7="","",MedalImport!D8) -> 4 | F7: =IF(A7="","",MedalImport!E8) -> 2 | G7: =IF(A7="","",D7+E7+F7) -> 9 | H7: {=IF(A7="","",LET(_xlpm.raw,A7,_xlpm.isExcluded,XLOOKUP(_xlpm.raw,Aliases!$A$2:$A$50,Aliases!$D$2:$D$50,FALSE),_xlpm.isMapped,ISNUMBER(MATCH(B7,Countries!$A$2:$A$72,0)),IF(_xlpm.isExcluded,"EXCLUDED",IF(_xlpm.isMapped,"OK","UNMAPPED"))))} -> OK
A8: =IF(MedalImport!B9="","",MedalImport!B9) -> Switzerland | B8: {=IF(A8="","",LET(_xlpm.raw,A8,_xlpm.alias,XLOOKUP(_xlpm.raw,Aliases!$A$2:$A$50,Aliases!$B$2:$B$50,""),IF(_xlpm.alias<>"",_xlpm.alias,_xlpm.raw)))} -> Switzerland | C8: {=IF(B8="","",XLOOKUP(B8,Countries!$A$2:$A$72,Countries!$B$2:$B$72,"???"))} -> SUI | D8: =IF(A8="","",MedalImport!C9) -> 4 | E8: =IF(A8="","",MedalImport!D9) -> 3 | F8: =IF(A8="","",MedalImport!E9) -> 5 | G8: =IF(A8="","",D8+E8+F8) -> 12 | H8: {=IF(A8="","",LET(_xlpm.raw,A8,_xlpm.isExcluded,XLOOKUP(_xlpm.raw,Aliases!$A$2:$A$50,Aliases!$D$2:$D$50,FALSE),_xlpm.isMapped,ISNUMBER(MATCH(B8,Countries!$A$2:$A$72,0)),IF(_xlpm.isExcluded,"EXCLUDED",IF(_xlpm.isMapped,"OK","UNMAPPED"))))} -> OK
A9: =IF(MedalImport!B10="","",MedalImport!B10) -> Austria | B9: {=IF(A9="","",LET(_xlpm.raw,A9,_xlpm.alias,XLOOKUP(_xlpm.raw,Aliases!$A$2:$A$50,Aliases!$B$2:$B$50,""),IF(_xlpm.alias<>"",_xlpm.alias,_xlpm.raw)))} -> Austria | C9: {=IF(B9="","",XLOOKUP(B9,Countries!$A$2:$A$72,Countries!$B$2:$B$72,"???"))} -> AUT | D9: =IF(A9="","",MedalImport!C10) -> 3 | E9: =IF(A9="","",MedalImport!D10) -> 5 | F9: =IF(A9="","",MedalImport!E10) -> 4 | G9: =IF(A9="","",D9+E9+F9) -> 12 | H9: {=IF(A9="","",LET(_xlpm.raw,A9,_xlpm.isExcluded,XLOOKUP(_xlpm.raw,Aliases!$A$2:$A$50,Aliases!$D$2:$D$50,FALSE),_xlpm.isMapped,ISNUMBER(MATCH(B9,Countries!$A$2:$A$72,0)),IF(_xlpm.isExcluded,"EXCLUDED",IF(_xlpm.isMapped,"OK","UNMAPPED"))))} -> OK
A10: =IF(MedalImport!B11="","",MedalImport!B11) -> Sweden | B10: {=IF(A10="","",LET(_xlpm.raw,A10,_xlpm.alias,XLOOKUP(_xlpm.raw,Aliases!$A$2:$A$50,Aliases!$B$2:$B$50,""),IF(_xlpm.alias<>"",_xlpm.alias,_xlpm.raw)))} -> Sweden | C10: {=IF(B10="","",XLOOKUP(B10,Countries!$A$2:$A$72,Countries!$B$2:$B$72,"???"))} -> SWE | D10: =IF(A10="","",MedalImport!C11) -> 4 | E10: =IF(A10="","",MedalImport!D11) -> 3 | F10: =IF(A10="","",MedalImport!E11) -> 3 | G10: =IF(A10="","",D10+E10+F10) -> 10 | H10: {=IF(A10="","",LET(_xlpm.raw,A10,_xlpm.isExcluded,XLOOKUP(_xlpm.raw,Aliases!$A$2:$A$50,Aliases!$D$2:$D$50,FALSE),_xlpm.isMapped,ISNUMBER(MATCH(B10,Countries!$A$2:$A$72,0)),IF(_xlpm.isExcluded,"EXCLUDED",IF(_xlpm.isMapped,"OK","UNMAPPED"))))} -> OK
A11: =IF(MedalImport!B12="","",MedalImport!B12) -> South Korea | B11: {=IF(A11="","",LET(_xlpm.raw,A11,_xlpm.alias,XLOOKUP(_xlpm.raw,Aliases!$A$2:$A$50,Aliases!$B$2:$B$50,""),IF(_xlpm.alias<>"",_xlpm.alias,_xlpm.raw)))} -> South Korea | C11: {=IF(B11="","",XLOOKUP(B11,Countries!$A$2:$A$72,Countries!$B$2:$B$72,"???"))} -> KOR | D11: =IF(A11="","",MedalImport!C12) -> 2 | E11: =IF(A11="","",MedalImport!D12) -> 3 | F11: =IF(A11="","",MedalImport!E12) -> 2 | G11: =IF(A11="","",D11+E11+F11) -> 7 | H11: {=IF(A11="","",LET(_xlpm.raw,A11,_xlpm.isExcluded,XLOOKUP(_xlpm.raw,Aliases!$A$2:$A$50,Aliases!$D$2:$D$50,FALSE),_xlpm.isMapped,ISNUMBER(MATCH(B11,Countries!$A$2:$A$72,0)),IF(_xlpm.isExcluded,"EXCLUDED",IF(_xlpm.isMapped,"OK","UNMAPPED"))))} -> OK
A12: =IF(MedalImport!B13="","",MedalImport!B13) -> China | B12: {=IF(A12="","",LET(_xlpm.raw,A12,_xlpm.alias,XLOOKUP(_xlpm.raw,Aliases!$A$2:$A$50,Aliases!$B$2:$B$50,""),IF(_xlpm.alias<>"",_xlpm.alias,_xlpm.raw)))} -> China | C12: {=IF(B12="","",XLOOKUP(B12,Countries!$A$2:$A$72,Countries!$B$2:$B$72,"???"))} -> CHN | D12: =IF(A12="","",MedalImport!C13) -> 3 | E12: =IF(A12="","",MedalImport!D13) -> 2 | F12: =IF(A12="","",MedalImport!E13) -> 4 | G12: =IF(A12="","",D12+E12+F12) -> 9 | H12: {=IF(A12="","",LET(_xlpm.raw,A12,_xlpm.isExcluded,XLOOKUP(_xlpm.raw,Aliases!$A$2:$A$50,Aliases!$D$2:$D$50,FALSE),_xlpm.isMapped,ISNUMBER(MATCH(B12,Countries!$A$2:$A$72,0)),IF(_xlpm.isExcluded,"EXCLUDED",IF(_xlpm.isMapped,"OK","UNMAPPED"))))} -> OK
A13: =IF(MedalImport!B14="","",MedalImport!B14) -> Japan | B13: {=IF(A13="","",LET(_xlpm.raw,A13,_xlpm.alias,XLOOKUP(_xlpm.raw,Aliases!$A$2:$A$50,Aliases!$B$2:$B$50,""),IF(_xlpm.alias<>"",_xlpm.alias,_xlpm.raw)))} -> Japan | C13: {=IF(B13="","",XLOOKUP(B13,Countries!$A$2:$A$72,Countries!$B$2:$B$72,"???"))} -> JPN | D13: =IF(A13="","",MedalImport!C14) -> 2 | E13: =IF(A13="","",MedalImport!D14) -> 4 | F13: =IF(A13="","",MedalImport!E14) -> 3 | G13: =IF(A13="","",D13+E13+F13) -> 9 | H13: {=IF(A13="","",LET(_xlpm.raw,A13,_xlpm.isExcluded,XLOOKUP(_xlpm.raw,Aliases!$A$2:$A$50,Aliases!$D$2:$D$50,FALSE),_xlpm.isMapped,ISNUMBER(MATCH(B13,Countries!$A$2:$A$72,0)),IF(_xlpm.isExcluded,"EXCLUDED",IF(_xlpm.isMapped,"OK","UNMAPPED"))))} -> OK
... A21: =IF(MedalImport!B22="","",MedalImport!B22) -> Hungary | B21: {=IF(A21="","",LET(_xlpm.raw,A21,_xlpm.alias,XLOOKUP(_xlpm.raw,Aliases!$A$2:$A$50,Aliases!$B$2:$B$50,""),IF(_xlpm.alias<>"",_xlpm.alias,_xlpm.raw)))} -> Hungary | C21: {=IF(B21="","",XLOOKUP(B21,Countries!$A$2:$A$72,Countries!$B$2:$B$72,"???"))} -> HUN | D21: =IF(A21="","",MedalImport!C22) -> 1 | E21: =IF(A21="","",MedalImport!D22) -> 0 | F21: =IF(A21="","",MedalImport!E22) -> 0 | G21: =IF(A21="","",D21+E21+F21) -> 1 | H21: {=IF(A21="","",LET(_xlpm.raw,A21,_xlpm.isExcluded,XLOOKUP(_xlpm.raw,Aliases!$A$2:$A$50,Aliases!$D$2:$D$50,FALSE),_xlpm.isMapped,ISNUMBER(MATCH(B21,Countries!$A$2:$A$72,0)),IF(_xlpm.isExcluded,"EXCLUDED",IF(_xlpm.isMapped,"OK","UNMAPPED"))))} -> OK
A22: =IF(MedalImport!B23="","",MedalImport!B23) | B22: =IF(A22="","",_xludf.LET(raw,A22,alias,_xludf.XLOOKUP(raw,Aliases!$A$2:$A$50,Aliases!$B$2:$B$50,""),IF(alias<>"",alias,raw))) | C22: =IF(B22="","",_xludf.XLOOKUP(B22,Countries!$A$2:$A$72,Countries!$B$2:$B$72,"???")) | D22: =IF(A22="","",MedalImport!C23) | E22: =IF(A22="","",MedalImport!D23) | F22: =IF(A22="","",MedalImport!E23) | G22: =IF(A22="","",D22+E22+F22) | H22: =IF(A22="","",_xludf.LET(raw,A22,isExcluded,_xludf.XLOOKUP(raw,Aliases!$A$2:$A$50,Aliases!$D$2:$D$50,FALSE),isMapped,ISNUMBER(MATCH(B22,Countries!$A$2:$A$72,0)),IF(isExcluded,"EXCLUDED",IF(isMapped,"OK","UNMAPPED"))))
A23: =IF(MedalImport!B24="","",MedalImport!B24) | B23: =IF(A23="","",_xludf.LET(raw,A23,alias,_xludf.XLOOKUP(raw,Aliases!$A$2:$A$50,Aliases!$B$2:$B$50,""),IF(alias<>"",alias,raw))) | C23: =IF(B23="","",_xludf.XLOOKUP(B23,Countries!$A$2:$A$72,Countries!$B$2:$B$72,"???")) | D23: =IF(A23="","",MedalImport!C24) | E23: =IF(A23="","",MedalImport!D24) | F23: =IF(A23="","",MedalImport!E24) | G23: =IF(A23="","",D23+E23+F23) | H23: =IF(A23="","",_xludf.LET(raw,A23,isExcluded,_xludf.XLOOKUP(raw,Aliases!$A$2:$A$50,Aliases!$D$2:$D$50,FALSE),isMapped,ISNUMBER(MATCH(B23,Countries!$A$2:$A$72,0)),IF(isExcluded,"EXCLUDED",IF(isMapped,"OK","UNMAPPED"))))
A24: =IF(MedalImport!B25="","",MedalImport!B25) | B24: =IF(A24="","",_xludf.LET(raw,A24,alias,_xludf.XLOOKUP(raw,Aliases!$A$2:$A$50,Aliases!$B$2:$B$50,""),IF(alias<>"",alias,raw))) | C24: =IF(B24="","",_xludf.XLOOKUP(B24,Countries!$A$2:$A$72,Countries!$B$2:$B$72,"???")) | D24: =IF(A24="","",MedalImport!C25) | E24: =IF(A24="","",MedalImport!D25) | F24: =IF(A24="","",MedalImport!E25) | G24: =IF(A24="","",D24+E24+F24) | H24: =IF(A24="","",_xludf.LET(raw,A24,isExcluded,_xludf.XLOOKUP(raw,Aliases!$A$2:$A$50,Aliases!$D$2:$D$50,FALSE),isMapped,ISNUMBER(MATCH(B24,Countries!$A$2:$A$72,0)),IF(isExcluded,"EXCLUDED",IF(isMapped,"OK","UNMAPPED"))))
A25: =IF(MedalImport!B26="","",MedalImport!B26) | B25: =IF(A25="","",_xludf.LET(raw,A25,alias,_xludf.XLOOKUP(raw,Aliases!$A$2:$A$50,Aliases!$B$2:$B$50,""),IF(alias<>"",alias,raw))) | C25: =IF(B25="","",_xludf.XLOOKUP(B25,Countries!$A$2:$A$72,Countries!$B$2:$B$72,"???")) | D25: =IF(A25="","",MedalImport!C26) | E25: =IF(A25="","",MedalImport!D26) | F25: =IF(A25="","",MedalImport!E26) | G25: =IF(A25="","",D25+E25+F25) | H25: =IF(A25="","",_xludf.LET(raw,A25,isExcluded,_xludf.XLOOKUP(raw,Aliases!$A$2:$A$50,Aliases!$D$2:$D$50,FALSE),isMapped,ISNUMBER(MATCH(B25,Countries!$A$2:$A$72,0)),IF(isExcluded,"EXCLUDED",IF(isMapped,"OK","UNMAPPED"))))
A26: =IF(MedalImport!B27="","",MedalImport!B27) | B26: =IF(A26="","",_xludf.LET(raw,A26,alias,_xludf.XLOOKUP(raw,Aliases!$A$2:$A$50,Aliases!$B$2:$B$50,""),IF(alias<>"",alias,raw))) | C26: =IF(B26="","",_xludf.XLOOKUP(B26,Countries!$A$2:$A$72,Countries!$B$2:$B$72,"???")) | D26: =IF(A26="","",MedalImport!C27) | E26: =IF(A26="","",MedalImport!D27) | F26: =IF(A26="","",MedalImport!E27) | G26: =IF(A26="","",D26+E26+F26) | H26: =IF(A26="","",_xludf.LET(raw,A26,isExcluded,_xludf.XLOOKUP(raw,Aliases!$A$2:$A$50,Aliases!$D$2:$D$50,FALSE),isMapped,ISNUMBER(MATCH(B26,Countries!$A$2:$A$72,0)),IF(isExcluded,"EXCLUDED",IF(isMapped,"OK","UNMAPPED"))))
A27: =IF(MedalImport!B28="","",MedalImport!B28) | B27: =IF(A27="","",_xludf.LET(raw,A27,alias,_xludf.XLOOKUP(raw,Aliases!$A$2:$A$50,Aliases!$B$2:$B$50,""),IF(alias<>"",alias,raw))) | C27: =IF(B27="","",_xludf.XLOOKUP(B27,Countries!$A$2:$A$72,Countries!$B$2:$B$72,"???")) | D27: =IF(A27="","",MedalImport!C28) | E27: =IF(A27="","",MedalImport!D28) | F27: =IF(A27="","",MedalImport!E28) | G27: =IF(A27="","",D27+E27+F27) | H27: =IF(A27="","",_xludf.LET(raw,A27,isExcluded,_xludf.XLOOKUP(raw,Aliases!$A$2:$A$50,Aliases!$D$2:$D$50,FALSE),isMapped,ISNUMBER(MATCH(B27,Countries!$A$2:$A$72,0)),IF(isExcluded,"EXCLUDED",IF(isMapped,"OK","UNMAPPED"))))
A28: =IF(MedalImport!B29="","",MedalImport!B29) | B28: =IF(A28="","",_xludf.LET(raw,A28,alias,_xludf.XLOOKUP(raw,Aliases!$A$2:$A$50,Aliases!$B$2:$B$50,""),IF(alias<>"",alias,raw))) | C28: =IF(B28="","",_xludf.XLOOKUP(B28,Countries!$A$2:$A$72,Countries!$B$2:$B$72,"???")) | D28: =IF(A28="","",MedalImport!C29) | E28: =IF(A28="","",MedalImport!D29) | F28: =IF(A28="","",MedalImport!E29) | G28: =IF(A28="","",D28+E28+F28) | H28: =IF(A28="","",_xludf.LET(raw,A28,isExcluded,_xludf.XLOOKUP(raw,Aliases!$A$2:$A$50,Aliases!$D$2:$D$50,FALSE),isMapped,ISNUMBER(MATCH(B28,Countries!$A$2:$A$72,0)),IF(isExcluded,"EXCLUDED",IF(isMapped,"OK","UNMAPPED"))))
A29: =IF(MedalImport!B30="","",MedalImport!B30) | B29: =IF(A29="","",_xludf.LET(raw,A29,alias,_xludf.XLOOKUP(raw,Aliases!$A$2:$A$50,Aliases!$B$2:$B$50,""),IF(alias<>"",alias,raw))) | C29: =IF(B29="","",_xludf.XLOOKUP(B29,Countries!$A$2:$A$72,Countries!$B$2:$B$72,"???")) | D29: =IF(A29="","",MedalImport!C30) | E29: =IF(A29="","",MedalImport!D30) | F29: =IF(A29="","",MedalImport!E30) | G29: =IF(A29="","",D29+E29+F29) | H29: =IF(A29="","",_xludf.LET(raw,A29,isExcluded,_xludf.XLOOKUP(raw,Aliases!$A$2:$A$50,Aliases!$D$2:$D$50,FALSE),isMapped,ISNUMBER(MATCH(B29,Countries!$A$2:$A$72,0)),IF(isExcluded,"EXCLUDED",IF(isMapped,"OK","UNMAPPED"))))
A30: =IF(MedalImport!B31="","",MedalImport!B31) | B30: =IF(A30="","",_xludf.LET(raw,A30,alias,_xludf.XLOOKUP(raw,Aliases!$A$2:$A$50,Aliases!$B$2:$B$50,""),IF(alias<>"",alias,raw))) | C30: =IF(B30="","",_xludf.XLOOKUP(B30,Countries!$A$2:$A$72,Countries!$B$2:$B$72,"???")) | D30: =IF(A30="","",MedalImport!C31) | E30: =IF(A30="","",MedalImport!D31) | F30: =IF(A30="","",MedalImport!E31) | G30: =IF(A30="","",D30+E30+F30) | H30: =IF(A30="","",_xludf.LET(raw,A30,isExcluded,_xludf.XLOOKUP(raw,Aliases!$A$2:$A$50,Aliases!$D$2:$D$50,FALSE),isMapped,ISNUMBER(MATCH(B30,Countries!$A$2:$A$72,0)),IF(isExcluded,"EXCLUDED",IF(isMapped,"OK","UNMAPPED"))))
A31: =IF(MedalImport!B32="","",MedalImport!B32) | B31: =IF(A31="","",_xludf.LET(raw,A31,alias,_xludf.XLOOKUP(raw,Aliases!$A$2:$A$50,Aliases!$B$2:$B$50,""),IF(alias<>"",alias,raw))) | C31: =IF(B31="","",_xludf.XLOOKUP(B31,Countries!$A$2:$A$72,Countries!$B$2:$B$72,"???")) | D31: =IF(A31="","",MedalImport!C32) | E31: =IF(A31="","",MedalImport!D32) | F31: =IF(A31="","",MedalImport!E32) | G31: =IF(A31="","",D31+E31+F31) | H31: =IF(A31="","",_xludf.LET(raw,A31,isExcluded,_xludf.XLOOKUP(raw,Aliases!$A$2:$A$50,Aliases!$D$2:$D$50,FALSE),isMapped,ISNUMBER(MATCH(B31,Countries!$A$2:$A$72,0)),IF(isExcluded,"EXCLUDED",IF(isMapped,"OK","UNMAPPED"))))
A32: =IF(MedalImport!B33="","",MedalImport!B33) | B32: =IF(A32="","",_xludf.LET(raw,A32,alias,_xludf.XLOOKUP(raw,Aliases!$A$2:$A$50,Aliases!$B$2:$B$50,""),IF(alias<>"",alias,raw))) | C32: =IF(B32="","",_xludf.XLOOKUP(B32,Countries!$A$2:$A$72,Countries!$B$2:$B$72,"???")) | D32: =IF(A32="","",MedalImport!C33) | E32: =IF(A32="","",MedalImport!D33) | F32: =IF(A32="","",MedalImport!E33) | G32: =IF(A32="","",D32+E32+F32) | H32: =IF(A32="","",_xludf.LET(raw,A32,isExcluded,_xludf.XLOOKUP(raw,Aliases!$A$2:$A$50,Aliases!$D$2:$D$50,FALSE),isMapped,ISNUMBER(MATCH(B32,Countries!$A$2:$A$72,0)),IF(isExcluded,"EXCLUDED",IF(isMapped,"OK","UNMAPPED"))))
A33: =IF(MedalImport!B34="","",MedalImport!B34) | B33: =IF(A33="","",_xludf.LET(raw,A33,alias,_xludf.XLOOKUP(raw,Aliases!$A$2:$A$50,Aliases!$B$2:$B$50,""),IF(alias<>"",alias,raw))) | C33: =IF(B33="","",_xludf.XLOOKUP(B33,Countries!$A$2:$A$72,Countries!$B$2:$B$72,"???")) | D33: =IF(A33="","",MedalImport!C34) | E33: =IF(A33="","",MedalImport!D34) | F33: =IF(A33="","",MedalImport!E34) | G33: =IF(A33="","",D33+E33+F33) | H33: =IF(A33="","",_xludf.LET(raw,A33,isExcluded,_xludf.XLOOKUP(raw,Aliases!$A$2:$A$50,Aliases!$D$2:$D$50,FALSE),isMapped,ISNUMBER(MATCH(B33,Countries!$A$2:$A$72,0)),IF(isExcluded,"EXCLUDED",IF(isMapped,"OK","UNMAPPED"))))
... A51: =IF(MedalImport!B52="","",MedalImport!B52) | B51: =IF(A51="","",_xludf.LET(raw,A51,alias,_xludf.XLOOKUP(raw,Aliases!$A$2:$A$50,Aliases!$B$2:$B$50,""),IF(alias<>"",alias,raw))) | C51: =IF(B51="","",_xludf.XLOOKUP(B51,Countries!$A$2:$A$72,Countries!$B$2:$B$72,"???")) | D51: =IF(A51="","",MedalImport!C52) | E51: =IF(A51="","",MedalImport!D52) | F51: =IF(A51="","",MedalImport!E52) | G51: =IF(A51="","",D51+E51+F51) | H51: =IF(A51="","",_xludf.LET(raw,A51,isExcluded,_xludf.XLOOKUP(raw,Aliases!$A$2:$A$50,Aliases!$D$2:$D$50,FALSE),isMapped,ISNUMBER(MATCH(B51,Countries!$A$2:$A$72,0)),IF(isExcluded,"EXCLUDED",IF(isMapped,"OK","UNMAPPED"))))

Sheet Entries
A1: Timestamp | B1: Email | C1: FirstName | D1: LastName | E1: DisplayName | F1: Tier1_Pick1 | G1: Tier2_Raw | H1: Tier3_Pick1 | I1: Tier4_Pick1 | J1: Tier5_Pick1 | K1: Tier6_Raw | L1: USA_TOTAL | M1: Tier2_Pick1 | N1: Tier2_Pick2 | O1: Tier6_Pick1 | P1: Tier6_Pick2 | Q1: PlayerID | R1: ValidationStatus | S1: ValidationDetails
A2: 46046.661 | B2: bhagstrom0@gmail.com | C2: Brad | D2: Hagstrom | E2: Brad Hagstrom | F2: United States | G2: France, South Korea | H2: China | I2: Finland | J2: Great Britain | K2: Belgium (30), âšª Benin (1) | L2: 12 | M2: =IF(G2="","",TRIM(LEFT(G2,FIND(",",G2)-1))) -> France | N2: =IF(G2="","",TRIM(MID(G2,FIND(",",G2)+1,100))) -> South Korea | O2: =IF(K2="","",IFERROR(TRIM(LEFT(SUBSTITUTE(TRIM(LEFT(K2,FIND(",",K2&",")-1)),"⚪",""),FIND(" (",SUBSTITUTE(TRIM(LEFT(K2,FIND(",",K2&",")-1)),"⚪","")&" (")-1)),TRIM(SUBSTITUTE(TRIM(LEFT(K2,FIND(",",K2&",")-1)),"⚪","")))) -> Belgium | P2: =IF(K2="","",IFERROR(TRIM(LEFT(SUBSTITUTE(TRIM(MID(K2,FIND(",",K2)+1,100)),"⚪",""),FIND(" (",SUBSTITUTE(TRIM(MID(K2,FIND(",",K2)+1,100)),"⚪","")&" (")-1)),TRIM(SUBSTITUTE(TRIM(MID(K2,FIND(",",K2)+1,100)),"⚪","")))) -> âšª Benin | Q2: =IF(C2="","",C2&"_"&D2&"_"&E2) -> Brad_Hagstrom_Brad Hagstrom | R2: =IF(C2="","",IF(AND(F2<>"",M2<>"",N2<>"",H2<>"",I2<>"",J2<>"",O2<>"",P2<>""),"OK","INCOMPLETE")) -> OK | S2: =IF(C2="","",IF(R2="INCOMPLETE","Missing picks","Valid")) -> Valid
M3: =IF(G3="","",TRIM(LEFT(G3,FIND(",",G3)-1))) | N3: =IF(G3="","",TRIM(MID(G3,FIND(",",G3)+1,100))) | O3: =IF(K3="","",IFERROR(TRIM(LEFT(SUBSTITUTE(TRIM(LEFT(K3,FIND(",",K3&",")-1)),"⚪",""),FIND(" (",SUBSTITUTE(TRIM(LEFT(K3,FIND(",",K3&",")-1)),"⚪","")&" (")-1)),TRIM(SUBSTITUTE(TRIM(LEFT(K3,FIND(",",K3&",")-1)),"⚪","")))) | P3: =IF(K3="","",IFERROR(TRIM(LEFT(SUBSTITUTE(TRIM(MID(K3,FIND(",",K3)+1,100)),"⚪",""),FIND(" (",SUBSTITUTE(TRIM(MID(K3,FIND(",",K3)+1,100)),"⚪","")&" (")-1)),TRIM(SUBSTITUTE(TRIM(MID(K3,FIND(",",K3)+1,100)),"⚪","")))) | Q3: =IF(C3="","",C3&"_"&D3&"_"&E3) | R3: =IF(C3="","",IF(AND(F3<>"",M3<>"",N3<>"",H3<>"",I3<>"",J3<>"",O3<>"",P3<>""),"OK","INCOMPLETE")) | S3: =IF(C3="","",IF(R3="INCOMPLETE","Missing picks","Valid"))
M4: =IF(G4="","",TRIM(LEFT(G4,FIND(",",G4)-1))) | N4: =IF(G4="","",TRIM(MID(G4,FIND(",",G4)+1,100))) | O4: =IF(K4="","",IFERROR(TRIM(LEFT(SUBSTITUTE(TRIM(LEFT(K4,FIND(",",K4&",")-1)),"⚪",""),FIND(" (",SUBSTITUTE(TRIM(LEFT(K4,FIND(",",K4&",")-1)),"⚪","")&" (")-1)),TRIM(SUBSTITUTE(TRIM(LEFT(K4,FIND(",",K4&",")-1)),"⚪","")))) | P4: =IF(K4="","",IFERROR(TRIM(LEFT(SUBSTITUTE(TRIM(MID(K4,FIND(",",K4)+1,100)),"⚪",""),FIND(" (",SUBSTITUTE(TRIM(MID(K4,FIND(",",K4)+1,100)),"⚪","")&" (")-1)),TRIM(SUBSTITUTE(TRIM(MID(K4,FIND(",",K4)+1,100)),"⚪","")))) | Q4: =IF(C4="","",C4&"_"&D4&"_"&E4) | R4: =IF(C4="","",IF(AND(F4<>"",M4<>"",N4<>"",H4<>"",I4<>"",J4<>"",O4<>"",P4<>""),"OK","INCOMPLETE")) | S4: =IF(C4="","",IF(R4="INCOMPLETE","Missing picks","Valid"))
M5: =IF(G5="","",TRIM(LEFT(G5,FIND(",",G5)-1))) | N5: =IF(G5="","",TRIM(MID(G5,FIND(",",G5)+1,100))) | O5: =IF(K5="","",IFERROR(TRIM(LEFT(SUBSTITUTE(TRIM(LEFT(K5,FIND(",",K5&",")-1)),"⚪",""),FIND(" (",SUBSTITUTE(TRIM(LEFT(K5,FIND(",",K5&",")-1)),"⚪","")&" (")-1)),TRIM(SUBSTITUTE(TRIM(LEFT(K5,FIND(",",K5&",")-1)),"⚪","")))) | P5: =IF(K5="","",IFERROR(TRIM(LEFT(SUBSTITUTE(TRIM(MID(K5,FIND(",",K5)+1,100)),"⚪",""),FIND(" (",SUBSTITUTE(TRIM(MID(K5,FIND(",",K5)+1,100)),"⚪","")&" (")-1)),TRIM(SUBSTITUTE(TRIM(MID(K5,FIND(",",K5)+1,100)),"⚪","")))) | Q5: =IF(C5="","",C5&"_"&D5&"_"&E5) | R5: =IF(C5="","",IF(AND(F5<>"",M5<>"",N5<>"",H5<>"",I5<>"",J5<>"",O5<>"",P5<>""),"OK","INCOMPLETE")) | S5: =IF(C5="","",IF(R5="INCOMPLETE","Missing picks","Valid"))
M6: =IF(G6="","",TRIM(LEFT(G6,FIND(",",G6)-1))) | N6: =IF(G6="","",TRIM(MID(G6,FIND(",",G6)+1,100))) | O6: =IF(K6="","",IFERROR(TRIM(LEFT(SUBSTITUTE(TRIM(LEFT(K6,FIND(",",K6&",")-1)),"⚪",""),FIND(" (",SUBSTITUTE(TRIM(LEFT(K6,FIND(",",K6&",")-1)),"⚪","")&" (")-1)),TRIM(SUBSTITUTE(TRIM(LEFT(K6,FIND(",",K6&",")-1)),"⚪","")))) | P6: =IF(K6="","",IFERROR(TRIM(LEFT(SUBSTITUTE(TRIM(MID(K6,FIND(",",K6)+1,100)),"⚪",""),FIND(" (",SUBSTITUTE(TRIM(MID(K6,FIND(",",K6)+1,100)),"⚪","")&" (")-1)),TRIM(SUBSTITUTE(TRIM(MID(K6,FIND(",",K6)+1,100)),"⚪","")))) | Q6: =IF(C6="","",C6&"_"&D6&"_"&E6) | R6: =IF(C6="","",IF(AND(F6<>"",M6<>"",N6<>"",H6<>"",I6<>"",J6<>"",O6<>"",P6<>""),"OK","INCOMPLETE")) | S6: =IF(C6="","",IF(R6="INCOMPLETE","Missing picks","Valid"))
M7: =IF(G7="","",TRIM(LEFT(G7,FIND(",",G7)-1))) | N7: =IF(G7="","",TRIM(MID(G7,FIND(",",G7)+1,100))) | O7: =IF(K7="","",IFERROR(TRIM(LEFT(SUBSTITUTE(TRIM(LEFT(K7,FIND(",",K7&",")-1)),"⚪",""),FIND(" (",SUBSTITUTE(TRIM(LEFT(K7,FIND(",",K7&",")-1)),"⚪","")&" (")-1)),TRIM(SUBSTITUTE(TRIM(LEFT(K7,FIND(",",K7&",")-1)),"⚪","")))) | P7: =IF(K7="","",IFERROR(TRIM(LEFT(SUBSTITUTE(TRIM(MID(K7,FIND(",",K7)+1,100)),"⚪",""),FIND(" (",SUBSTITUTE(TRIM(MID(K7,FIND(",",K7)+1,100)),"⚪","")&" (")-1)),TRIM(SUBSTITUTE(TRIM(MID(K7,FIND(",",K7)+1,100)),"⚪","")))) | Q7: =IF(C7="","",C7&"_"&D7&"_"&E7) | R7: =IF(C7="","",IF(AND(F7<>"",M7<>"",N7<>"",H7<>"",I7<>"",J7<>"",O7<>"",P7<>""),"OK","INCOMPLETE")) | S7: =IF(C7="","",IF(R7="INCOMPLETE","Missing picks","Valid"))
M8: =IF(G8="","",TRIM(LEFT(G8,FIND(",",G8)-1))) | N8: =IF(G8="","",TRIM(MID(G8,FIND(",",G8)+1,100))) | O8: =IF(K8="","",IFERROR(TRIM(LEFT(SUBSTITUTE(TRIM(LEFT(K8,FIND(",",K8&",")-1)),"⚪",""),FIND(" (",SUBSTITUTE(TRIM(LEFT(K8,FIND(",",K8&",")-1)),"⚪","")&" (")-1)),TRIM(SUBSTITUTE(TRIM(LEFT(K8,FIND(",",K8&",")-1)),"⚪","")))) | P8: =IF(K8="","",IFERROR(TRIM(LEFT(SUBSTITUTE(TRIM(MID(K8,FIND(",",K8)+1,100)),"⚪",""),FIND(" (",SUBSTITUTE(TRIM(MID(K8,FIND(",",K8)+1,100)),"⚪","")&" (")-1)),TRIM(SUBSTITUTE(TRIM(MID(K8,FIND(",",K8)+1,100)),"⚪","")))) | Q8: =IF(C8="","",C8&"_"&D8&"_"&E8) | R8: =IF(C8="","",IF(AND(F8<>"",M8<>"",N8<>"",H8<>"",I8<>"",J8<>"",O8<>"",P8<>""),"OK","INCOMPLETE")) | S8: =IF(C8="","",IF(R8="INCOMPLETE","Missing picks","Valid"))
M9: =IF(G9="","",TRIM(LEFT(G9,FIND(",",G9)-1))) | N9: =IF(G9="","",TRIM(MID(G9,FIND(",",G9)+1,100))) | O9: =IF(K9="","",IFERROR(TRIM(LEFT(SUBSTITUTE(TRIM(LEFT(K9,FIND(",",K9&",")-1)),"⚪",""),FIND(" (",SUBSTITUTE(TRIM(LEFT(K9,FIND(",",K9&",")-1)),"⚪","")&" (")-1)),TRIM(SUBSTITUTE(TRIM(LEFT(K9,FIND(",",K9&",")-1)),"⚪","")))) | P9: =IF(K9="","",IFERROR(TRIM(LEFT(SUBSTITUTE(TRIM(MID(K9,FIND(",",K9)+1,100)),"⚪",""),FIND(" (",SUBSTITUTE(TRIM(MID(K9,FIND(",",K9)+1,100)),"⚪","")&" (")-1)),TRIM(SUBSTITUTE(TRIM(MID(K9,FIND(",",K9)+1,100)),"⚪","")))) | Q9: =IF(C9="","",C9&"_"&D9&"_"&E9) | R9: =IF(C9="","",IF(AND(F9<>"",M9<>"",N9<>"",H9<>"",I9<>"",J9<>"",O9<>"",P9<>""),"OK","INCOMPLETE")) | S9: =IF(C9="","",IF(R9="INCOMPLETE","Missing picks","Valid"))
M10: =IF(G10="","",TRIM(LEFT(G10,FIND(",",G10)-1))) | N10: =IF(G10="","",TRIM(MID(G10,FIND(",",G10)+1,100))) | O10: =IF(K10="","",IFERROR(TRIM(LEFT(SUBSTITUTE(TRIM(LEFT(K10,FIND(",",K10&",")-1)),"⚪",""),FIND(" (",SUBSTITUTE(TRIM(LEFT(K10,FIND(",",K10&",")-1)),"⚪","")&" (")-1)),TRIM(SUBSTITUTE(TRIM(LEFT(K10,FIND(",",K10&",")-1)),"⚪","")))) | P10: =IF(K10="","",IFERROR(TRIM(LEFT(SUBSTITUTE(TRIM(MID(K10,FIND(",",K10)+1,100)),"⚪",""),FIND(" (",SUBSTITUTE(TRIM(MID(K10,FIND(",",K10)+1,100)),"⚪","")&" (")-1)),TRIM(SUBSTITUTE(TRIM(MID(K10,FIND(",",K10)+1,100)),"⚪","")))) | Q10: =IF(C10="","",C10&"_"&D10&"_"&E10) | R10: =IF(C10="","",IF(AND(F10<>"",M10<>"",N10<>"",H10<>"",I10<>"",J10<>"",O10<>"",P10<>""),"OK","INCOMPLETE")) | S10: =IF(C10="","",IF(R10="INCOMPLETE","Missing picks","Valid"))
M11: =IF(G11="","",TRIM(LEFT(G11,FIND(",",G11)-1))) | N11: =IF(G11="","",TRIM(MID(G11,FIND(",",G11)+1,100))) | O11: =IF(K11="","",IFERROR(TRIM(LEFT(SUBSTITUTE(TRIM(LEFT(K11,FIND(",",K11&",")-1)),"⚪",""),FIND(" (",SUBSTITUTE(TRIM(LEFT(K11,FIND(",",K11&",")-1)),"⚪","")&" (")-1)),TRIM(SUBSTITUTE(TRIM(LEFT(K11,FIND(",",K11&",")-1)),"⚪","")))) | P11: =IF(K11="","",IFERROR(TRIM(LEFT(SUBSTITUTE(TRIM(MID(K11,FIND(",",K11)+1,100)),"⚪",""),FIND(" (",SUBSTITUTE(TRIM(MID(K11,FIND(",",K11)+1,100)),"⚪","")&" (")-1)),TRIM(SUBSTITUTE(TRIM(MID(K11,FIND(",",K11)+1,100)),"⚪","")))) | Q11: =IF(C11="","",C11&"_"&D11&"_"&E11) | R11: =IF(C11="","",IF(AND(F11<>"",M11<>"",N11<>"",H11<>"",I11<>"",J11<>"",O11<>"",P11<>""),"OK","INCOMPLETE")) | S11: =IF(C11="","",IF(R11="INCOMPLETE","Missing picks","Valid"))
M12: =IF(G12="","",TRIM(LEFT(G12,FIND(",",G12)-1))) | N12: =IF(G12="","",TRIM(MID(G12,FIND(",",G12)+1,100))) | O12: =IF(K12="","",IFERROR(TRIM(LEFT(SUBSTITUTE(TRIM(LEFT(K12,FIND(",",K12&",")-1)),"⚪",""),FIND(" (",SUBSTITUTE(TRIM(LEFT(K12,FIND(",",K12&",")-1)),"⚪","")&" (")-1)),TRIM(SUBSTITUTE(TRIM(LEFT(K12,FIND(",",K12&",")-1)),"⚪","")))) | P12: =IF(K12="","",IFERROR(TRIM(LEFT(SUBSTITUTE(TRIM(MID(K12,FIND(",",K12)+1,100)),"⚪",""),FIND(" (",SUBSTITUTE(TRIM(MID(K12,FIND(",",K12)+1,100)),"⚪","")&" (")-1)),TRIM(SUBSTITUTE(TRIM(MID(K12,FIND(",",K12)+1,100)),"⚪","")))) | Q12: =IF(C12="","",C12&"_"&D12&"_"&E12) | R12: =IF(C12="","",IF(AND(F12<>"",M12<>"",N12<>"",H12<>"",I12<>"",J12<>"",O12<>"",P12<>""),"OK","INCOMPLETE")) | S12: =IF(C12="","",IF(R12="INCOMPLETE","Missing picks","Valid"))
M13: =IF(G13="","",TRIM(LEFT(G13,FIND(",",G13)-1))) | N13: =IF(G13="","",TRIM(MID(G13,FIND(",",G13)+1,100))) | O13: =IF(K13="","",IFERROR(TRIM(LEFT(SUBSTITUTE(TRIM(LEFT(K13,FIND(",",K13&",")-1)),"⚪",""),FIND(" (",SUBSTITUTE(TRIM(LEFT(K13,FIND(",",K13&",")-1)),"⚪","")&" (")-1)),TRIM(SUBSTITUTE(TRIM(LEFT(K13,FIND(",",K13&",")-1)),"⚪","")))) | P13: =IF(K13="","",IFERROR(TRIM(LEFT(SUBSTITUTE(TRIM(MID(K13,FIND(",",K13)+1,100)),"⚪",""),FIND(" (",SUBSTITUTE(TRIM(MID(K13,FIND(",",K13)+1,100)),"⚪","")&" (")-1)),TRIM(SUBSTITUTE(TRIM(MID(K13,FIND(",",K13)+1,100)),"⚪","")))) | Q13: =IF(C13="","",C13&"_"&D13&"_"&E13) | R13: =IF(C13="","",IF(AND(F13<>"",M13<>"",N13<>"",H13<>"",I13<>"",J13<>"",O13<>"",P13<>""),"OK","INCOMPLETE")) | S13: =IF(C13="","",IF(R13="INCOMPLETE","Missing picks","Valid"))
M14: =IF(G14="","",TRIM(LEFT(G14,FIND(",",G14)-1))) | N14: =IF(G14="","",TRIM(MID(G14,FIND(",",G14)+1,100))) | O14: =IF(K14="","",IFERROR(TRIM(LEFT(SUBSTITUTE(TRIM(LEFT(K14,FIND(",",K14&",")-1)),"⚪",""),FIND(" (",SUBSTITUTE(TRIM(LEFT(K14,FIND(",",K14&",")-1)),"⚪","")&" (")-1)),TRIM(SUBSTITUTE(TRIM(LEFT(K14,FIND(",",K14&",")-1)),"⚪","")))) | P14: =IF(K14="","",IFERROR(TRIM(LEFT(SUBSTITUTE(TRIM(MID(K14,FIND(",",K14)+1,100)),"⚪",""),FIND(" (",SUBSTITUTE(TRIM(MID(K14,FIND(",",K14)+1,100)),"⚪","")&" (")-1)),TRIM(SUBSTITUTE(TRIM(MID(K14,FIND(",",K14)+1,100)),"⚪","")))) | Q14: =IF(C14="","",C14&"_"&D14&"_"&E14) | R14: =IF(C14="","",IF(AND(F14<>"",M14<>"",N14<>"",H14<>"",I14<>"",J14<>"",O14<>"",P14<>""),"OK","INCOMPLETE")) | S14: =IF(C14="","",IF(R14="INCOMPLETE","Missing picks","Valid"))
... M51: =IF(G51="","",TRIM(LEFT(G51,FIND(",",G51)-1))) | N51: =IF(G51="","",TRIM(MID(G51,FIND(",",G51)+1,100))) | O51: =IF(K51="","",IFERROR(TRIM(LEFT(SUBSTITUTE(TRIM(LEFT(K51,FIND(",",K51&",")-1)),"⚪",""),FIND(" (",SUBSTITUTE(TRIM(LEFT(K51,FIND(",",K51&",")-1)),"⚪","")&" (")-1)),TRIM(SUBSTITUTE(TRIM(LEFT(K51,FIND(",",K51&",")-1)),"⚪","")))) | P51: =IF(K51="","",IFERROR(TRIM(LEFT(SUBSTITUTE(TRIM(MID(K51,FIND(",",K51)+1,100)),"⚪",""),FIND(" (",SUBSTITUTE(TRIM(MID(K51,FIND(",",K51)+1,100)),"⚪","")&" (")-1)),TRIM(SUBSTITUTE(TRIM(MID(K51,FIND(",",K51)+1,100)),"⚪","")))) | Q51: =IF(C51="","",C51&"_"&D51&"_"&E51) | R51: =IF(C51="","",IF(AND(F51<>"",M51<>"",N51<>"",H51<>"",I51<>"",J51<>"",O51<>"",P51<>""),"OK","INCOMPLETE")) | S51: =IF(C51="","",IF(R51="INCOMPLETE","Missing picks","Valid"))

Sheet Scores
A1: PlayerID | B1: DisplayName | C1: PickSlot | D1: Tier | E1: CountryName | F1: IOC | G1: Multiplier | H1: Gold | I1: Silver | J1: Bronze | K1: GoldPts | L1: SilverPts | M1: BronzePts | N1: TotalPts | O1: IsValid | P1: HasMedaled | Q1: MedalIndicator
A2: {=IFERROR(IF(INDEX(Entries!$C$2:$C$48,1)="","",INDEX(Entries!$Q$2:$Q$48,1)),"")} -> Brad_Hagstrom_Brad Hagstrom | B2: {=IF(A2="","",IFERROR(INDEX(Entries!$E$2:$E$48,1),""))} -> Brad Hagstrom | C2: =IF(A2="","","Tier1_Pick1") -> Tier1_Pick1 | D2: =IF(A2="","",1) -> 1 | E2: {=IF(A2="","",IFERROR(INDEX(Entries!$F$2:$F$48,1),""))} -> United States | F2: {=IF(E2="","",IFERROR(XLOOKUP(E2,Countries!$A$2:$A$72,Countries!$B$2:$B$72,"???"),"???"))} -> USA | G2: {=IF(E2="",0,IFERROR(XLOOKUP(E2,Countries!$A$2:$A$72,Countries!$E$2:$E$72,0),0))} -> 1 | H2: {=IF(E2="",0,IFERROR(XLOOKUP(E2,Medals!$B$2:$B$51,Medals!$D$2:$D$51,0),0))} -> 6 | I2: {=IF(E2="",0,IFERROR(XLOOKUP(E2,Medals!$B$2:$B$51,Medals!$E$2:$E$51,0),0))} -> 8 | J2: {=IF(E2="",0,IFERROR(XLOOKUP(E2,Medals!$B$2:$B$51,Medals!$F$2:$F$51,0),0))} -> 7 | K2: =H2*GoldPoints*G2 -> 18 | L2: =I2*SilverPoints*G2 -> 16 | M2: =J2*BronzePoints*G2 -> 7 | N2: =K2+L2+M2 -> 41 | O2: {=IF(E2="",FALSE,IFERROR(AND(ISNUMBER(MATCH(E2,Countries!$A$2:$A$72,0)),XLOOKUP(E2,Countries!$A$2:$A$72,Countries!$I$2:$I$72,FALSE)),FALSE))} -> TRUE | P2: {=IF(E2="",FALSE,IFERROR(XLOOKUP(E2,Countries!$A$2:$A$72,Countries!$G$2:$G$72,FALSE),FALSE))} -> TRUE | Q2: =IF(P2,"","⚪")
A3: {=IFERROR(IF(INDEX(Entries!$C$2:$C$48,1)="","",INDEX(Entries!$Q$2:$Q$48,1)),"")} -> Brad_Hagstrom_Brad Hagstrom | B3: {=IF(A3="","",IFERROR(INDEX(Entries!$E$2:$E$48,1),""))} -> Brad Hagstrom | C3: =IF(A3="","","Tier2_Pick1") -> Tier2_Pick1 | D3: =IF(A3="","",2) -> 2 | E3: {=IF(A3="","",IFERROR(INDEX(Entries!$M$2:$M$48,1),""))} -> France | F3: {=IF(E3="","",IFERROR(XLOOKUP(E3,Countries!$A$2:$A$72,Countries!$B$2:$B$72,"???"),"???"))} -> FRA | G3: {=IF(E3="",0,IFERROR(XLOOKUP(E3,Countries!$A$2:$A$72,Countries!$E$2:$E$72,0),0))} -> 2 | H3: {=IF(E3="",0,IFERROR(XLOOKUP(E3,Medals!$B$2:$B$51,Medals!$D$2:$D$51,0),0))} -> 3 | I3: {=IF(E3="",0,IFERROR(XLOOKUP(E3,Medals!$B$2:$B$51,Medals!$E$2:$E$51,0),0))} -> 4 | J3: {=IF(E3="",0,IFERROR(XLOOKUP(E3,Medals!$B$2:$B$51,Medals!$F$2:$F$51,0),0))} -> 2 | K3: =H3*GoldPoints*G3 -> 18 | L3: =I3*SilverPoints*G3 -> 16 | M3: =J3*BronzePoints*G3 -> 4 | N3: =K3+L3+M3 -> 38 | O3: {=IF(E3="",FALSE,IFERROR(AND(ISNUMBER(MATCH(E3,Countries!$A$2:$A$72,0)),XLOOKUP(E3,Countries!$A$2:$A$72,Countries!$I$2:$I$72,FALSE)),FALSE))} -> TRUE | P3: {=IF(E3="",FALSE,IFERROR(XLOOKUP(E3,Countries!$A$2:$A$72,Countries!$G$2:$G$72,FALSE),FALSE))} -> TRUE | Q3: =IF(P3,"","⚪")
A4: {=IFERROR(IF(INDEX(Entries!$C$2:$C$48,1)="","",INDEX(Entries!$Q$2:$Q$48,1)),"")} -> Brad_Hagstrom_Brad Hagstrom | B4: {=IF(A4="","",IFERROR(INDEX(Entries!$E$2:$E$48,1),""))} -> Brad Hagstrom | C4: =IF(A4="","","Tier2_Pick2") -> Tier2_Pick2 | D4: =IF(A4="","",2) -> 2 | E4: {=IF(A4="","",IFERROR(INDEX(Entries!$N$2:$N$48,1),""))} -> South Korea | F4: {=IF(E4="","",IFERROR(XLOOKUP(E4,Countries!$A$2:$A$72,Countries!$B$2:$B$72,"???"),"???"))} -> KOR | G4: {=IF(E4="",0,IFERROR(XLOOKUP(E4,Countries!$A$2:$A$72,Countries!$E$2:$E$72,0),0))} -> 2 | H4: {=IF(E4="",0,IFERROR(XLOOKUP(E4,Medals!$B$2:$B$51,Medals!$D$2:$D$51,0),0))} -> 2 | I4: {=IF(E4="",0,IFERROR(XLOOKUP(E4,Medals!$B$2:$B$51,Medals!$E$2:$E$51,0),0))} -> 3 | J4: {=IF(E4="",0,IFERROR(XLOOKUP(E4,Medals!$B$2:$B$51,Medals!$F$2:$F$51,0),0))} -> 2 | K4: =H4*GoldPoints*G4 -> 12 | L4: =I4*SilverPoints*G4 -> 12 | M4: =J4*BronzePoints*G4 -> 4 | N4: =K4+L4+M4 -> 28 | O4: {=IF(E4="",FALSE,IFERROR(AND(ISNUMBER(MATCH(E4,Countries!$A$2:$A$72,0)),XLOOKUP(E4,Countries!$A$2:$A$72,Countries!$I$2:$I$72,FALSE)),FALSE))} -> TRUE | P4: {=IF(E4="",FALSE,IFERROR(XLOOKUP(E4,Countries!$A$2:$A$72,Countries!$G$2:$G$72,FALSE),FALSE))} -> TRUE | Q4: =IF(P4,"","⚪")
A5: {=IFERROR(IF(INDEX(Entries!$C$2:$C$48,1)="","",INDEX(Entries!$Q$2:$Q$48,1)),"")} -> Brad_Hagstrom_Brad Hagstrom | B5: {=IF(A5="","",IFERROR(INDEX(Entries!$E$2:$E$48,1),""))} -> Brad Hagstrom | C5: =IF(A5="","","Tier3_Pick1") -> Tier3_Pick1 | D5: =IF(A5="","",3) -> 3 | E5: {=IF(A5="","",IFERROR(INDEX(Entries!$H$2:$H$48,1),""))} -> China | F5: {=IF(E5="","",IFERROR(XLOOKUP(E5,Countries!$A$2:$A$72,Countries!$B$2:$B$72,"???"),"???"))} -> CHN | G5: {=IF(E5="",0,IFERROR(XLOOKUP(E5,Countries!$A$2:$A$72,Countries!$E$2:$E$72,0),0))} -> 3 | H5: {=IF(E5="",0,IFERROR(XLOOKUP(E5,Medals!$B$2:$B$51,Medals!$D$2:$D$51,0),0))} -> 3 | I5: {=IF(E5="",0,IFERROR(XLOOKUP(E5,Medals!$B$2:$B$51,Medals!$E$2:$E$51,0),0))} -> 2 | J5: {=IF(E5="",0,IFERROR(XLOOKUP(E5,Medals!$B$2:$B$51,Medals!$F$2:$F$51,0),0))} -> 4 | K5: =H5*GoldPoints*G5 -> 27 | L5: =I5*SilverPoints*G5 -> 12 | M5: =J5*BronzePoints*G5 -> 12 | N5: =K5+L5+M5 -> 51 | O5: {=IF(E5="",FALSE,IFERROR(AND(ISNUMBER(MATCH(E5,Countries!$A$2:$A$72,0)),XLOOKUP(E5,Countries!$A$2:$A$72,Countries!$I$2:$I$72,FALSE)),FALSE))} -> TRUE | P5: {=IF(E5="",FALSE,IFERROR(XLOOKUP(E5,Countries!$A$2:$A$72,Countries!$G$2:$G$72,FALSE),FALSE))} -> TRUE | Q5: =IF(P5,"","⚪")
A6: {=IFERROR(IF(INDEX(Entries!$C$2:$C$48,1)="","",INDEX(Entries!$Q$2:$Q$48,1)),"")} -> Brad_Hagstrom_Brad Hagstrom | B6: {=IF(A6="","",IFERROR(INDEX(Entries!$E$2:$E$48,1),""))} -> Brad Hagstrom | C6: =IF(A6="","","Tier4_Pick1") -> Tier4_Pick1 | D6: =IF(A6="","",4) -> 4 | E6: {=IF(A6="","",IFERROR(INDEX(Entries!$I$2:$I$48,1),""))} -> Finland | F6: {=IF(E6="","",IFERROR(XLOOKUP(E6,Countries!$A$2:$A$72,Countries!$B$2:$B$72,"???"),"???"))} -> FIN | G6: {=IF(E6="",0,IFERROR(XLOOKUP(E6,Countries!$A$2:$A$72,Countries!$E$2:$E$72,0),0))} -> 6 | H6: {=IF(E6="",0,IFERROR(XLOOKUP(E6,Medals!$B$2:$B$51,Medals!$D$2:$D$51,0),0))} -> 2 | I6: {=IF(E6="",0,IFERROR(XLOOKUP(E6,Medals!$B$2:$B$51,Medals!$E$2:$E$51,0),0))} -> 2 | J6: {=IF(E6="",0,IFERROR(XLOOKUP(E6,Medals!$B$2:$B$51,Medals!$F$2:$F$51,0),0))} -> 3 | K6: =H6*GoldPoints*G6 -> 36 | L6: =I6*SilverPoints*G6 -> 24 | M6: =J6*BronzePoints*G6 -> 18 | N6: =K6+L6+M6 -> 78 | O6: {=IF(E6="",FALSE,IFERROR(AND(ISNUMBER(MATCH(E6,Countries!$A$2:$A$72,0)),XLOOKUP(E6,Countries!$A$2:$A$72,Countries!$I$2:$I$72,FALSE)),FALSE))} -> TRUE | P6: {=IF(E6="",FALSE,IFERROR(XLOOKUP(E6,Countries!$A$2:$A$72,Countries!$G$2:$G$72,FALSE),FALSE))} -> TRUE | Q6: =IF(P6,"","⚪")
A7: {=IFERROR(IF(INDEX(Entries!$C$2:$C$48,1)="","",INDEX(Entries!$Q$2:$Q$48,1)),"")} -> Brad_Hagstrom_Brad Hagstrom | B7: {=IF(A7="","",IFERROR(INDEX(Entries!$E$2:$E$48,1),""))} -> Brad Hagstrom | C7: =IF(A7="","","Tier5_Pick1") -> Tier5_Pick1 | D7: =IF(A7="","",5) -> 5 | E7: {=IF(A7="","",IFERROR(INDEX(Entries!$J$2:$J$48,1),""))} -> Great Britain | F7: {=IF(E7="","",IFERROR(XLOOKUP(E7,Countries!$A$2:$A$72,Countries!$B$2:$B$72,"???"),"???"))} -> GBR | G7: {=IF(E7="",0,IFERROR(XLOOKUP(E7,Countries!$A$2:$A$72,Countries!$E$2:$E$72,0),0))} -> 10 | H7: {=IF(E7="",0,IFERROR(XLOOKUP(E7,Medals!$B$2:$B$51,Medals!$D$2:$D$51,0),0))} -> 1 | I7: {=IF(E7="",0,IFERROR(XLOOKUP(E7,Medals!$B$2:$B$51,Medals!$E$2:$E$51,0),0))} -> 1 | J7: {=IF(E7="",0,IFERROR(XLOOKUP(E7,Medals!$B$2:$B$51,Medals!$F$2:$F$51,0),0))} -> 1 | K7: =H7*GoldPoints*G7 -> 30 | L7: =I7*SilverPoints*G7 -> 20 | M7: =J7*BronzePoints*G7 -> 10 | N7: =K7+L7+M7 -> 60 | O7: {=IF(E7="",FALSE,IFERROR(AND(ISNUMBER(MATCH(E7,Countries!$A$2:$A$72,0)),XLOOKUP(E7,Countries!$A$2:$A$72,Countries!$I$2:$I$72,FALSE)),FALSE))} -> TRUE | P7: {=IF(E7="",FALSE,IFERROR(XLOOKUP(E7,Countries!$A$2:$A$72,Countries!$G$2:$G$72,FALSE),FALSE))} -> TRUE | Q7: =IF(P7,"","⚪")
A8: {=IFERROR(IF(INDEX(Entries!$C$2:$C$48,1)="","",INDEX(Entries!$Q$2:$Q$48,1)),"")} -> Brad_Hagstrom_Brad Hagstrom | B8: {=IF(A8="","",IFERROR(INDEX(Entries!$E$2:$E$48,1),""))} -> Brad Hagstrom | C8: =IF(A8="","","Tier6_Pick1") -> Tier6_Pick1 | D8: =IF(A8="","",6) -> 6 | E8: {=IF(A8="","",IFERROR(INDEX(Entries!$O$2:$O$48,1),""))} -> Belgium | F8: {=IF(E8="","",IFERROR(XLOOKUP(E8,Countries!$A$2:$A$72,Countries!$B$2:$B$72,"???"),"???"))} -> BEL | G8: {=IF(E8="",0,IFERROR(XLOOKUP(E8,Countries!$A$2:$A$72,Countries!$E$2:$E$72,0),0))} -> 20 | H8: {=IF(E8="",0,IFERROR(XLOOKUP(E8,Medals!$B$2:$B$51,Medals!$D$2:$D$51,0),0))} -> 0 | I8: {=IF(E8="",0,IFERROR(XLOOKUP(E8,Medals!$B$2:$B$51,Medals!$E$2:$E$51,0),0))} -> 0 | J8: {=IF(E8="",0,IFERROR(XLOOKUP(E8,Medals!$B$2:$B$51,Medals!$F$2:$F$51,0),0))} -> 0 | K8: =H8*GoldPoints*G8 -> 0 | L8: =I8*SilverPoints*G8 -> 0 | M8: =J8*BronzePoints*G8 -> 0 | N8: =K8+L8+M8 -> 0 | O8: {=IF(E8="",FALSE,IFERROR(AND(ISNUMBER(MATCH(E8,Countries!$A$2:$A$72,0)),XLOOKUP(E8,Countries!$A$2:$A$72,Countries!$I$2:$I$72,FALSE)),FALSE))} -> TRUE | P8: {=IF(E8="",FALSE,IFERROR(XLOOKUP(E8,Countries!$A$2:$A$72,Countries!$G$2:$G$72,FALSE),FALSE))} -> TRUE | Q8: =IF(P8,"","⚪")
A9: {=IFERROR(IF(INDEX(Entries!$C$2:$C$48,1)="","",INDEX(Entries!$Q$2:$Q$48,1)),"")} -> Brad_Hagstrom_Brad Hagstrom | B9: {=IF(A9="","",IFERROR(INDEX(Entries!$E$2:$E$48,1),""))} -> Brad Hagstrom | C9: =IF(A9="","","Tier6_Pick2") -> Tier6_Pick2 | D9: =IF(A9="","",6) -> 6 | E9: {=IF(A9="","",IFERROR(INDEX(Entries!$P$2:$P$48,1),""))} -> âšª Benin | F9: {=IF(E9="","",IFERROR(XLOOKUP(E9,Countries!$A$2:$A$72,Countries!$B$2:$B$72,"???"),"???"))} -> ??? | G9: {=IF(E9="",0,IFERROR(XLOOKUP(E9,Countries!$A$2:$A$72,Countries!$E$2:$E$72,0),0))} -> 0 | H9: {=IF(E9="",0,IFERROR(XLOOKUP(E9,Medals!$B$2:$B$51,Medals!$D$2:$D$51,0),0))} -> 0 | I9: {=IF(E9="",0,IFERROR(XLOOKUP(E9,Medals!$B$2:$B$51,Medals!$E$2:$E$51,0),0))} -> 0 | J9: {=IF(E9="",0,IFERROR(XLOOKUP(E9,Medals!$B$2:$B$51,Medals!$F$2:$F$51,0),0))} -> 0 | K9: =H9*GoldPoints*G9 -> 0 | L9: =I9*SilverPoints*G9 -> 0 | M9: =J9*BronzePoints*G9 -> 0 | N9: =K9+L9+M9 -> 0 | O9: {=IF(E9="",FALSE,IFERROR(AND(ISNUMBER(MATCH(E9,Countries!$A$2:$A$72,0)),XLOOKUP(E9,Countries!$A$2:$A$72,Countries!$I$2:$I$72,FALSE)),FALSE))} -> FALSE | P9: {=IF(E9="",FALSE,IFERROR(XLOOKUP(E9,Countries!$A$2:$A$72,Countries!$G$2:$G$72,FALSE),FALSE))} -> FALSE | Q9: =IF(P9,"","⚪") -> ⚪
A10: {=IFERROR(IF(INDEX(Entries!$C$2:$C$48,2)="","",INDEX(Entries!$Q$2:$Q$48,2)),"")} | B10: {=IF(A10="","",IFERROR(INDEX(Entries!$E$2:$E$48,2),""))} | C10: =IF(A10="","","Tier1_Pick1") | D10: =IF(A10="","",1) | E10: {=IF(A10="","",IFERROR(INDEX(Entries!$F$2:$F$48,2),""))} | F10: {=IF(E10="","",IFERROR(XLOOKUP(E10,Countries!$A$2:$A$72,Countries!$B$2:$B$72,"???"),"???"))} | G10: {=IF(E10="",0,IFERROR(XLOOKUP(E10,Countries!$A$2:$A$72,Countries!$E$2:$E$72,0),0))} -> 0 | H10: {=IF(E10="",0,IFERROR(XLOOKUP(E10,Medals!$B$2:$B$51,Medals!$D$2:$D$51,0),0))} -> 0 | I10: {=IF(E10="",0,IFERROR(XLOOKUP(E10,Medals!$B$2:$B$51,Medals!$E$2:$E$51,0),0))} -> 0 | J10: {=IF(E10="",0,IFERROR(XLOOKUP(E10,Medals!$B$2:$B$51,Medals!$F$2:$F$51,0),0))} -> 0 | K10: =H10*GoldPoints*G10 -> 0 | L10: =I10*SilverPoints*G10 -> 0 | M10: =J10*BronzePoints*G10 -> 0 | N10: =K10+L10+M10 -> 0 | O10: {=IF(E10="",FALSE,IFERROR(AND(ISNUMBER(MATCH(E10,Countries!$A$2:$A$72,0)),XLOOKUP(E10,Countries!$A$2:$A$72,Countries!$I$2:$I$72,FALSE)),FALSE))} -> FALSE | P10: {=IF(E10="",FALSE,IFERROR(XLOOKUP(E10,Countries!$A$2:$A$72,Countries!$G$2:$G$72,FALSE),FALSE))} -> FALSE | Q10: =IF(P10,"","⚪") -> ⚪
A11: {=IFERROR(IF(INDEX(Entries!$C$2:$C$48,2)="","",INDEX(Entries!$Q$2:$Q$48,2)),"")} | B11: {=IF(A11="","",IFERROR(INDEX(Entries!$E$2:$E$48,2),""))} | C11: =IF(A11="","","Tier2_Pick1") | D11: =IF(A11="","",2) | E11: {=IF(A11="","",IFERROR(INDEX(Entries!$M$2:$M$48,2),""))} | F11: {=IF(E11="","",IFERROR(XLOOKUP(E11,Countries!$A$2:$A$72,Countries!$B$2:$B$72,"???"),"???"))} | G11: {=IF(E11="",0,IFERROR(XLOOKUP(E11,Countries!$A$2:$A$72,Countries!$E$2:$E$72,0),0))} -> 0 | H11: {=IF(E11="",0,IFERROR(XLOOKUP(E11,Medals!$B$2:$B$51,Medals!$D$2:$D$51,0),0))} -> 0 | I11: {=IF(E11="",0,IFERROR(XLOOKUP(E11,Medals!$B$2:$B$51,Medals!$E$2:$E$51,0),0))} -> 0 | J11: {=IF(E11="",0,IFERROR(XLOOKUP(E11,Medals!$B$2:$B$51,Medals!$F$2:$F$51,0),0))} -> 0 | K11: =H11*GoldPoints*G11 -> 0 | L11: =I11*SilverPoints*G11 -> 0 | M11: =J11*BronzePoints*G11 -> 0 | N11: =K11+L11+M11 -> 0 | O11: {=IF(E11="",FALSE,IFERROR(AND(ISNUMBER(MATCH(E11,Countries!$A$2:$A$72,0)),XLOOKUP(E11,Countries!$A$2:$A$72,Countries!$I$2:$I$72,FALSE)),FALSE))} -> FALSE | P11: {=IF(E11="",FALSE,IFERROR(XLOOKUP(E11,Countries!$A$2:$A$72,Countries!$G$2:$G$72,FALSE),FALSE))} -> FALSE | Q11: =IF(P11,"","⚪") -> ⚪
A12: {=IFERROR(IF(INDEX(Entries!$C$2:$C$48,2)="","",INDEX(Entries!$Q$2:$Q$48,2)),"")} | B12: {=IF(A12="","",IFERROR(INDEX(Entries!$E$2:$E$48,2),""))} | C12: =IF(A12="","","Tier2_Pick2") | D12: =IF(A12="","",2) | E12: {=IF(A12="","",IFERROR(INDEX(Entries!$N$2:$N$48,2),""))} | F12: {=IF(E12="","",IFERROR(XLOOKUP(E12,Countries!$A$2:$A$72,Countries!$B$2:$B$72,"???"),"???"))} | G12: {=IF(E12="",0,IFERROR(XLOOKUP(E12,Countries!$A$2:$A$72,Countries!$E$2:$E$72,0),0))} -> 0 | H12: {=IF(E12="",0,IFERROR(XLOOKUP(E12,Medals!$B$2:$B$51,Medals!$D$2:$D$51,0),0))} -> 0 | I12: {=IF(E12="",0,IFERROR(XLOOKUP(E12,Medals!$B$2:$B$51,Medals!$E$2:$E$51,0),0))} -> 0 | J12: {=IF(E12="",0,IFERROR(XLOOKUP(E12,Medals!$B$2:$B$51,Medals!$F$2:$F$51,0),0))} -> 0 | K12: =H12*GoldPoints*G12 -> 0 | L12: =I12*SilverPoints*G12 -> 0 | M12: =J12*BronzePoints*G12 -> 0 | N12: =K12+L12+M12 -> 0 | O12: {=IF(E12="",FALSE,IFERROR(AND(ISNUMBER(MATCH(E12,Countries!$A$2:$A$72,0)),XLOOKUP(E12,Countries!$A$2:$A$72,Countries!$I$2:$I$72,FALSE)),FALSE))} -> FALSE | P12: {=IF(E12="",FALSE,IFERROR(XLOOKUP(E12,Countries!$A$2:$A$72,Countries!$G$2:$G$72,FALSE),FALSE))} -> FALSE | Q12: =IF(P12,"","⚪") -> ⚪
A13: {=IFERROR(IF(INDEX(Entries!$C$2:$C$48,2)="","",INDEX(Entries!$Q$2:$Q$48,2)),"")} | B13: {=IF(A13="","",IFERROR(INDEX(Entries!$E$2:$E$48,2),""))} | C13: =IF(A13="","","Tier3_Pick1") | D13: =IF(A13="","",3) | E13: {=IF(A13="","",IFERROR(INDEX(Entries!$H$2:$H$48,2),""))} | F13: {=IF(E13="","",IFERROR(XLOOKUP(E13,Countries!$A$2:$A$72,Countries!$B$2:$B$72,"???"),"???"))} | G13: {=IF(E13="",0,IFERROR(XLOOKUP(E13,Countries!$A$2:$A$72,Countries!$E$2:$E$72,0),0))} -> 0 | H13: {=IF(E13="",0,IFERROR(XLOOKUP(E13,Medals!$B$2:$B$51,Medals!$D$2:$D$51,0),0))} -> 0 | I13: {=IF(E13="",0,IFERROR(XLOOKUP(E13,Medals!$B$2:$B$51,Medals!$E$2:$E$51,0),0))} -> 0 | J13: {=IF(E13="",0,IFERROR(XLOOKUP(E13,Medals!$B$2:$B$51,Medals!$F$2:$F$51,0),0))} -> 0 | K13: =H13*GoldPoints*G13 -> 0 | L13: =I13*SilverPoints*G13 -> 0 | M13: =J13*BronzePoints*G13 -> 0 | N13: =K13+L13+M13 -> 0 | O13: {=IF(E13="",FALSE,IFERROR(AND(ISNUMBER(MATCH(E13,Countries!$A$2:$A$72,0)),XLOOKUP(E13,Countries!$A$2:$A$72,Countries!$I$2:$I$72,FALSE)),FALSE))} -> FALSE | P13: {=IF(E13="",FALSE,IFERROR(XLOOKUP(E13,Countries!$A$2:$A$72,Countries!$G$2:$G$72,FALSE),FALSE))} -> FALSE | Q13: =IF(P13,"","⚪") -> ⚪
